Workbook

Sheet 00_SKU_Master
A1: Dept | B1: SKU | C1: RAW_WIP_CODE | D1: Customer | E1: Product_Group | F1: Avg_Case_Weight | G1: Trays_Per_Case | H1: Tray_Type | I1: Tray_Size | J1: SKU_Desc | K1: Tray Pack Speed | L1: Package_Type | M1: STD | N1: Class | O1: Weight | P1: Active | Q1: SortOrder
A2: Cut_up | B2: 64 | C2: 61086#2 | D2: Bulk Pack | E2: ThighMeat | F2: 5 | J2: MB BSTHIGH AC BG 5KG | N2: SILVER
A3: Cut_up | B3: 65 | C3: 61050#2 | D3: Bulk Pack | E3: BSB | F3: 5 | J3: MB BSHB AC RND 5KG | N3: SILVER
A4: Cut_up | B4: 159 | C4: 61061 | D4: Bulk Pack | E4: BA | F4: 18 | J4: MS LEG BA 18KG | N4: SILVER
A5: Cut_up | B5: 160 | C5: 61072 | D5: Bulk Pack | E5: Drum | F5: 18 | J5: MS DRUM 18KG | N5: SILVER
A6: Cut_up | B6: 161 | C6: 61082 | D6: Bulk Pack | E6: Thigh | F6: 18 | J6: MB THIGH 20KG | N6: SILVER
A7: Cut_up | B7: 165 | C7: 61050#2 | D7: Bulk Pack | E7: BSB | F7: 10 | J7: MB BSHB AC RND 10KG | N7: SILVER
A8: Cut_up | B8: 834 | C8: 61082 | D8: Bulk Pack | E8: Thigh | F8: 18 | J8: THIGH 18KG | N8: SILVER
A9: Cut_up | B9: 868 | C9: 61014 | D9: Bulk Pack | E9: SplitWing | F9: 18 | J9: MB SPL WING 18KG | N9: SILVER
A10: Cut_up | B10: 895 | C10: 61072 | D10: Bulk Pack | E10: Drum | F10: 18 | J10: MB DRUM AC 18KG | N10: GOLD
A11: Cut_up | B11: 902 | C11: 61082 | D11: Bulk Pack | E11: Thigh | N11: SILVER
A12: Cut_up | B12: 904 | C12: 61010 | D12: Bulk Pack | E12: Wing | F12: 18 | J12: MB WING AC 18KG | N12: SILVER
A13: Cut_up | B13: 1026 | C13: 61010 | D13: Bulk Pack | E13: Wing | N13: SILVER
A14: Cut_up | B14: 1081 | C14: 61050#2 | D14: Bulk Pack | E14: BSB | N14: SILVER
A15: Cut_up | B15: 1446 | C15: 61050#2 | D15: Bulk Pack | E15: BSB | N15: SILVER
A16: Cut_up | B16: 1887 | C16: 61061 | D16: Bulk Pack | E16: BA | N16: GOLD
A17: Cut_up | B17: 1888 | D17: Bulk Pack | E17: SplitBreast | N17: GOLD
A18: Cut_up | B18: 1894 | C18: 61050#2 | D18: Bulk Pack | E18: BSB | J18: MB BSHB RND AC 18KG | N18: SILVER
A19: Cut_up | B19: 2233 | C19: 61014 | D19: Bulk Pack | E19: SplitWing | F19: 20 | J19: 24839 MB COS SPL WING AC | N19: GOLD
A20: Cut_up | B20: 2235 | C20: 61072 | D20: Bulk Pack | E20: Drum | F20: 20 | N20: GOLD
A21: Cut_up | B21: 2236 | C21: 61050 | D21: Bulk Pack | E21: BSB | F21: 20 | J21: 17219 MB COS BSHB AC | N21: PLATINUM
A22: Cut_up | B22: 200064 | C22: 61086#2 | D22: Bulk Pack | E22: ThighMeat | F22: 5 | J22: MB HA BSTHIGH AC BG 5KG | N22: SILVER
A23: Cut_up | B23: 200083 | D23: Bulk Pack | E23: SplitBreast | J23: MB HA FB BA AC COMBO | N23: SILVER
A24: Cut_up | B24: 200089 | D24: Bulk Pack | E24: SplitBreast | F24: 585 | J24: MB HA FB AC COMBO | N24: SILVER
A25: Cut_up | B25: 200095 | C25: 61072 | D25: Bulk Pack | E25: Drum | F25: 18 | J25: MS HA DRUM 18KG | N25: SILVER
A26: Cut_up | B26: 200159 | C26: 61061 | D26: Bulk Pack | E26: BA | F26: 18 | J26: MS HA LEG BA 18KG | N26: SILVER
A27: Cut_up | B27: 200868 | C27: 61014 | D27: Bulk Pack | E27: SplitWing | F27: 18 | J27: MB HA SPL WING AC 18KG | N27: SILVER
A28: Cut_up | B28: 200902 | C28: 61082 | D28: Bulk Pack | E28: Thigh | F28: 18 | J28: HA THIGH AC 18KG | N28: SILVER
A29: Cut_up | B29: 200903 | C29: 61061 | D29: Bulk Pack | E29: BA | F29: 18 | J29: HA LEG BA AC 18KG | N29: SILVER
A30: Cut_up | B30: 200904 | C30: 61010 | D30: Bulk Pack | E30: Wing | F30: 18 | J30: MB HA WING AC 18KG | N30: SILVER
A31: Cut_up | B31: 201894 | C31: 61050#2 | D31: Bulk Pack | E31: BSB | F31: 18 | J31: MB HA BSHB RND AC 18KG | N31: SILVER
A32: Cut_up | B32: 201895 | C32: 61050#2 | D32: Bulk Pack | E32: BSB | F32: 18 | J32: MB HA BSHB RND AC 18KG FFF | N32: SILVER
A33: Cut_up | B33: 201899 | C33: 61050#2 | D33: Bulk Pack | E33: BSB | F33: 10 | J33: MB HA BSHB 2ND 10KG | N33: SILVER
A34: Cut_up | B34: 203033 | C34: 61061 | D34: Bulk Pack | E34: BA | N34: SILVER
A35: Cut_up | B35: 203035 | C35: 61014 | D35: Bulk Pack | E35: SplitWing | F35: 23 | J35: MB HA SPL WING AC RET 23KG | N35: PLATINUM
A36: Cut_up | B36: 203087 | C36: 61050 | D36: Bulk Pack | E36: BSB | N36: PLATINUM
A37: Cut_up | B37: 203169 | C37: 61050#2 | D37: Bulk Pack | E37: BSB | N37: SILVER
A38: Cut_up | B38: 203171 | C38: 61072 | D38: Bulk Pack | E38: Drum | N38: SILVER
A39: Cut_up | B39: 203172 | C39: 61010 | D39: Bulk Pack | E39: Wing | F39: 25 | J39: MS HA WING RET 25KG | N39: SILVER
A40: Cut_up | B40: 203173 | C40: 61014 | D40: Bulk Pack | E40: SplitWing | J40: MS HA SPL WING RET 25KG | N40: SILVER
...

Sheet 00_Yield_Rates
A1: Part | B1: Product_Group | C1: Group | D1: Level | E1: Adjusted Yield (% normalized to 100%) | G1: WOG Basis | H1: Group | I1: Product_Group | J1: Adjusted Yield (%) | K1: Meaning (per 1 kg WOG)
A2: Breast (bone-in) | B2: SplitBreast | C2: Breast | D2: 1 | E2: 35.5 | G2: WOG=100% | H2: Breast | I2: SplitBreast | J2: 43 | K2: Finished kg obtainable from 1 kg WOG (percentage)
A3: Boneless Skinless Breast | B3: BSB | C3: Breast | D3: 2 | E3: 23.5 | G3: WOG=100% | H3: Breast | I3: BSB | J3: 31 | K3: Finished kg obtainable from 1 kg WOG (percentage)
A4: Boneless Skinless Breast | B4: WOF | C4: Breast | D4: 2 | E4: 19 | G4: WOG=100% | H4: Breast | I4: WOF | J4: =E3-E5 -> 19 | K4: Finished kg obtainable from 1 kg WOG (percentage)
A5: Tenderloin | B5: Fillet | C5: Breast | D5: 2 | E5: 4.5 | G5: WOG=100% | H5: Breast | I5: Fillet | J5: 4.12 | K5: Finished kg obtainable from 1 kg WOG (percentage)
A6: BA Leg | B6: BA | C6: LegBA | D6: 1 | E6: 47 | G6: WOG=100% | H6: LegBA | I6: BA | J6: 42 | K6: Finished kg obtainable from 1 kg WOG (percentage)
A7: Leg Quarter | B7: Wleg | C7: Leg | D7: 2 | E7: 32 | G7: WOG=100% | H7: Leg | I7: Wleg | J7: 38.82 | K7: Finished kg obtainable from 1 kg WOG (percentage)
A8: Thigh (bone-in) | B8: Thigh | C8: Leg | D8: 2 | E8: 17.5 | G8: WOG=100% | H8: Leg | I8: Thigh | J8: 19.1 | K8: Finished kg obtainable from 1 kg WOG (percentage)
A9: Boneless Thigh | B9: ThighMeat | C9: Leg | D9: 3 | E9: 11.5 | G9: WOG=100% | H9: Leg | I9: ThighMeat | J9: 10.5 | K9: Finished kg obtainable from 1 kg WOG (percentage)
A10: Drumstick | B10: Drum | C10: Leg | D10: 2 | E10: 14.3 | G10: WOG=100% | H10: Leg | I10: Drum | J10: 12.8 | K10: Finished kg obtainable from 1 kg WOG (percentage)
A11: Whole Wing | B11: Wing | C11: Wing | D11: 1 | E11: 10.8 | G11: WOG=100% | H11: Wing | I11: Wing | J11: 11 | K11: Finished kg obtainable from 1 kg WOG (percentage)
A12: Wing - Drumette | B12: SplitWing | C12: Wing | D12: 2 | E12: 9.5 | G12: WOG=100% | H12: Wing | I12: SplitWing | J12: 9.6 | K12: Finished kg obtainable from 1 kg WOG (percentage)
A13: Wing - Mid-joint | B13: SplitWing | C13: Wing | D13: 2 | E13: 9.5 | G13: WOG=100% | H13: Wing | I13: SplitWing | J13: 9.6 | K13: Finished kg obtainable from 1 kg WOG (percentage)
A14: Wing - Tip | B14: Wing - Tip | C14: Wing | D14: 2 | E14: 2.5 | G14: WOG=100% | H14: BackBone | I14: Back | J14: 9.41 | K14: Finished kg obtainable from 1 kg WOG (percentage)
A15: Back | B15: Back | C15: BackBone | D15: 2 | E15: 0
A16: Skin | C16: Skin | D16: 1 | E16: 0 | G16: 0
A17: Trim / Fat / Misc | C17: Other | D17: 1 | E17: 0 | G17: Note: | H17: Use: WOG_kg = Finished_kg / (Yield%/100). Total cages = MAX across Product_Groups.
A21: WOG | B21: Wings (Whole) | C21: 10.8 | D21: split
A22: WOG | B22: BSB (No Tenders) | C22: 19 | D22: split
A23: WOG | B23: Tenders (Sasa) | C23: 4.5 | D23: split
A24: WOG | B24: Breast Skin | C24: 3 | D24: split
A25: WOG | B25: Breast Bone (Keel) | C25: 4.5 | D25: split
A26: WOG | B26: Drumsticks | C26: 14.5 | D26: split
A27: WOG | B27: BST (Boneless Skinless Thigh) | C27: 11.5 | D27: split
A28: WOG | B28: Thigh Skin | C28: 2.5 | D28: split
A29: WOG | B29: Thigh Bone (Femur) | C29: 3.5 | D29: split
A30: WOG | B30: Back Skin | C30: 1.5 | D30: split
A31: WOG | B31: Frame / Carcass | C31: 20 | D31: split
A32: WOG | B32: Fat & Scrap | C32: 1.5 | D32: split
... A34: WOG | B34: Unallocated/Other | C34: 2 | D34: balance

Sheet 01_Cages_Plan
B2: Cut up Plan | H2: Code | I2: Cages | J2: Hours | L2: Flock # | M2: Size | N2: Code | O2: Size
B3: Total Cages | C3: 265 | D3: Manual input (do not link orders) | E3: RWA | H3: 200190/191 | I3: 4 | J3: =I3/$C$7 -> 0.24637681 | L3: Flock # 1 | M3: Big Bird | N3: 200141/150 | O3: 1.6-2.3
B4: Total Cages Request | C4: =C3-F7 -> 198 | E4: MLF | F4: =SUM(I3:I7) -> 67 | H4: 200140 | I4: 42 | J4: =I4/$C$7 -> 2.5869565 | L4: Flock # 2 | M4: Small Bird | N4: 200140/151 | O4: 1.3-1.6
B5: Avg Cage weight | C5: 680 | E5: St. Fran | F5: =I8 -> 0 | H5: 200141 | I5: 21 | J5: =I5/$C$7 -> 1.2934783 | L5: Flock # 3 | M5: Small Bird | N5: 200015
B6: Avg Bird weight | C6: 1.6 | E6: EVP | F6: =I9 -> 0 | H6: 200150 | J6: =I6/$C$7 -> 0 | L6: Flock # 4 | N6: St Francois | O6: 1.8
B7: Cages/Hour | C7: =60/(C5/C6/C9) -> 16.235294 | E7: Total: | F7: =SUM(F3:F6) -> 67 | H7: 200151 | J7: =I7/$C$7 -> 0 | L7: Flock # 5 | N7: Eden Valley
B8: Brids/cage | C8: =C5/C6 -> 425 | H8: Saint Francois | J8: =I8/$C$7 -> 0 | L8: Flock # 6 | M8: Mix Bird | N8: 200023
B9: Machine Speed (BPM) | C9: 115 | H9: Eden Valley | J9: =I9/$C$7 -> 0 | L9: Flock # 7 | M9: Big Bird | N9: 200017
L10: Flock # 19 | M10: Mix Bird | N10: 200190

Sheet 02_TrayPack_Order
B2: Code | C2: Extra Cases Produced | D2: Cases Remaining To Be Produced | F2: Y | M2: Total | N2: RAW_WIP_CODE | O2: Category | P2: Product_Group | Q2: Avg_Case_Weight | R2: WIP_kg
B3: ='05_Daily_Orders'!C3 -> 260 | C3: 0 | D3: 0 | G3: 0 | M3: =IF($F$2="n",0,(SUM(G3:L3)-C3)) -> 0 | N3: =_xlfn.IFNA(_xlfn.XLOOKUP(B3,'00_SKU_Master'!$B$2:$B$379,'00_SKU_Master'!$C$2:$C$379,0),"") -> 61050#2 | O3: ='05_Daily_Orders'!M3 -> LCL | P3: =_xlfn.IFNA(_xlfn.XLOOKUP(B3,'00_SKU_Master'!$B$2:$B$379,'00_SKU_Master'!$E$2:$E$379,""),"") -> BSB | Q3: =_xlfn.IFNA(_xlfn.XLOOKUP(B3,'00_SKU_Master'!$B$2:$B$379,'00_SKU_Master'!$F$2:$F$379,0),0) -> 0 | R3: =IF($M3="",0,$M3*Q3) -> 0
B4: ='05_Daily_Orders'!C4 -> 331 | C4: 0 | D4: 10 | G4: 0 | M4: =IF($F$2="n",0,(SUM(G4:L4)-C4)) -> 0 | N4: =_xlfn.IFNA(_xlfn.XLOOKUP(B4,'00_SKU_Master'!$B$2:$B$379,'00_SKU_Master'!$C$2:$C$379,0),"") -> 61061 | O4: ='05_Daily_Orders'!M4 -> METRO | P4: =_xlfn.IFNA(_xlfn.XLOOKUP(B4,'00_SKU_Master'!$B$2:$B$379,'00_SKU_Master'!$E$2:$E$379,""),"") -> BA | Q4: =_xlfn.IFNA(_xlfn.XLOOKUP(B4,'00_SKU_Master'!$B$2:$B$379,'00_SKU_Master'!$F$2:$F$379,0),0) -> 10.008899 | R4: =IF($M4="",0,$M4*Q4) -> 0
B5: ='05_Daily_Orders'!C5 -> 349 | C5: 0 | D5: 0 | G5: 0 | M5: =IF($F$2="n",0,(SUM(G5:L5)-C5)) -> 0 | N5: =_xlfn.IFNA(_xlfn.XLOOKUP(B5,'00_SKU_Master'!$B$2:$B$379,'00_SKU_Master'!$C$2:$C$379,0),"") -> 61040#2 | O5: ='05_Daily_Orders'!M5 -> FB | P5: =_xlfn.IFNA(_xlfn.XLOOKUP(B5,'00_SKU_Master'!$B$2:$B$379,'00_SKU_Master'!$E$2:$E$379,""),"") -> SplitBreast | Q5: =_xlfn.IFNA(_xlfn.XLOOKUP(B5,'00_SKU_Master'!$B$2:$B$379,'00_SKU_Master'!$F$2:$F$379,0),0) -> 0 | R5: =IF($M5="",0,$M5*Q5) -> 0
B6: ='05_Daily_Orders'!C6 -> 484 | C6: 0 | D6: 0 | G6: 28 | M6: =IF($F$2="n",0,(SUM(G6:L6)-C6)) -> 28 | N6: =_xlfn.IFNA(_xlfn.XLOOKUP(B6,'00_SKU_Master'!$B$2:$B$379,'00_SKU_Master'!$C$2:$C$379,0),"") -> 61121 | O6: ='05_Daily_Orders'!M6 -> FB | P6: =_xlfn.IFNA(_xlfn.XLOOKUP(B6,'00_SKU_Master'!$B$2:$B$379,'00_SKU_Master'!$E$2:$E$379,""),"") -> Backbone | Q6: =_xlfn.IFNA(_xlfn.XLOOKUP(B6,'00_SKU_Master'!$B$2:$B$379,'00_SKU_Master'!$F$2:$F$379,0),0) -> 9.4150185 | R6: =IF($M6="",0,$M6*Q6) -> 263.62052
B7: ='05_Daily_Orders'!C7 -> 784 | C7: 1 | D7: 0 | G7: 86 | M7: =IF($F$2="n",0,(SUM(G7:L7)-C7)) -> 85 | N7: =_xlfn.IFNA(_xlfn.XLOOKUP(B7,'00_SKU_Master'!$B$2:$B$379,'00_SKU_Master'!$C$2:$C$379,0),"") -> 61086#2 | O7: ='05_Daily_Orders'!M7 -> FB | P7: =_xlfn.IFNA(_xlfn.XLOOKUP(B7,'00_SKU_Master'!$B$2:$B$379,'00_SKU_Master'!$E$2:$E$379,""),"") -> ThighMeat | Q7: =_xlfn.IFNA(_xlfn.XLOOKUP(B7,'00_SKU_Master'!$B$2:$B$379,'00_SKU_Master'!$F$2:$F$379,0),0) -> 8.2634387 | R7: =IF($M7="",0,$M7*Q7) -> 702.39229
B8: ='05_Daily_Orders'!C8 -> 946 | C8: 0 | D8: 0 | G8: 0 | M8: =IF($F$2="n",0,(SUM(G8:L8)-C8)) -> 0 | N8: =_xlfn.IFNA(_xlfn.XLOOKUP(B8,'00_SKU_Master'!$B$2:$B$379,'00_SKU_Master'!$C$2:$C$379,0),"") -> 61040#2 | O8: ='05_Daily_Orders'!M8 -> FB | P8: =_xlfn.IFNA(_xlfn.XLOOKUP(B8,'00_SKU_Master'!$B$2:$B$379,'00_SKU_Master'!$E$2:$E$379,""),"") -> SplitBreast | Q8: =_xlfn.IFNA(_xlfn.XLOOKUP(B8,'00_SKU_Master'!$B$2:$B$379,'00_SKU_Master'!$F$2:$F$379,0),0) -> 0 | R8: =IF($M8="",0,$M8*Q8) -> 0
B9: ='05_Daily_Orders'!C9 -> 956 | C9: 0 | D9: 0 | G9: 0 | M9: =IF($F$2="n",0,(SUM(G9:L9)-C9)) -> 0 | N9: =_xlfn.IFNA(_xlfn.XLOOKUP(B9,'00_SKU_Master'!$B$2:$B$379,'00_SKU_Master'!$C$2:$C$379,0),"") -> 61072#2 | O9: ='05_Daily_Orders'!M9 -> FB | P9: =_xlfn.IFNA(_xlfn.XLOOKUP(B9,'00_SKU_Master'!$B$2:$B$379,'00_SKU_Master'!$E$2:$E$379,""),"") -> Drum | Q9: =_xlfn.IFNA(_xlfn.XLOOKUP(B9,'00_SKU_Master'!$B$2:$B$379,'00_SKU_Master'!$F$2:$F$379,0),0) -> 0 | R9: =IF($M9="",0,$M9*Q9) -> 0
B10: ='05_Daily_Orders'!C10 -> 957 | C10: 0 | D10: 0 | G10: 0 | M10: =IF($F$2="n",0,(SUM(G10:L10)-C10)) -> 0 | N10: =_xlfn.IFNA(_xlfn.XLOOKUP(B10,'00_SKU_Master'!$B$2:$B$379,'00_SKU_Master'!$C$2:$C$379,0),"") -> 61082 | O10: ='05_Daily_Orders'!M10 -> FB | P10: =_xlfn.IFNA(_xlfn.XLOOKUP(B10,'00_SKU_Master'!$B$2:$B$379,'00_SKU_Master'!$E$2:$E$379,""),"") -> Thigh | Q10: =_xlfn.IFNA(_xlfn.XLOOKUP(B10,'00_SKU_Master'!$B$2:$B$379,'00_SKU_Master'!$F$2:$F$379,0),0) -> 0 | R10: =IF($M10="",0,$M10*Q10) -> 0
B11: ='05_Daily_Orders'!C11 -> 1023 | C11: 0 | D11: 5 | G11: 0 | M11: =IF($F$2="n",0,(SUM(G11:L11)-C11)) -> 0 | N11: =_xlfn.IFNA(_xlfn.XLOOKUP(B11,'00_SKU_Master'!$B$2:$B$379,'00_SKU_Master'!$C$2:$C$379,0),"") -> 61121 | O11: ='05_Daily_Orders'!M11 -> METRO | P11: =_xlfn.IFNA(_xlfn.XLOOKUP(B11,'00_SKU_Master'!$B$2:$B$379,'00_SKU_Master'!$E$2:$E$379,""),"") -> Backbone | Q11: =_xlfn.IFNA(_xlfn.XLOOKUP(B11,'00_SKU_Master'!$B$2:$B$379,'00_SKU_Master'!$F$2:$F$379,0),0) -> 9.3701256 | R11: =IF($M11="",0,$M11*Q11) -> 0
B12: ='05_Daily_Orders'!C12 -> 1830 | C12: 0 | D12: 59 | G12: 52 | M12: =IF($F$2="n",0,(SUM(G12:L12)-C12)) -> 52 | N12: =_xlfn.IFNA(_xlfn.XLOOKUP(B12,'00_SKU_Master'!$B$2:$B$379,'00_SKU_Master'!$C$2:$C$379,0),"") -> 61050F | O12: ='05_Daily_Orders'!M12 -> FB | P12: =_xlfn.IFNA(_xlfn.XLOOKUP(B12,'00_SKU_Master'!$B$2:$B$379,'00_SKU_Master'!$E$2:$E$379,""),"") -> BSB | Q12: =_xlfn.IFNA(_xlfn.XLOOKUP(B12,'00_SKU_Master'!$B$2:$B$379,'00_SKU_Master'!$F$2:$F$379,0),0) -> 3.5867374 | R12: =IF($M12="",0,$M12*Q12) -> 186.51034
B13: ='05_Daily_Orders'!C13 -> 1831 | C13: 0 | D13: 110 | G13: 75 | M13: =IF($F$2="n",0,(SUM(G13:L13)-C13)) -> 75 | N13: =_xlfn.IFNA(_xlfn.XLOOKUP(B13,'00_SKU_Master'!$B$2:$B$379,'00_SKU_Master'!$C$2:$C$379,0),"") -> 203021 | O13: ='05_Daily_Orders'!M13 -> FB | P13: =_xlfn.IFNA(_xlfn.XLOOKUP(B13,'00_SKU_Master'!$B$2:$B$379,'00_SKU_Master'!$E$2:$E$379,""),"") -> Whole Bird-Small | Q13: =_xlfn.IFNA(_xlfn.XLOOKUP(B13,'00_SKU_Master'!$B$2:$B$379,'00_SKU_Master'!$F$2:$F$379,0),0) -> 7.2381956 | R13: =IF($M13="",0,$M13*Q13) -> 542.86467
B14: ='05_Daily_Orders'!C14 -> 1837 | C14: 0 | D14: 0 | G14: 0 | M14: =IF($F$2="n",0,(SUM(G14:L14)-C14)) -> 0 | N14: =_xlfn.IFNA(_xlfn.XLOOKUP(B14,'00_SKU_Master'!$B$2:$B$379,'00_SKU_Master'!$C$2:$C$379,0),"") -> 61010 | O14: ='05_Daily_Orders'!M14 -> FB | P14: =_xlfn.IFNA(_xlfn.XLOOKUP(B14,'00_SKU_Master'!$B$2:$B$379,'00_SKU_Master'!$E$2:$E$379,""),"") -> Wing | Q14: =_xlfn.IFNA(_xlfn.XLOOKUP(B14,'00_SKU_Master'!$B$2:$B$379,'00_SKU_Master'!$F$2:$F$379,0),0) -> 0 | R14: =IF($M14="",0,$M14*Q14) -> 0
... B265: ='05_Daily_Orders'!C265 -> 207128 | C265: 0 | D265: 0 | G265: 0 | M265: =IF($F$2="n",0,(SUM(G265:L265)-C265)) -> 0 | N265: =_xlfn.IFNA(_xlfn.XLOOKUP(B265,'00_SKU_Master'!$B$2:$B$379,'00_SKU_Master'!$C$2:$C$379,0),"") -> 203021 | O265: ='05_Daily_Orders'!M265 -> LCL | P265: =_xlfn.IFNA(_xlfn.XLOOKUP(B265,'00_SKU_Master'!$B$2:$B$379,'00_SKU_Master'!$E$2:$E$379,""),"") -> Whole Bird-Small | Q265: =_xlfn.IFNA(_xlfn.XLOOKUP(B265,'00_SKU_Master'!$B$2:$B$379,'00_SKU_Master'!$F$2:$F$379,0),0) -> 0 | R265: =IF($M265="",0,$M265*Q265) -> 0

Sheet 03_BulkPack_Order
B2: {=IFERROR(VALUE(LEFT(C2, MATCH(FALSE, ISNUMBER(MID(C2, ROW(INDIRECT("1:"&LEN(C2)+1)), 1) *1), 0) -1)),"")} | C2: For sale | H2: =IFERROR(SUMIF('13_Progress_Track'!$A$2:$A$108,B2,'13_Progress_Track'!$E$2:$E$108),"0") -> 0 | K2: Product_Group | L2: Avg_Case_Weight | M2: Yield_Rate | N2: WIP_kg | O2: Outside_Code
B3: {=IFERROR(VALUE(LEFT(C3, MATCH(FALSE, ISNUMBER(MID(C3, ROW(INDIRECT("1:"&LEN(C3)+1)), 1) *1), 0) -1)),"")} -> 203035 | C3: 203035 container | D3: 261 | H3: =IFERROR(SUMIF('13_Progress_Track'!$A$2:$A$108,B3,'13_Progress_Track'!$E$2:$E$108),"0") -> 0 | I3: =IFERROR(D3-H3,"") -> 261 | K3: =IFERROR(_xlfn.XLOOKUP(B3,'00_SKU_Master'!$B$2:$B$379,'00_SKU_Master'!$E$2:$E$379,""),"") -> SplitWing | L3: =IFERROR(_xlfn.XLOOKUP(B3,'00_SKU_Master'!$B$2:$B$379,'00_SKU_Master'!$F$2:$F$379,0),0) -> 23 | M3: =IFERROR(_xlfn.XLOOKUP(K3,'00_Yield_Rates'!$B$2:$B$33,'00_Yield_Rates'!$E$2:$E$33,0)/100,0) -> 0.095 | N3: =IF(AND(ISNUMBER(I3),ISNUMBER(L3)),I3*L3,0) -> 6003 | O3: =IF($B3="","",$B3) -> 203035
B4: {=IFERROR(VALUE(LEFT(C4, MATCH(FALSE, ISNUMBER(MID(C4, ROW(INDIRECT("1:"&LEN(C4)+1)), 1) *1), 0) -1)),"")} -> 203172 | C4: 203172 container | H4: =IFERROR(SUMIF('13_Progress_Track'!$A$2:$A$108,B4,'13_Progress_Track'!$E$2:$E$108),"0") -> 0 | I4: =IFERROR(D4-H4,"") -> 0 | K4: =IFERROR(_xlfn.XLOOKUP(B4,'00_SKU_Master'!$B$2:$B$379,'00_SKU_Master'!$E$2:$E$379,""),"") -> Wing | L4: =IFERROR(_xlfn.XLOOKUP(B4,'00_SKU_Master'!$B$2:$B$379,'00_SKU_Master'!$F$2:$F$379,0),0) -> 25 | M4: =IFERROR(_xlfn.XLOOKUP(K4,'00_Yield_Rates'!$B$2:$B$33,'00_Yield_Rates'!$E$2:$E$33,0)/100,0) -> 0.108 | N4: =IF(AND(ISNUMBER(I4),ISNUMBER(L4)),I4*L4,0) -> 0 | O4: =IF($B4="","",$B4) -> 203172
B5: {=IFERROR(VALUE(LEFT(C5, MATCH(FALSE, ISNUMBER(MID(C5, ROW(INDIRECT("1:"&LEN(C5)+1)), 1) *1), 0) -1)),"")} -> 868 | C5: 868 Spl Wings | D5: 40 | H5: =IFERROR(SUMIF('13_Progress_Track'!$A$2:$A$108,B5,'13_Progress_Track'!$E$2:$E$108),"0") -> 0 | I5: =IFERROR(D5-H5,"") -> 40 | K5: =IFERROR(_xlfn.XLOOKUP(B5,'00_SKU_Master'!$B$2:$B$379,'00_SKU_Master'!$E$2:$E$379,""),"") -> SplitWing | L5: =IFERROR(_xlfn.XLOOKUP(B5,'00_SKU_Master'!$B$2:$B$379,'00_SKU_Master'!$F$2:$F$379,0),0) -> 18 | M5: =IFERROR(_xlfn.XLOOKUP(K5,'00_Yield_Rates'!$B$2:$B$33,'00_Yield_Rates'!$E$2:$E$33,0)/100,0) -> 0.095 | N5: =IF(AND(ISNUMBER(I5),ISNUMBER(L5)),I5*L5,0) -> 720 | O5: =IF($B5="","",$B5) -> 868
B6: {=IFERROR(VALUE(LEFT(C6, MATCH(FALSE, ISNUMBER(MID(C6, ROW(INDIRECT("1:"&LEN(C6)+1)), 1) *1), 0) -1)),"")} -> 200868 | C6: 200868 MB HA SPL WING AC 18KG | D6: 120 | H6: =IFERROR(SUMIF('13_Progress_Track'!$A$2:$A$108,B6,'13_Progress_Track'!$E$2:$E$108),"0") -> 0 | I6: =IFERROR(D6-H6,"") -> 120 | K6: =IFERROR(_xlfn.XLOOKUP(B6,'00_SKU_Master'!$B$2:$B$379,'00_SKU_Master'!$E$2:$E$379,""),"") -> SplitWing | L6: =IFERROR(_xlfn.XLOOKUP(B6,'00_SKU_Master'!$B$2:$B$379,'00_SKU_Master'!$F$2:$F$379,0),0) -> 18 | M6: =IFERROR(_xlfn.XLOOKUP(K6,'00_Yield_Rates'!$B$2:$B$33,'00_Yield_Rates'!$E$2:$E$33,0)/100,0) -> 0.095 | N6: =IF(AND(ISNUMBER(I6),ISNUMBER(L6)),I6*L6,0) -> 2160 | O6: =IF($B6="","",$B6) -> 200868
B7: {=IFERROR(VALUE(LEFT(C7, MATCH(FALSE, ISNUMBER(MID(C7, ROW(INDIRECT("1:"&LEN(C7)+1)), 1) *1), 0) -1)),"")} -> 40021 | C7: 40021 Spl Wings 4x10lb | H7: =IFERROR(SUMIF('13_Progress_Track'!$A$2:$A$108,B7,'13_Progress_Track'!$E$2:$E$108),"0") -> 0 | I7: =IFERROR(D7-H7,"") -> 0 | K7: =IFERROR(_xlfn.XLOOKUP(B7,'00_SKU_Master'!$B$2:$B$379,'00_SKU_Master'!$E$2:$E$379,""),"") | L7: =IFERROR(_xlfn.XLOOKUP(B7,'00_SKU_Master'!$B$2:$B$379,'00_SKU_Master'!$F$2:$F$379,0),0) -> 0 | M7: =IFERROR(_xlfn.XLOOKUP(K7,'00_Yield_Rates'!$B$2:$B$33,'00_Yield_Rates'!$E$2:$E$33,0)/100,0) -> 0 | N7: =IF(AND(ISNUMBER(I7),ISNUMBER(L7)),I7*L7,0) -> 0 | O7: =IF($B7="","",$B7) -> 40021
B8: {=IFERROR(VALUE(LEFT(C8, MATCH(FALSE, ISNUMBER(MID(C8, ROW(INDIRECT("1:"&LEN(C8)+1)), 1) *1), 0) -1)),"")} -> 904 | C8: 904 H. Whole wings | H8: =IFERROR(SUMIF('13_Progress_Track'!$A$2:$A$108,B8,'13_Progress_Track'!$E$2:$E$108),"0") -> 0 | I8: =IFERROR(D8-H8,"") -> 0 | K8: =IFERROR(_xlfn.XLOOKUP(B8,'00_SKU_Master'!$B$2:$B$379,'00_SKU_Master'!$E$2:$E$379,""),"") -> Wing | L8: =IFERROR(_xlfn.XLOOKUP(B8,'00_SKU_Master'!$B$2:$B$379,'00_SKU_Master'!$F$2:$F$379,0),0) -> 18 | M8: =IFERROR(_xlfn.XLOOKUP(K8,'00_Yield_Rates'!$B$2:$B$33,'00_Yield_Rates'!$E$2:$E$33,0)/100,0) -> 0.108 | N8: =IF(AND(ISNUMBER(I8),ISNUMBER(L8)),I8*L8,0) -> 0 | O8: =IF($B8="","",$B8) -> 904
B9: {=IFERROR(VALUE(LEFT(C9, MATCH(FALSE, ISNUMBER(MID(C9, ROW(INDIRECT("1:"&LEN(C9)+1)), 1) *1), 0) -1)),"")} -> 200904 | C9: 200904 H. Whole wings | H9: =IFERROR(SUMIF('13_Progress_Track'!$A$2:$A$108,B9,'13_Progress_Track'!$E$2:$E$108),"0") -> 0 | I9: =IFERROR(D9-H9,"") -> 0 | K9: =IFERROR(_xlfn.XLOOKUP(B9,'00_SKU_Master'!$B$2:$B$379,'00_SKU_Master'!$E$2:$E$379,""),"") -> Wing | L9: =IFERROR(_xlfn.XLOOKUP(B9,'00_SKU_Master'!$B$2:$B$379,'00_SKU_Master'!$F$2:$F$379,0),0) -> 18 | M9: =IFERROR(_xlfn.XLOOKUP(K9,'00_Yield_Rates'!$B$2:$B$33,'00_Yield_Rates'!$E$2:$E$33,0)/100,0) -> 0.108 | N9: =IF(AND(ISNUMBER(I9),ISNUMBER(L9)),I9*L9,0) -> 0 | O9: =IF($B9="","",$B9) -> 200904
B10: {=IFERROR(VALUE(LEFT(C10, MATCH(FALSE, ISNUMBER(MID(C10, ROW(INDIRECT("1:"&LEN(C10)+1)), 1) *1), 0) -1)),"")} -> 895 | C10: 895 Drums | H10: =IFERROR(SUMIF('13_Progress_Track'!$A$2:$A$108,B10,'13_Progress_Track'!$E$2:$E$108),"0") -> 0 | I10: =IFERROR(D10-H10,"") -> 0 | K10: =IFERROR(_xlfn.XLOOKUP(B10,'00_SKU_Master'!$B$2:$B$379,'00_SKU_Master'!$E$2:$E$379,""),"") -> Drum | L10: =IFERROR(_xlfn.XLOOKUP(B10,'00_SKU_Master'!$B$2:$B$379,'00_SKU_Master'!$F$2:$F$379,0),0) -> 18 | M10: =IFERROR(_xlfn.XLOOKUP(K10,'00_Yield_Rates'!$B$2:$B$33,'00_Yield_Rates'!$E$2:$E$33,0)/100,0) -> 0.143 | N10: =IF(AND(ISNUMBER(I10),ISNUMBER(L10)),I10*L10,0) -> 0 | O10: =IF($B10="","",$B10) -> 895
B11: {=IFERROR(VALUE(LEFT(C11, MATCH(FALSE, ISNUMBER(MID(C11, ROW(INDIRECT("1:"&LEN(C11)+1)), 1) *1), 0) -1)),"")} -> 200095 | C11: 200095 H. Drums | D11: 735 | H11: =IFERROR(SUMIF('13_Progress_Track'!$A$2:$A$108,B11,'13_Progress_Track'!$E$2:$E$108),"0") -> 0 | I11: =IFERROR(D11-H11,"") -> 735 | K11: =IFERROR(_xlfn.XLOOKUP(B11,'00_SKU_Master'!$B$2:$B$379,'00_SKU_Master'!$E$2:$E$379,""),"") -> Drum | L11: =IFERROR(_xlfn.XLOOKUP(B11,'00_SKU_Master'!$B$2:$B$379,'00_SKU_Master'!$F$2:$F$379,0),0) -> 18 | M11: =IFERROR(_xlfn.XLOOKUP(K11,'00_Yield_Rates'!$B$2:$B$33,'00_Yield_Rates'!$E$2:$E$33,0)/100,0) -> 0.143 | N11: =IF(AND(ISNUMBER(I11),ISNUMBER(L11)),I11*L11,0) -> 13230 | O11: =IF($B11="","",$B11) -> 200095
B12: {=IFERROR(VALUE(LEFT(C12, MATCH(FALSE, ISNUMBER(MID(C12, ROW(INDIRECT("1:"&LEN(C12)+1)), 1) *1), 0) -1)),"")} -> 160 | C12: 0160 Drums | H12: =IFERROR(SUMIF('13_Progress_Track'!$A$2:$A$108,B12,'13_Progress_Track'!$E$2:$E$108),"0") -> 0 | I12: =IFERROR(D12-H12,"") -> 0 | K12: =IFERROR(_xlfn.XLOOKUP(B12,'00_SKU_Master'!$B$2:$B$379,'00_SKU_Master'!$E$2:$E$379,""),"") -> Drum | L12: =IFERROR(_xlfn.XLOOKUP(B12,'00_SKU_Master'!$B$2:$B$379,'00_SKU_Master'!$F$2:$F$379,0),0) -> 18 | M12: =IFERROR(_xlfn.XLOOKUP(K12,'00_Yield_Rates'!$B$2:$B$33,'00_Yield_Rates'!$E$2:$E$33,0)/100,0) -> 0.143 | N12: =IF(AND(ISNUMBER(I12),ISNUMBER(L12)),I12*L12,0) -> 0 | O12: =IF($B12="","",$B12) -> 160
B13: {=IFERROR(VALUE(LEFT(C13, MATCH(FALSE, ISNUMBER(MID(C13, ROW(INDIRECT("1:"&LEN(C13)+1)), 1) *1), 0) -1)),"")} -> 203271 | C13: 203271 DRUM 110G LESS RET 25KG | H13: =IFERROR(SUMIF('13_Progress_Track'!$A$2:$A$108,B13,'13_Progress_Track'!$E$2:$E$108),"0") -> 0 | I13: =IFERROR(D13-H13,"") -> 0 | K13: =IFERROR(_xlfn.XLOOKUP(B13,'00_SKU_Master'!$B$2:$B$379,'00_SKU_Master'!$E$2:$E$379,""),"") | L13: =IFERROR(_xlfn.XLOOKUP(B13,'00_SKU_Master'!$B$2:$B$379,'00_SKU_Master'!$F$2:$F$379,0),0) -> 0 | M13: =IFERROR(_xlfn.XLOOKUP(K13,'00_Yield_Rates'!$B$2:$B$33,'00_Yield_Rates'!$E$2:$E$33,0)/100,0) -> 0 | N13: =IF(AND(ISNUMBER(I13),ISNUMBER(L13)),I13*L13,0) -> 0 | O13: =IF($B13="","",$B13) -> 203271
B14: {=IFERROR(VALUE(LEFT(C14, MATCH(FALSE, ISNUMBER(MID(C14, ROW(INDIRECT("1:"&LEN(C14)+1)), 1) *1), 0) -1)),"")} -> 159 | C14: 159 BA Legs | D14: 250 | H14: =IFERROR(SUMIF('13_Progress_Track'!$A$2:$A$108,B14,'13_Progress_Track'!$E$2:$E$108),"0") -> 0 | I14: =IFERROR(D14-H14,"") -> 250 | K14: =IFERROR(_xlfn.XLOOKUP(B14,'00_SKU_Master'!$B$2:$B$379,'00_SKU_Master'!$E$2:$E$379,""),"") -> BA | L14: =IFERROR(_xlfn.XLOOKUP(B14,'00_SKU_Master'!$B$2:$B$379,'00_SKU_Master'!$F$2:$F$379,0),0) -> 18 | M14: =IFERROR(_xlfn.XLOOKUP(K14,'00_Yield_Rates'!$B$2:$B$33,'00_Yield_Rates'!$E$2:$E$33,0)/100,0) -> 0.47 | N14: =IF(AND(ISNUMBER(I14),ISNUMBER(L14)),I14*L14,0) -> 4500 | O14: =IF($B14="","",$B14) -> 159
B15: {=IFERROR(VALUE(LEFT(C15, MATCH(FALSE, ISNUMBER(MID(C15, ROW(INDIRECT("1:"&LEN(C15)+1)), 1) *1), 0) -1)),"")} -> 200903 | C15: 200903 H. BA Legs a/c | D15: 150 | H15: =IFERROR(SUMIF('13_Progress_Track'!$A$2:$A$108,B15,'13_Progress_Track'!$E$2:$E$108),"0") -> 0 | I15: =IFERROR(D15-H15,"") -> 150 | K15: =IFERROR(_xlfn.XLOOKUP(B15,'00_SKU_Master'!$B$2:$B$379,'00_SKU_Master'!$E$2:$E$379,""),"") -> BA | L15: =IFERROR(_xlfn.XLOOKUP(B15,'00_SKU_Master'!$B$2:$B$379,'00_SKU_Master'!$F$2:$F$379,0),0) -> 18 | M15: =IFERROR(_xlfn.XLOOKUP(K15,'00_Yield_Rates'!$B$2:$B$33,'00_Yield_Rates'!$E$2:$E$33,0)/100,0) -> 0.47 | N15: =IF(AND(ISNUMBER(I15),ISNUMBER(L15)),I15*L15,0) -> 2700 | O15: =IF($B15="","",$B15) -> 200903
B16: {=IFERROR(VALUE(LEFT(C16, MATCH(FALSE, ISNUMBER(MID(C16, ROW(INDIRECT("1:"&LEN(C16)+1)), 1) *1), 0) -1)),"")} -> 165 | C16: 165 Bnls breast | H16: =IFERROR(SUMIF('13_Progress_Track'!$A$2:$A$108,B16,'13_Progress_Track'!$E$2:$E$108),"0") -> 0 | I16: =IFERROR(D16-H16,"") -> 0 | K16: =IFERROR(_xlfn.XLOOKUP(B16,'00_SKU_Master'!$B$2:$B$379,'00_SKU_Master'!$E$2:$E$379,""),"") -> BSB | L16: =IFERROR(_xlfn.XLOOKUP(B16,'00_SKU_Master'!$B$2:$B$379,'00_SKU_Master'!$F$2:$F$379,0),0) -> 10 | M16: =IFERROR(_xlfn.XLOOKUP(K16,'00_Yield_Rates'!$B$2:$B$33,'00_Yield_Rates'!$E$2:$E$33,0)/100,0) -> 0.235 | N16: =IF(AND(ISNUMBER(I16),ISNUMBER(L16)),I16*L16,0) -> 0 | O16: =IF($B16="","",$B16) -> 165
B17: {=IFERROR(VALUE(LEFT(C17, MATCH(FALSE, ISNUMBER(MID(C17, ROW(INDIRECT("1:"&LEN(C17)+1)), 1) *1), 0) -1)),"")} -> 201894 | C17: 201894 H. Bnls breast | H17: =IFERROR(SUMIF('13_Progress_Track'!$A$2:$A$108,B17,'13_Progress_Track'!$E$2:$E$108),"0") -> 0 | I17: =IFERROR(D17-H17,"") -> 0 | K17: =IFERROR(_xlfn.XLOOKUP(B17,'00_SKU_Master'!$B$2:$B$379,'00_SKU_Master'!$E$2:$E$379,""),"") -> BSB | L17: =IFERROR(_xlfn.XLOOKUP(B17,'00_SKU_Master'!$B$2:$B$379,'00_SKU_Master'!$F$2:$F$379,0),0) -> 18 | M17: =IFERROR(_xlfn.XLOOKUP(K17,'00_Yield_Rates'!$B$2:$B$33,'00_Yield_Rates'!$E$2:$E$33,0)/100,0) -> 0.235 | N17: =IF(AND(ISNUMBER(I17),ISNUMBER(L17)),I17*L17,0) -> 0 | O17: =IF($B17="","",$B17) -> 201894
B18: {=IFERROR(VALUE(LEFT(C18, MATCH(FALSE, ISNUMBER(MID(C18, ROW(INDIRECT("1:"&LEN(C18)+1)), 1) *1), 0) -1)),"")} -> 201895 | C18: 201895 H. Bnls breast | H18: =IFERROR(SUMIF('13_Progress_Track'!$A$2:$A$108,B18,'13_Progress_Track'!$E$2:$E$108),"0") -> 0 | I18: =IFERROR(D18-H18,"") -> 0 | K18: =IFERROR(_xlfn.XLOOKUP(B18,'00_SKU_Master'!$B$2:$B$379,'00_SKU_Master'!$E$2:$E$379,""),"") -> BSB | L18: =IFERROR(_xlfn.XLOOKUP(B18,'00_SKU_Master'!$B$2:$B$379,'00_SKU_Master'!$F$2:$F$379,0),0) -> 18 | M18: =IFERROR(_xlfn.XLOOKUP(K18,'00_Yield_Rates'!$B$2:$B$33,'00_Yield_Rates'!$E$2:$E$33,0)/100,0) -> 0.235 | N18: =IF(AND(ISNUMBER(I18),ISNUMBER(L18)),I18*L18,0) -> 0 | O18: =IF($B18="","",$B18) -> 201895
B19: {=IFERROR(VALUE(LEFT(C19, MATCH(FALSE, ISNUMBER(MID(C19, ROW(INDIRECT("1:"&LEN(C19)+1)), 1) *1), 0) -1)),"")} -> 834 | C19: 834 Bone in Thigh | H19: =IFERROR(SUMIF('13_Progress_Track'!$A$2:$A$108,B19,'13_Progress_Track'!$E$2:$E$108),"0") -> 0 | I19: =IFERROR(D19-H19,"") -> 0 | K19: =IFERROR(_xlfn.XLOOKUP(B19,'00_SKU_Master'!$B$2:$B$379,'00_SKU_Master'!$E$2:$E$379,""),"") -> Thigh | L19: =IFERROR(_xlfn.XLOOKUP(B19,'00_SKU_Master'!$B$2:$B$379,'00_SKU_Master'!$F$2:$F$379,0),0) -> 18 | M19: =IFERROR(_xlfn.XLOOKUP(K19,'00_Yield_Rates'!$B$2:$B$33,'00_Yield_Rates'!$E$2:$E$33,0)/100,0) -> 0.175 | N19: =IF(AND(ISNUMBER(I19),ISNUMBER(L19)),I19*L19,0) -> 0 | O19: =IF($B19="","",$B19) -> 834
B20: {=IFERROR(VALUE(LEFT(C20, MATCH(FALSE, ISNUMBER(MID(C20, ROW(INDIRECT("1:"&LEN(C20)+1)), 1) *1), 0) -1)),"")} -> 200902 | C20: 200902 Bone in Thigh | D20: 65 | H20: =IFERROR(SUMIF('13_Progress_Track'!$A$2:$A$108,B20,'13_Progress_Track'!$E$2:$E$108),"0") -> 0 | I20: =IFERROR(D20-H20,"") -> 65 | K20: =IFERROR(_xlfn.XLOOKUP(B20,'00_SKU_Master'!$B$2:$B$379,'00_SKU_Master'!$E$2:$E$379,""),"") -> Thigh | L20: =IFERROR(_xlfn.XLOOKUP(B20,'00_SKU_Master'!$B$2:$B$379,'00_SKU_Master'!$F$2:$F$379,0),0) -> 18 | M20: =IFERROR(_xlfn.XLOOKUP(K20,'00_Yield_Rates'!$B$2:$B$33,'00_Yield_Rates'!$E$2:$E$33,0)/100,0) -> 0.175 | N20: =IF(AND(ISNUMBER(I20),ISNUMBER(L20)),I20*L20,0) -> 1170 | O20: =IF($B20="","",$B20) -> 200902
B21: {=IFERROR(VALUE(LEFT(C21, MATCH(FALSE, ISNUMBER(MID(C21, ROW(INDIRECT("1:"&LEN(C21)+1)), 1) *1), 0) -1)),"")} -> 161 | C21: 161 Bone in Thigh | H21: =IFERROR(SUMIF('13_Progress_Track'!$A$2:$A$108,B21,'13_Progress_Track'!$E$2:$E$108),"0") -> 0 | I21: =IFERROR(D21-H21,"") -> 0 | K21: =IFERROR(_xlfn.XLOOKUP(B21,'00_SKU_Master'!$B$2:$B$379,'00_SKU_Master'!$E$2:$E$379,""),"") -> Thigh | L21: =IFERROR(_xlfn.XLOOKUP(B21,'00_SKU_Master'!$B$2:$B$379,'00_SKU_Master'!$F$2:$F$379,0),0) -> 18 | M21: =IFERROR(_xlfn.XLOOKUP(K21,'00_Yield_Rates'!$B$2:$B$33,'00_Yield_Rates'!$E$2:$E$33,0)/100,0) -> 0.175 | N21: =IF(AND(ISNUMBER(I21),ISNUMBER(L21)),I21*L21,0) -> 0 | O21: =IF($B21="","",$B21) -> 161
B22: {=IFERROR(VALUE(LEFT(C22, MATCH(FALSE, ISNUMBER(MID(C22, ROW(INDIRECT("1:"&LEN(C22)+1)), 1) *1), 0) -1)),"")} -> 200064 | C22: 200064 H. bnls thighs | D22: 60 | H22: =IFERROR(SUMIF('13_Progress_Track'!$A$2:$A$108,B22,'13_Progress_Track'!$E$2:$E$108),"0") -> 0 | I22: =IFERROR(D22-H22,"") -> 60 | K22: =IFERROR(_xlfn.XLOOKUP(B22,'00_SKU_Master'!$B$2:$B$379,'00_SKU_Master'!$E$2:$E$379,""),"") -> ThighMeat | L22: =IFERROR(_xlfn.XLOOKUP(B22,'00_SKU_Master'!$B$2:$B$379,'00_SKU_Master'!$F$2:$F$379,0),0) -> 5 | M22: =IFERROR(_xlfn.XLOOKUP(K22,'00_Yield_Rates'!$B$2:$B$33,'00_Yield_Rates'!$E$2:$E$33,0)/100,0) -> 0.115 | N22: =IF(AND(ISNUMBER(I22),ISNUMBER(L22)),I22*L22,0) -> 300 | O22: =IF($B22="","",$B22) -> 200064
B23: {=IFERROR(VALUE(LEFT(C23, MATCH(FALSE, ISNUMBER(MID(C23, ROW(INDIRECT("1:"&LEN(C23)+1)), 1) *1), 0) -1)),"")} | H23: =IFERROR(SUMIF('13_Progress_Track'!$A$2:$A$108,B23,'13_Progress_Track'!$E$2:$E$108),"0") -> 0 | I23: =IFERROR(D23-H23,"") -> 0 | K23: =IFERROR(_xlfn.XLOOKUP(B23,'00_SKU_Master'!$B$2:$B$379,'00_SKU_Master'!$E$2:$E$379,""),"") | L23: =IFERROR(_xlfn.XLOOKUP(B23,'00_SKU_Master'!$B$2:$B$379,'00_SKU_Master'!$F$2:$F$379,0),0) -> 0 | M23: =IFERROR(_xlfn.XLOOKUP(K23,'00_Yield_Rates'!$B$2:$B$33,'00_Yield_Rates'!$E$2:$E$33,0)/100,0) -> 0 | N23: =IF(AND(ISNUMBER(I23),ISNUMBER(L23)),I23*L23,0) -> 0 | O23: =IF($B23="","",$B23)
B24: {=IFERROR(VALUE(LEFT(C24, MATCH(FALSE, ISNUMBER(MID(C24, ROW(INDIRECT("1:"&LEN(C24)+1)), 1) *1), 0) -1)),"")} | H24: =IFERROR(SUMIF('13_Progress_Track'!$A$2:$A$108,B24,'13_Progress_Track'!$E$2:$E$108),"0") -> 0 | I24: =IFERROR(D24-H24,"") -> 0 | K24: =IFERROR(_xlfn.XLOOKUP(B24,'00_SKU_Master'!$B$2:$B$379,'00_SKU_Master'!$E$2:$E$379,""),"") | L24: =IFERROR(_xlfn.XLOOKUP(B24,'00_SKU_Master'!$B$2:$B$379,'00_SKU_Master'!$F$2:$F$379,0),0) -> 0 | M24: =IFERROR(_xlfn.XLOOKUP(K24,'00_Yield_Rates'!$B$2:$B$33,'00_Yield_Rates'!$E$2:$E$33,0)/100,0) -> 0 | N24: =IF(AND(ISNUMBER(I24),ISNUMBER(L24)),I24*L24,0) -> 0 | O24: =IF($B24="","",$B24)
B25: {=IFERROR(VALUE(LEFT(C25, MATCH(FALSE, ISNUMBER(MID(C25, ROW(INDIRECT("1:"&LEN(C25)+1)), 1) *1), 0) -1)),"")} | H25: =IFERROR(SUMIF('13_Progress_Track'!$A$2:$A$108,B25,'13_Progress_Track'!$E$2:$E$108),"0") -> 0 | I25: =IFERROR(D25-H25,"") -> 0 | K25: =IFERROR(_xlfn.XLOOKUP(B25,'00_SKU_Master'!$B$2:$B$379,'00_SKU_Master'!$E$2:$E$379,""),"") | L25: =IFERROR(_xlfn.XLOOKUP(B25,'00_SKU_Master'!$B$2:$B$379,'00_SKU_Master'!$F$2:$F$379,0),0) -> 0 | M25: =IFERROR(_xlfn.XLOOKUP(K25,'00_Yield_Rates'!$B$2:$B$33,'00_Yield_Rates'!$E$2:$E$33,0)/100,0) -> 0 | N25: =IF(AND(ISNUMBER(I25),ISNUMBER(L25)),I25*L25,0) -> 0 | O25: =IF($B25="","",$B25)
B26: {=IFERROR(VALUE(LEFT(C26, MATCH(FALSE, ISNUMBER(MID(C26, ROW(INDIRECT("1:"&LEN(C26)+1)), 1) *1), 0) -1)),"")} | H26: =IFERROR(SUMIF('13_Progress_Track'!$A$2:$A$108,B26,'13_Progress_Track'!$E$2:$E$108),"0") -> 0 | I26: =IFERROR(D26-H26,"") -> 0 | K26: =IFERROR(_xlfn.XLOOKUP(B26,'00_SKU_Master'!$B$2:$B$379,'00_SKU_Master'!$E$2:$E$379,""),"") | L26: =IFERROR(_xlfn.XLOOKUP(B26,'00_SKU_Master'!$B$2:$B$379,'00_SKU_Master'!$F$2:$F$379,0),0) -> 0 | M26: =IFERROR(_xlfn.XLOOKUP(K26,'00_Yield_Rates'!$B$2:$B$33,'00_Yield_Rates'!$E$2:$E$33,0)/100,0) -> 0 | N26: =IF(AND(ISNUMBER(I26),ISNUMBER(L26)),I26*L26,0) -> 0 | O26: =IF($B26="","",$B26)
B27: {=IFERROR(VALUE(LEFT(C27, MATCH(FALSE, ISNUMBER(MID(C27, ROW(INDIRECT("1:"&LEN(C27)+1)), 1) *1), 0) -1)),"")} | H27: =IFERROR(SUMIF('13_Progress_Track'!$A$2:$A$108,B27,'13_Progress_Track'!$E$2:$E$108),"0") -> 0 | I27: =IFERROR(D27-H27,"") -> 0 | K27: =IFERROR(_xlfn.XLOOKUP(B27,'00_SKU_Master'!$B$2:$B$379,'00_SKU_Master'!$E$2:$E$379,""),"") | L27: =IFERROR(_xlfn.XLOOKUP(B27,'00_SKU_Master'!$B$2:$B$379,'00_SKU_Master'!$F$2:$F$379,0),0) -> 0 | M27: =IFERROR(_xlfn.XLOOKUP(K27,'00_Yield_Rates'!$B$2:$B$33,'00_Yield_Rates'!$E$2:$E$33,0)/100,0) -> 0 | N27: =IF(AND(ISNUMBER(I27),ISNUMBER(L27)),I27*L27,0) -> 0 | O27: =IF($B27="","",$B27)
B28: {=IFERROR(VALUE(LEFT(C28, MATCH(FALSE, ISNUMBER(MID(C28, ROW(INDIRECT("1:"&LEN(C28)+1)), 1) *1), 0) -1)),"")} | H28: =IFERROR(SUMIF('13_Progress_Track'!$A$2:$A$108,B28,'13_Progress_Track'!$E$2:$E$108),"0") -> 0 | I28: =IFERROR(D28-H28,"") -> 0 | K28: =IFERROR(_xlfn.XLOOKUP(B28,'00_SKU_Master'!$B$2:$B$379,'00_SKU_Master'!$E$2:$E$379,""),"") | L28: =IFERROR(_xlfn.XLOOKUP(B28,'00_SKU_Master'!$B$2:$B$379,'00_SKU_Master'!$F$2:$F$379,0),0) -> 0 | M28: =IFERROR(_xlfn.XLOOKUP(K28,'00_Yield_Rates'!$B$2:$B$33,'00_Yield_Rates'!$E$2:$E$33,0)/100,0) -> 0 | N28: =IF(AND(ISNUMBER(I28),ISNUMBER(L28)),I28*L28,0) -> 0 | O28: =IF($B28="","",$B28)
B29: {=IFERROR(VALUE(LEFT(C29, MATCH(FALSE, ISNUMBER(MID(C29, ROW(INDIRECT("1:"&LEN(C29)+1)), 1) *1), 0) -1)),"")} | H29: =IFERROR(SUMIF('13_Progress_Track'!$A$2:$A$108,B29,'13_Progress_Track'!$E$2:$E$108),"0") -> 0 | I29: =IFERROR(D29-H29,"") -> 0 | K29: =IFERROR(_xlfn.XLOOKUP(B29,'00_SKU_Master'!$B$2:$B$379,'00_SKU_Master'!$E$2:$E$379,""),"") | L29: =IFERROR(_xlfn.XLOOKUP(B29,'00_SKU_Master'!$B$2:$B$379,'00_SKU_Master'!$F$2:$F$379,0),0) -> 0 | M29: =IFERROR(_xlfn.XLOOKUP(K29,'00_Yield_Rates'!$B$2:$B$33,'00_Yield_Rates'!$E$2:$E$33,0)/100,0) -> 0 | N29: =IF(AND(ISNUMBER(I29),ISNUMBER(L29)),I29*L29,0) -> 0 | O29: =IF($B29="","",$B29)
B30: 2233 | H30: =IFERROR(SUMIF('13_Progress_Track'!$A$2:$A$108,B30,'13_Progress_Track'!$E$2:$E$108),"0") -> 0 | I30: =IFERROR(D30-H30,"") -> 0 | K30: =IFERROR(_xlfn.XLOOKUP(B30,'00_SKU_Master'!$B$2:$B$379,'00_SKU_Master'!$E$2:$E$379,""),"") -> SplitWing | L30: =IFERROR(_xlfn.XLOOKUP(B30,'00_SKU_Master'!$B$2:$B$379,'00_SKU_Master'!$F$2:$F$379,0),0) -> 20 | M30: =IFERROR(_xlfn.XLOOKUP(K30,'00_Yield_Rates'!$B$2:$B$33,'00_Yield_Rates'!$E$2:$E$33,0)/100,0) -> 0.095 | N30: =IF(AND(ISNUMBER(I30),ISNUMBER(L30)),I30*L30,0) -> 0 | O30: =IF($B30="","",$B30) -> 2233
B31: 2235 | D31: 180 | H31: =IFERROR(SUMIF('13_Progress_Track'!$A$2:$A$108,B31,'13_Progress_Track'!$E$2:$E$108),"0") -> 0 | I31: =IFERROR(D31-H31,"") -> 180 | K31: =IFERROR(_xlfn.XLOOKUP(B31,'00_SKU_Master'!$B$2:$B$379,'00_SKU_Master'!$E$2:$E$379,""),"") -> Drum | L31: =IFERROR(_xlfn.XLOOKUP(B31,'00_SKU_Master'!$B$2:$B$379,'00_SKU_Master'!$F$2:$F$379,0),0) -> 20 | M31: =IFERROR(_xlfn.XLOOKUP(K31,'00_Yield_Rates'!$B$2:$B$33,'00_Yield_Rates'!$E$2:$E$33,0)/100,0) -> 0.143 | N31: =IF(AND(ISNUMBER(I31),ISNUMBER(L31)),I31*L31,0) -> 3600 | O31: =IF($B31="","",$B31) -> 2235
B32: 2236 | H32: =IFERROR(SUMIF('13_Progress_Track'!$A$2:$A$108,B32,'13_Progress_Track'!$E$2:$E$108),"0") -> 0 | I32: =IFERROR(D32-H32,"") -> 0 | K32: =IFERROR(_xlfn.XLOOKUP(B32,'00_SKU_Master'!$B$2:$B$379,'00_SKU_Master'!$E$2:$E$379,""),"") -> BSB | L32: =IFERROR(_xlfn.XLOOKUP(B32,'00_SKU_Master'!$B$2:$B$379,'00_SKU_Master'!$F$2:$F$379,0),0) -> 20 | M32: =IFERROR(_xlfn.XLOOKUP(K32,'00_Yield_Rates'!$B$2:$B$33,'00_Yield_Rates'!$E$2:$E$33,0)/100,0) -> 0.235 | N32: =IF(AND(ISNUMBER(I32),ISNUMBER(L32)),I32*L32,0) -> 0 | O32: =IF($B32="","",$B32) -> 2236
B33: 423002 | H33: =IFERROR(SUMIF('13_Progress_Track'!$A$2:$A$108,B33,'13_Progress_Track'!$E$2:$E$108),"0") -> 0 | I33: =IFERROR(D33-H33,"") -> 0 | K33: =IFERROR(_xlfn.XLOOKUP(B33,'00_SKU_Master'!$B$2:$B$379,'00_SKU_Master'!$E$2:$E$379,""),"") | L33: =IFERROR(_xlfn.XLOOKUP(B33,'00_SKU_Master'!$B$2:$B$379,'00_SKU_Master'!$F$2:$F$379,0),0) -> 0 | M33: =IFERROR(_xlfn.XLOOKUP(K33,'00_Yield_Rates'!$B$2:$B$33,'00_Yield_Rates'!$E$2:$E$33,0)/100,0) -> 0 | N33: =IF(AND(ISNUMBER(I33),ISNUMBER(L33)),I33*L33,0) -> 0 | O33: =IF($B33="","",$B33) -> 423002
B34: 203010 | H34: =IFERROR(SUMIF('13_Progress_Track'!$A$2:$A$108,B34,'13_Progress_Track'!$E$2:$E$108),"0") -> 0 | I34: =IFERROR(D34-H34,"") -> 0 | K34: =IFERROR(_xlfn.XLOOKUP(B34,'00_SKU_Master'!$B$2:$B$379,'00_SKU_Master'!$E$2:$E$379,""),"") | L34: =IFERROR(_xlfn.XLOOKUP(B34,'00_SKU_Master'!$B$2:$B$379,'00_SKU_Master'!$F$2:$F$379,0),0) -> 0 | M34: =IFERROR(_xlfn.XLOOKUP(K34,'00_Yield_Rates'!$B$2:$B$33,'00_Yield_Rates'!$E$2:$E$33,0)/100,0) -> 0 | N34: =IF(AND(ISNUMBER(I34),ISNUMBER(L34)),I34*L34,0) -> 0 | O34: =IF($B34="","",$B34) -> 203010
B35: 423625 | H35: =IFERROR(SUMIF('13_Progress_Track'!$A$2:$A$108,B35,'13_Progress_Track'!$E$2:$E$108),"0") -> 0 | I35: =IFERROR(D35-H35,"") -> 0 | K35: =IFERROR(_xlfn.XLOOKUP(B35,'00_SKU_Master'!$B$2:$B$379,'00_SKU_Master'!$E$2:$E$379,""),"") | L35: =IFERROR(_xlfn.XLOOKUP(B35,'00_SKU_Master'!$B$2:$B$379,'00_SKU_Master'!$F$2:$F$379,0),0) -> 0 | M35: =IFERROR(_xlfn.XLOOKUP(K35,'00_Yield_Rates'!$B$2:$B$33,'00_Yield_Rates'!$E$2:$E$33,0)/100,0) -> 0 | N35: =IF(AND(ISNUMBER(I35),ISNUMBER(L35)),I35*L35,0) -> 0 | O35: =IF($B35="","",$B35) -> 423625
B36: 203624 | H36: =IFERROR(SUMIF('13_Progress_Track'!$A$2:$A$108,B36,'13_Progress_Track'!$E$2:$E$108),"0") -> 0 | I36: =IFERROR(D36-H36,"") -> 0 | K36: =IFERROR(_xlfn.XLOOKUP(B36,'00_SKU_Master'!$B$2:$B$379,'00_SKU_Master'!$E$2:$E$379,""),"") -> FAT | L36: =IFERROR(_xlfn.XLOOKUP(B36,'00_SKU_Master'!$B$2:$B$379,'00_SKU_Master'!$F$2:$F$379,0),0) -> 25 | M36: =IFERROR(_xlfn.XLOOKUP(K36,'00_Yield_Rates'!$B$2:$B$33,'00_Yield_Rates'!$E$2:$E$33,0)/100,0) -> 0 | N36: =IF(AND(ISNUMBER(I36),ISNUMBER(L36)),I36*L36,0) -> 0 | O36: =IF($B36="","",$B36) -> 203624
O37: =IF($B37="","",$B37)
O38: =IF($B38="","",$B38)
O39: =IF($B39="","",$B39)
O40: =IF($B40="","",$B40)
O41: =IF($B41="","",$B41)
...

Sheet 04_Bagging_Order
C1: =SUM(C3:C20) -> 570 | D1: =SUM(D3:D20) -> 0 | E1: =SUM(E3:E20) -> 0 | F1: =SUM(F3:F20) -> 0 | I1: =SUMIF(I3:I23,">0") -> 570 | J1: =SUM(J3:J20) -> 0 | K1: =SUMIF(K3:K21,">0") -> 570 | N1: Totals: | Q1: =SUM(Q3:Q20) -> 5264.4496
B2: SKU | H2: SKU | I2: Today's | J2: Completed | K2: Remaining | N2: Product_Group | O2: Avg_Case_Weight | P2: Yield_Rate | Q2: WIP_kg | R2: RAW_WIP_CODE
B3: ='00_SKU_Master'!B358 -> 2050 | C3: 117 | H3: =B3 -> 2050 | I3: =SUM(C3:F3) -> 117 | J3: =SUMIF('13_Progress_Track'!$A$2:$A$108,B3,'13_Progress_Track'!$E$2:$E$108) -> 0 | K3: =I3-J3 -> 117 | N3: =IFERROR(_xlfn.XLOOKUP(B3,'00_SKU_Master'!$B$2:$B$379,'00_SKU_Master'!$E$2:$E$379,""),"") -> BA | O3: =IFERROR(_xlfn.SINGLE(_xlfn.XLOOKUP(B3,'00_SKU_Master'!$B$2:$B$379,'00_SKU_Master'!$F$2:$F$379,0)),0) -> 11.333345 | P3: =IFERROR(_xlfn.XLOOKUP(N3,'00_Yield_Rates'!$B$2:$B$33,'00_Yield_Rates'!$E$2:$E$33,0)/100,0) -> 0.47 | Q3: =IF(AND(ISNUMBER(I3),ISNUMBER(O3)),I3*O3,0) -> 1326.0014 | R3: =IFERROR(_xlfn.XLOOKUP($H3,'00_SKU_Master'!$B$2:$B$379,'00_SKU_Master'!$C$2:$C$379,""),"") -> 61062
B4: ='00_SKU_Master'!B359 -> 2051 | C4: 185 | H4: =B4 -> 2051 | I4: =SUM(C4:F4) -> 185 | J4: =SUMIF('13_Progress_Track'!$A$2:$A$108,B4,'13_Progress_Track'!$E$2:$E$108) -> 0 | K4: =I4-J4 -> 185 | N4: =IFERROR(_xlfn.XLOOKUP(B4,'00_SKU_Master'!$B$2:$B$379,'00_SKU_Master'!$E$2:$E$379,""),"") -> Drum | O4: =IFERROR(_xlfn.SINGLE(_xlfn.XLOOKUP(B4,'00_SKU_Master'!$B$2:$B$379,'00_SKU_Master'!$F$2:$F$379,0)),0) -> 10.945225 | P4: =IFERROR(_xlfn.XLOOKUP(N4,'00_Yield_Rates'!$B$2:$B$33,'00_Yield_Rates'!$E$2:$E$33,0)/100,0) -> 0.143 | Q4: =IF(AND(ISNUMBER(I4),ISNUMBER(O4)),I4*O4,0) -> 2024.8667 | R4: =IFERROR(_xlfn.XLOOKUP($H4,'00_SKU_Master'!$B$2:$B$379,'00_SKU_Master'!$C$2:$C$379,""),"") -> 61073
B5: ='00_SKU_Master'!B360 -> 2081 | C5: 83 | H5: =B5 -> 2081 | I5: =SUM(C5:F5) -> 83 | J5: =SUMIF('13_Progress_Track'!$A$2:$A$108,B5,'13_Progress_Track'!$E$2:$E$108) -> 0 | K5: =I5-J5 -> 83 | N5: =IFERROR(_xlfn.XLOOKUP(B5,'00_SKU_Master'!$B$2:$B$379,'00_SKU_Master'!$E$2:$E$379,""),"") -> Wing | O5: =IFERROR(_xlfn.SINGLE(_xlfn.XLOOKUP(B5,'00_SKU_Master'!$B$2:$B$379,'00_SKU_Master'!$F$2:$F$379,0)),0) -> 11.244537 | P5: =IFERROR(_xlfn.XLOOKUP(N5,'00_Yield_Rates'!$B$2:$B$33,'00_Yield_Rates'!$E$2:$E$33,0)/100,0) -> 0.108 | Q5: =IF(AND(ISNUMBER(I5),ISNUMBER(O5)),I5*O5,0) -> 933.29661 | R5: =IFERROR(_xlfn.XLOOKUP($H5,'00_SKU_Master'!$B$2:$B$379,'00_SKU_Master'!$C$2:$C$379,""),"") -> 61018
B6: ='00_SKU_Master'!B361 -> 7113 | C6: 0 | H6: =B6 -> 7113 | I6: =SUM(C6:F6) -> 0 | J6: =SUMIF('13_Progress_Track'!$A$2:$A$108,B6,'13_Progress_Track'!$E$2:$E$108) -> 0 | K6: =I6-J6 -> 0 | N6: =IFERROR(_xlfn.XLOOKUP(B6,'00_SKU_Master'!$B$2:$B$379,'00_SKU_Master'!$E$2:$E$379,""),"") -> 0 | O6: =IFERROR(_xlfn.SINGLE(_xlfn.XLOOKUP(B6,'00_SKU_Master'!$B$2:$B$379,'00_SKU_Master'!$F$2:$F$379,0)),0) -> 12.853 | P6: =IFERROR(_xlfn.XLOOKUP(N6,'00_Yield_Rates'!$B$2:$B$33,'00_Yield_Rates'!$E$2:$E$33,0)/100,0) -> 0 | Q6: =IF(AND(ISNUMBER(I6),ISNUMBER(O6)),I6*O6,0) -> 0 | R6: =IFERROR(_xlfn.XLOOKUP($H6,'00_SKU_Master'!$B$2:$B$379,'00_SKU_Master'!$C$2:$C$379,""),"") -> W-Chicken
B7: ='00_SKU_Master'!B362 -> 200179 | C7: 0 | H7: =B7 -> 200179 | I7: =SUM(C7:F7) -> 0 | J7: =SUMIF('13_Progress_Track'!$A$2:$A$108,B7,'13_Progress_Track'!$E$2:$E$108) -> 0 | K7: =I7-J7 -> 0 | N7: =IFERROR(_xlfn.XLOOKUP(B7,'00_SKU_Master'!$B$2:$B$379,'00_SKU_Master'!$E$2:$E$379,""),"") -> BA | O7: =IFERROR(_xlfn.SINGLE(_xlfn.XLOOKUP(B7,'00_SKU_Master'!$B$2:$B$379,'00_SKU_Master'!$F$2:$F$379,0)),0) -> 0 | P7: =IFERROR(_xlfn.XLOOKUP(N7,'00_Yield_Rates'!$B$2:$B$33,'00_Yield_Rates'!$E$2:$E$33,0)/100,0) -> 0.47 | Q7: =IF(AND(ISNUMBER(I7),ISNUMBER(O7)),I7*O7,0) -> 0 | R7: =IFERROR(_xlfn.XLOOKUP($H7,'00_SKU_Master'!$B$2:$B$379,'00_SKU_Master'!$C$2:$C$379,""),"") -> 61062
B8: ='00_SKU_Master'!B363 -> 200182 | C8: 35 | H8: =B8 -> 200182 | I8: =SUM(C8:F8) -> 35 | J8: =SUMIF('13_Progress_Track'!$A$2:$A$108,B8,'13_Progress_Track'!$E$2:$E$108) -> 0 | K8: =I8-J8 -> 35 | N8: =IFERROR(_xlfn.XLOOKUP(B8,'00_SKU_Master'!$B$2:$B$379,'00_SKU_Master'!$E$2:$E$379,""),"") -> Wing | O8: =IFERROR(_xlfn.SINGLE(_xlfn.XLOOKUP(B8,'00_SKU_Master'!$B$2:$B$379,'00_SKU_Master'!$F$2:$F$379,0)),0) -> 9.9302222 | P8: =IFERROR(_xlfn.XLOOKUP(N8,'00_Yield_Rates'!$B$2:$B$33,'00_Yield_Rates'!$E$2:$E$33,0)/100,0) -> 0.108 | Q8: =IF(AND(ISNUMBER(I8),ISNUMBER(O8)),I8*O8,0) -> 347.55778 | R8: =IFERROR(_xlfn.XLOOKUP($H8,'00_SKU_Master'!$B$2:$B$379,'00_SKU_Master'!$C$2:$C$379,""),"") -> 61018
B9: ='00_SKU_Master'!B364 -> 200183 | C9: 36 | H9: =B9 -> 200183 | I9: =SUM(C9:F9) -> 36 | J9: =SUMIF('13_Progress_Track'!$A$2:$A$108,B9,'13_Progress_Track'!$E$2:$E$108) -> 0 | K9: =I9-J9 -> 36 | N9: =IFERROR(_xlfn.XLOOKUP(B9,'00_SKU_Master'!$B$2:$B$379,'00_SKU_Master'!$E$2:$E$379,""),"") -> BA | O9: =IFERROR(_xlfn.SINGLE(_xlfn.XLOOKUP(B9,'00_SKU_Master'!$B$2:$B$379,'00_SKU_Master'!$F$2:$F$379,0)),0) -> 9.0926639 | P9: =IFERROR(_xlfn.XLOOKUP(N9,'00_Yield_Rates'!$B$2:$B$33,'00_Yield_Rates'!$E$2:$E$33,0)/100,0) -> 0.47 | Q9: =IF(AND(ISNUMBER(I9),ISNUMBER(O9)),I9*O9,0) -> 327.3359 | R9: =IFERROR(_xlfn.XLOOKUP($H9,'00_SKU_Master'!$B$2:$B$379,'00_SKU_Master'!$C$2:$C$379,""),"") -> 61062
B10: ='00_SKU_Master'!B365 -> 200184 | C10: 34 | H10: =B10 -> 200184 | I10: =SUM(C10:F10) -> 34 | J10: =SUMIF('13_Progress_Track'!$A$2:$A$108,B10,'13_Progress_Track'!$E$2:$E$108) -> 0 | K10: =I10-J10 -> 34 | N10: =IFERROR(_xlfn.XLOOKUP(B10,'00_SKU_Master'!$B$2:$B$379,'00_SKU_Master'!$E$2:$E$379,""),"") -> 0 | O10: =IFERROR(_xlfn.SINGLE(_xlfn.XLOOKUP(B10,'00_SKU_Master'!$B$2:$B$379,'00_SKU_Master'!$F$2:$F$379,0)),0) -> 8.982093 | P10: =IFERROR(_xlfn.XLOOKUP(N10,'00_Yield_Rates'!$B$2:$B$33,'00_Yield_Rates'!$E$2:$E$33,0)/100,0) -> 0 | Q10: =IF(AND(ISNUMBER(I10),ISNUMBER(O10)),I10*O10,0) -> 305.39116 | R10: =IFERROR(_xlfn.XLOOKUP($H10,'00_SKU_Master'!$B$2:$B$379,'00_SKU_Master'!$C$2:$C$379,""),"") -> 61073
B11: ='00_SKU_Master'!B366 -> 2511 | C11: 0 | H11: =B11 -> 2511 | I11: =SUM(C11:F11) -> 0 | J11: =SUMIF('13_Progress_Track'!$A$2:$A$108,B11,'13_Progress_Track'!$E$2:$E$108) -> 0 | K11: =I11-J11 -> 0 | N11: =IFERROR(_xlfn.XLOOKUP(B11,'00_SKU_Master'!$B$2:$B$379,'00_SKU_Master'!$E$2:$E$379,""),"") -> Wing | O11: =IFERROR(_xlfn.SINGLE(_xlfn.XLOOKUP(B11,'00_SKU_Master'!$B$2:$B$379,'00_SKU_Master'!$F$2:$F$379,0)),0) -> 14 | P11: =IFERROR(_xlfn.XLOOKUP(N11,'00_Yield_Rates'!$B$2:$B$33,'00_Yield_Rates'!$E$2:$E$33,0)/100,0) -> 0.108 | Q11: =IF(AND(ISNUMBER(I11),ISNUMBER(O11)),I11*O11,0) -> 0 | R11: =IFERROR(_xlfn.XLOOKUP($H11,'00_SKU_Master'!$B$2:$B$379,'00_SKU_Master'!$C$2:$C$379,""),"") -> 61014B
B12: ='00_SKU_Master'!B367 -> 1077 | C12: 0 | H12: =B12 -> 1077 | I12: =SUM(C12:F12) -> 0 | J12: =SUMIF('13_Progress_Track'!$A$2:$A$108,B12,'13_Progress_Track'!$E$2:$E$108) -> 0 | K12: =I12-J12 -> 0 | N12: =IFERROR(_xlfn.XLOOKUP(B12,'00_SKU_Master'!$B$2:$B$379,'00_SKU_Master'!$E$2:$E$379,""),"") -> 0 | O12: =IFERROR(_xlfn.SINGLE(_xlfn.XLOOKUP(B12,'00_SKU_Master'!$B$2:$B$379,'00_SKU_Master'!$F$2:$F$379,0)),0) -> 0 | P12: =IFERROR(_xlfn.XLOOKUP(N12,'00_Yield_Rates'!$B$2:$B$33,'00_Yield_Rates'!$E$2:$E$33,0)/100,0) -> 0 | Q12: =IF(AND(ISNUMBER(I12),ISNUMBER(O12)),I12*O12,0) -> 0 | R12: =IFERROR(_xlfn.XLOOKUP($H12,'00_SKU_Master'!$B$2:$B$379,'00_SKU_Master'!$C$2:$C$379,""),"") -> 0
B13: ='00_SKU_Master'!B368 -> 1078 | C13: 0 | H13: =B13 -> 1078 | I13: =SUM(C13:F13) -> 0 | J13: =SUMIF('13_Progress_Track'!$A$2:$A$108,B13,'13_Progress_Track'!$E$2:$E$108) -> 0 | K13: =I13-J13 -> 0 | N13: =IFERROR(_xlfn.XLOOKUP(B13,'00_SKU_Master'!$B$2:$B$379,'00_SKU_Master'!$E$2:$E$379,""),"") -> 0 | O13: =IFERROR(_xlfn.SINGLE(_xlfn.XLOOKUP(B13,'00_SKU_Master'!$B$2:$B$379,'00_SKU_Master'!$F$2:$F$379,0)),0) -> 0 | P13: =IFERROR(_xlfn.XLOOKUP(N13,'00_Yield_Rates'!$B$2:$B$33,'00_Yield_Rates'!$E$2:$E$33,0)/100,0) -> 0 | Q13: =IF(AND(ISNUMBER(I13),ISNUMBER(O13)),I13*O13,0) -> 0 | R13: =IFERROR(_xlfn.XLOOKUP($H13,'00_SKU_Master'!$B$2:$B$379,'00_SKU_Master'!$C$2:$C$379,""),"") -> 0
B14: ='00_SKU_Master'!B369 -> 1080 | C14: 0 | H14: =B14 -> 1080 | I14: =SUM(C14:F14) -> 0 | J14: =SUMIF('13_Progress_Track'!$A$2:$A$108,B14,'13_Progress_Track'!$E$2:$E$108) -> 0 | K14: =I14-J14 -> 0 | N14: =IFERROR(_xlfn.XLOOKUP(B14,'00_SKU_Master'!$B$2:$B$379,'00_SKU_Master'!$E$2:$E$379,""),"") -> 0 | O14: =IFERROR(_xlfn.SINGLE(_xlfn.XLOOKUP(B14,'00_SKU_Master'!$B$2:$B$379,'00_SKU_Master'!$F$2:$F$379,0)),0) -> 0 | P14: =IFERROR(_xlfn.XLOOKUP(N14,'00_Yield_Rates'!$B$2:$B$33,'00_Yield_Rates'!$E$2:$E$33,0)/100,0) -> 0 | Q14: =IF(AND(ISNUMBER(I14),ISNUMBER(O14)),I14*O14,0) -> 0 | R14: =IFERROR(_xlfn.XLOOKUP($H14,'00_SKU_Master'!$B$2:$B$379,'00_SKU_Master'!$C$2:$C$379,""),"") -> 0
... B20: ='00_SKU_Master'!B375 -> 7176 | C20: 0 | H20: =B20 -> 7176 | I20: =SUM(C20:F20) -> 0 | J20: =SUMIF('13_Progress_Track'!$A$2:$A$108,B20,'13_Progress_Track'!$E$2:$E$108) -> 0 | K20: =I20-J20 -> 0 | N20: =IFERROR(_xlfn.XLOOKUP(B20,'00_SKU_Master'!$B$2:$B$379,'00_SKU_Master'!$E$2:$E$379,""),"") -> BA | O20: =IFERROR(_xlfn.SINGLE(_xlfn.XLOOKUP(B20,'00_SKU_Master'!$B$2:$B$379,'00_SKU_Master'!$F$2:$F$379,0)),0) -> 0 | P20: =IFERROR(_xlfn.XLOOKUP(N20,'00_Yield_Rates'!$B$2:$B$33,'00_Yield_Rates'!$E$2:$E$33,0)/100,0) -> 0.47 | Q20: =IF(AND(ISNUMBER(I20),ISNUMBER(O20)),I20*O20,0) -> 0 | R20: =IFERROR(_xlfn.XLOOKUP($H20,'00_SKU_Master'!$B$2:$B$379,'00_SKU_Master'!$C$2:$C$379,""),"") -> 61062

Sheet 05_Daily_Orders
B2: Description | C2: SKU | D2: Cases Ordered - Orginal | E2: Cases Added On | F2: Cases Completed | G2: Extra Cases Produced | H2: Cases Remaining | I2: WIP_Code | J2: WIP_kg | K2: Tray/Min | L2: Speed | M2: Category | N2: Today's Order
B3: =IF(C3="","",_xlfn.XLOOKUP(C3,'00_SKU_Master'!$B$2:$B$2000,'00_SKU_Master'!$J$2:$J$2000,"")) -> MS LCL BSHB PET8 PP | C3: {=_xlfn.SORTBY(_xlfn._xlws.FILTER('00_SKU_Master'!$B$2:$B$2000,('00_SKU_Master'!$A$2:$A$2000="Tray_Pack")*('00_SKU_Master'!$P$2:$P$2000="Y")),_xlfn._xlws.FILTER('00_SKU_Master'!$Q$2:$Q$2000,('00_SKU_Master'!$A$2:$A$2000="Tray_Pack")*('00_SKU_Master'!$P$2:$P$2000="Y")),1)} -> 260 | D3: =_xlfn.XLOOKUP(C3,'02_TrayPack_Order'!$B$3:$B$265,'02_TrayPack_Order'!$D$3:$D$265) -> 0 | E3: =_xlfn.XLOOKUP(C3,'02_TrayPack_Order'!$B$3:$B$265,'02_TrayPack_Order'!$M$3:$M$265,0) -> 0 | F3: =SUMIF('13_Progress_Track'!$A$2:$A$108,C3,'13_Progress_Track'!$E$2:$E$108) -> 0 | G3: =IF(F3>(D3+E3),(F3-(D3+E3)),0) -> 0 | H3: =IF(G3>0,0,D3+E3-F3) -> 0 | I3: =_xlfn.IFNA(_xlfn.XLOOKUP(C3,'00_SKU_Master'!$B$2:$B$2000,'00_SKU_Master'!$C$2:$C$2000),"") -> 61050#2 | J3: =IFERROR(_xlfn.XLOOKUP(C3,'00_SKU_Master'!$B$2:$B$2000,'00_SKU_Master'!$F$2:$F$2000,0)*N3,0) -> 0 | K3: =_xlfn.IFNA(_xlfn.XLOOKUP(C3,'00_SKU_Master'!$B$2:$B$2000,'00_SKU_Master'!$H$2:$H$2000,0),"") -> PET 8 | L3: =_xlfn.IFNA(_xlfn.XLOOKUP(C3,'00_SKU_Master'!$B$2:$B$2000,'00_SKU_Master'!$K$2:$K$2000,0),"") -> Fast | M3: =_xlfn.XLOOKUP(C3,'00_SKU_Master'!$B$2:$B$2000,'00_SKU_Master'!$D$2:$D$2000) -> LCL | N3: =IF((D3-F3)<0,0,D3-F3) -> 0
B4: =IF(C4="","",_xlfn.XLOOKUP(C4,'00_SKU_Master'!$B$2:$B$2000,'00_SKU_Master'!$J$2:$J$2000,"")) -> MS LEG BA ST | C4: 331 | D4: =_xlfn.XLOOKUP(C4,'02_TrayPack_Order'!$B$3:$B$265,'02_TrayPack_Order'!$D$3:$D$265) -> 10 | E4: =_xlfn.XLOOKUP(C4,'02_TrayPack_Order'!$B$3:$B$265,'02_TrayPack_Order'!$M$3:$M$265,0) -> 0 | F4: =SUMIF('13_Progress_Track'!$A$2:$A$108,C4,'13_Progress_Track'!$E$2:$E$108) -> 0 | G4: =IF(F4>(D4+E4),(F4-(D4+E4)),0) -> 0 | H4: =IF(G4>0,0,D4+E4-F4) -> 10 | I4: =_xlfn.IFNA(_xlfn.XLOOKUP(C4,'00_SKU_Master'!$B$2:$B$2000,'00_SKU_Master'!$C$2:$C$2000),"") -> 61061 | J4: =IFERROR(_xlfn.XLOOKUP(C4,'00_SKU_Master'!$B$2:$B$2000,'00_SKU_Master'!$F$2:$F$2000,0)*N4,0) -> 100.08899 | K4: =_xlfn.IFNA(_xlfn.XLOOKUP(C4,'00_SKU_Master'!$B$2:$B$2000,'00_SKU_Master'!$H$2:$H$2000,0),"") -> ST 3XP | L4: =_xlfn.IFNA(_xlfn.XLOOKUP(C4,'00_SKU_Master'!$B$2:$B$2000,'00_SKU_Master'!$K$2:$K$2000,0),"") -> Fast | M4: =_xlfn.XLOOKUP(C4,'00_SKU_Master'!$B$2:$B$2000,'00_SKU_Master'!$D$2:$D$2000) -> METRO | N4: =IF((D4-F4)<0,0,D4-F4) -> 10
B5: =IF(C5="","",_xlfn.XLOOKUP(C5,'00_SKU_Master'!$B$2:$B$2000,'00_SKU_Master'!$J$2:$J$2000,"")) -> PB HB ST | C5: 349 | D5: =_xlfn.XLOOKUP(C5,'02_TrayPack_Order'!$B$3:$B$265,'02_TrayPack_Order'!$D$3:$D$265) -> 0 | E5: =_xlfn.XLOOKUP(C5,'02_TrayPack_Order'!$B$3:$B$265,'02_TrayPack_Order'!$M$3:$M$265,0) -> 0 | F5: =SUMIF('13_Progress_Track'!$A$2:$A$108,C5,'13_Progress_Track'!$E$2:$E$108) -> 0 | G5: =IF(F5>(D5+E5),(F5-(D5+E5)),0) -> 0 | H5: =IF(G5>0,0,D5+E5-F5) -> 0 | I5: =_xlfn.IFNA(_xlfn.XLOOKUP(C5,'00_SKU_Master'!$B$2:$B$2000,'00_SKU_Master'!$C$2:$C$2000),"") -> 61040#2 | J5: =IFERROR(_xlfn.XLOOKUP(C5,'00_SKU_Master'!$B$2:$B$2000,'00_SKU_Master'!$F$2:$F$2000,0)*N5,0) -> 0 | K5: =_xlfn.IFNA(_xlfn.XLOOKUP(C5,'00_SKU_Master'!$B$2:$B$2000,'00_SKU_Master'!$H$2:$H$2000,0),"") -> ST 3XP | L5: =_xlfn.IFNA(_xlfn.XLOOKUP(C5,'00_SKU_Master'!$B$2:$B$2000,'00_SKU_Master'!$K$2:$K$2000,0),"") -> Fast | M5: =_xlfn.XLOOKUP(C5,'00_SKU_Master'!$B$2:$B$2000,'00_SKU_Master'!$D$2:$D$2000) -> FB | N5: =IF((D5-F5)<0,0,D5-F5) -> 0
B6: =IF(C6="","",_xlfn.XLOOKUP(C6,'00_SKU_Master'!$B$2:$B$2000,'00_SKU_Master'!$J$2:$J$2000,"")) -> MS BACK ST PP | C6: 484 | D6: =_xlfn.XLOOKUP(C6,'02_TrayPack_Order'!$B$3:$B$265,'02_TrayPack_Order'!$D$3:$D$265) -> 0 | E6: =_xlfn.XLOOKUP(C6,'02_TrayPack_Order'!$B$3:$B$265,'02_TrayPack_Order'!$M$3:$M$265,0) -> 28 | F6: =SUMIF('13_Progress_Track'!$A$2:$A$108,C6,'13_Progress_Track'!$E$2:$E$108) -> 0 | G6: =IF(F6>(D6+E6),(F6-(D6+E6)),0) -> 0 | H6: =IF(G6>0,0,D6+E6-F6) -> 28 | I6: =_xlfn.IFNA(_xlfn.XLOOKUP(C6,'00_SKU_Master'!$B$2:$B$2000,'00_SKU_Master'!$C$2:$C$2000),"") -> 61121 | J6: =IFERROR(_xlfn.XLOOKUP(C6,'00_SKU_Master'!$B$2:$B$2000,'00_SKU_Master'!$F$2:$F$2000,0)*N6,0) -> 0 | K6: =_xlfn.IFNA(_xlfn.XLOOKUP(C6,'00_SKU_Master'!$B$2:$B$2000,'00_SKU_Master'!$H$2:$H$2000,0),"") -> ST 3XP | L6: =_xlfn.IFNA(_xlfn.XLOOKUP(C6,'00_SKU_Master'!$B$2:$B$2000,'00_SKU_Master'!$K$2:$K$2000,0),"") -> Fast | M6: =_xlfn.XLOOKUP(C6,'00_SKU_Master'!$B$2:$B$2000,'00_SKU_Master'!$D$2:$D$2000) -> FB | N6: =IF((D6-F6)<0,0,D6-F6) -> 0
B7: =IF(C7="","",_xlfn.XLOOKUP(C7,'00_SKU_Master'!$B$2:$B$2000,'00_SKU_Master'!$J$2:$J$2000,"")) -> MS BSC BSTHIGH LT PP | C7: 784 | D7: =_xlfn.XLOOKUP(C7,'02_TrayPack_Order'!$B$3:$B$265,'02_TrayPack_Order'!$D$3:$D$265) -> 0 | E7: =_xlfn.XLOOKUP(C7,'02_TrayPack_Order'!$B$3:$B$265,'02_TrayPack_Order'!$M$3:$M$265,0) -> 85 | F7: =SUMIF('13_Progress_Track'!$A$2:$A$108,C7,'13_Progress_Track'!$E$2:$E$108) -> 0 | G7: =IF(F7>(D7+E7),(F7-(D7+E7)),0) -> 0 | H7: =IF(G7>0,0,D7+E7-F7) -> 85 | I7: =_xlfn.IFNA(_xlfn.XLOOKUP(C7,'00_SKU_Master'!$B$2:$B$2000,'00_SKU_Master'!$C$2:$C$2000),"") -> 61086#2 | J7: =IFERROR(_xlfn.XLOOKUP(C7,'00_SKU_Master'!$B$2:$B$2000,'00_SKU_Master'!$F$2:$F$2000,0)*N7,0) -> 0 | K7: =_xlfn.IFNA(_xlfn.XLOOKUP(C7,'00_SKU_Master'!$B$2:$B$2000,'00_SKU_Master'!$H$2:$H$2000,0),"") -> LT 8XP | L7: =_xlfn.IFNA(_xlfn.XLOOKUP(C7,'00_SKU_Master'!$B$2:$B$2000,'00_SKU_Master'!$K$2:$K$2000,0),"") -> Slow | M7: =_xlfn.XLOOKUP(C7,'00_SKU_Master'!$B$2:$B$2000,'00_SKU_Master'!$D$2:$D$2000) -> FB | N7: =IF((D7-F7)<0,0,D7-F7) -> 0
B8: =IF(C8="","",_xlfn.XLOOKUP(C8,'00_SKU_Master'!$B$2:$B$2000,'00_SKU_Master'!$J$2:$J$2000,"")) -> PB BSC HB FT PP 8/BOX | C8: 946 | D8: =_xlfn.XLOOKUP(C8,'02_TrayPack_Order'!$B$3:$B$265,'02_TrayPack_Order'!$D$3:$D$265) -> 0 | E8: =_xlfn.XLOOKUP(C8,'02_TrayPack_Order'!$B$3:$B$265,'02_TrayPack_Order'!$M$3:$M$265,0) -> 0 | F8: =SUMIF('13_Progress_Track'!$A$2:$A$108,C8,'13_Progress_Track'!$E$2:$E$108) -> 0 | G8: =IF(F8>(D8+E8),(F8-(D8+E8)),0) -> 0 | H8: =IF(G8>0,0,D8+E8-F8) -> 0 | I8: =_xlfn.IFNA(_xlfn.XLOOKUP(C8,'00_SKU_Master'!$B$2:$B$2000,'00_SKU_Master'!$C$2:$C$2000),"") -> 61040#2 | J8: =IFERROR(_xlfn.XLOOKUP(C8,'00_SKU_Master'!$B$2:$B$2000,'00_SKU_Master'!$F$2:$F$2000,0)*N8,0) -> 0 | K8: =_xlfn.IFNA(_xlfn.XLOOKUP(C8,'00_SKU_Master'!$B$2:$B$2000,'00_SKU_Master'!$H$2:$H$2000,0),"") -> LT 14D | L8: =_xlfn.IFNA(_xlfn.XLOOKUP(C8,'00_SKU_Master'!$B$2:$B$2000,'00_SKU_Master'!$K$2:$K$2000,0),"") -> Fast | M8: =_xlfn.XLOOKUP(C8,'00_SKU_Master'!$B$2:$B$2000,'00_SKU_Master'!$D$2:$D$2000) -> FB | N8: =IF((D8-F8)<0,0,D8-F8) -> 0
B9: =IF(C9="","",_xlfn.XLOOKUP(C9,'00_SKU_Master'!$B$2:$B$2000,'00_SKU_Master'!$J$2:$J$2000,"")) -> PB BSC DRUM FT PP | C9: 956 | D9: =_xlfn.XLOOKUP(C9,'02_TrayPack_Order'!$B$3:$B$265,'02_TrayPack_Order'!$D$3:$D$265) -> 0 | E9: =_xlfn.XLOOKUP(C9,'02_TrayPack_Order'!$B$3:$B$265,'02_TrayPack_Order'!$M$3:$M$265,0) -> 0 | F9: =SUMIF('13_Progress_Track'!$A$2:$A$108,C9,'13_Progress_Track'!$E$2:$E$108) -> 0 | G9: =IF(F9>(D9+E9),(F9-(D9+E9)),0) -> 0 | H9: =IF(G9>0,0,D9+E9-F9) -> 0 | I9: =_xlfn.IFNA(_xlfn.XLOOKUP(C9,'00_SKU_Master'!$B$2:$B$2000,'00_SKU_Master'!$C$2:$C$2000),"") -> 61072#2 | J9: =IFERROR(_xlfn.XLOOKUP(C9,'00_SKU_Master'!$B$2:$B$2000,'00_SKU_Master'!$F$2:$F$2000,0)*N9,0) -> 0 | K9: =_xlfn.IFNA(_xlfn.XLOOKUP(C9,'00_SKU_Master'!$B$2:$B$2000,'00_SKU_Master'!$H$2:$H$2000,0),"") -> LT 14D | L9: =_xlfn.IFNA(_xlfn.XLOOKUP(C9,'00_SKU_Master'!$B$2:$B$2000,'00_SKU_Master'!$K$2:$K$2000,0),"") -> Fast | M9: =_xlfn.XLOOKUP(C9,'00_SKU_Master'!$B$2:$B$2000,'00_SKU_Master'!$D$2:$D$2000) -> FB | N9: =IF((D9-F9)<0,0,D9-F9) -> 0
B10: =IF(C10="","",_xlfn.XLOOKUP(C10,'00_SKU_Master'!$B$2:$B$2000,'00_SKU_Master'!$J$2:$J$2000,"")) -> PB BSC THIGH FT PP | C10: 957 | D10: =_xlfn.XLOOKUP(C10,'02_TrayPack_Order'!$B$3:$B$265,'02_TrayPack_Order'!$D$3:$D$265) -> 0 | E10: =_xlfn.XLOOKUP(C10,'02_TrayPack_Order'!$B$3:$B$265,'02_TrayPack_Order'!$M$3:$M$265,0) -> 0 | F10: =SUMIF('13_Progress_Track'!$A$2:$A$108,C10,'13_Progress_Track'!$E$2:$E$108) -> 0 | G10: =IF(F10>(D10+E10),(F10-(D10+E10)),0) -> 0 | H10: =IF(G10>0,0,D10+E10-F10) -> 0 | I10: =_xlfn.IFNA(_xlfn.XLOOKUP(C10,'00_SKU_Master'!$B$2:$B$2000,'00_SKU_Master'!$C$2:$C$2000),"") -> 61082 | J10: =IFERROR(_xlfn.XLOOKUP(C10,'00_SKU_Master'!$B$2:$B$2000,'00_SKU_Master'!$F$2:$F$2000,0)*N10,0) -> 0 | K10: =_xlfn.IFNA(_xlfn.XLOOKUP(C10,'00_SKU_Master'!$B$2:$B$2000,'00_SKU_Master'!$H$2:$H$2000,0),"") -> LT 14D | L10: =_xlfn.IFNA(_xlfn.XLOOKUP(C10,'00_SKU_Master'!$B$2:$B$2000,'00_SKU_Master'!$K$2:$K$2000,0),"") -> Fast | M10: =_xlfn.XLOOKUP(C10,'00_SKU_Master'!$B$2:$B$2000,'00_SKU_Master'!$D$2:$D$2000) -> FB | N10: =IF((D10-F10)<0,0,D10-F10) -> 0
B11: =IF(C11="","",_xlfn.XLOOKUP(C11,'00_SKU_Master'!$B$2:$B$2000,'00_SKU_Master'!$J$2:$J$2000,"")) -> PB BACK ST | C11: 1023 | D11: =_xlfn.XLOOKUP(C11,'02_TrayPack_Order'!$B$3:$B$265,'02_TrayPack_Order'!$D$3:$D$265) -> 5 | E11: =_xlfn.XLOOKUP(C11,'02_TrayPack_Order'!$B$3:$B$265,'02_TrayPack_Order'!$M$3:$M$265,0) -> 0 | F11: =SUMIF('13_Progress_Track'!$A$2:$A$108,C11,'13_Progress_Track'!$E$2:$E$108) -> 0 | G11: =IF(F11>(D11+E11),(F11-(D11+E11)),0) -> 0 | H11: =IF(G11>0,0,D11+E11-F11) -> 5 | I11: =_xlfn.IFNA(_xlfn.XLOOKUP(C11,'00_SKU_Master'!$B$2:$B$2000,'00_SKU_Master'!$C$2:$C$2000),"") -> 61121 | J11: =IFERROR(_xlfn.XLOOKUP(C11,'00_SKU_Master'!$B$2:$B$2000,'00_SKU_Master'!$F$2:$F$2000,0)*N11,0) -> 46.850628 | K11: =_xlfn.IFNA(_xlfn.XLOOKUP(C11,'00_SKU_Master'!$B$2:$B$2000,'00_SKU_Master'!$H$2:$H$2000,0),"") -> ST 3XP | L11: =_xlfn.IFNA(_xlfn.XLOOKUP(C11,'00_SKU_Master'!$B$2:$B$2000,'00_SKU_Master'!$K$2:$K$2000,0),"") -> Fast | M11: =_xlfn.XLOOKUP(C11,'00_SKU_Master'!$B$2:$B$2000,'00_SKU_Master'!$D$2:$D$2000) -> METRO | N11: =IF((D11-F11)<0,0,D11-F11) -> 5
B12: =IF(C12="","",_xlfn.XLOOKUP(C12,'00_SKU_Master'!$B$2:$B$2000,'00_SKU_Master'!$J$2:$J$2000,"")) -> MS BSC FFTF BSHB AC 3D PP | C12: 1830 | D12: =_xlfn.XLOOKUP(C12,'02_TrayPack_Order'!$B$3:$B$265,'02_TrayPack_Order'!$D$3:$D$265) -> 59 | E12: =_xlfn.XLOOKUP(C12,'02_TrayPack_Order'!$B$3:$B$265,'02_TrayPack_Order'!$M$3:$M$265,0) -> 52 | F12: =SUMIF('13_Progress_Track'!$A$2:$A$108,C12,'13_Progress_Track'!$E$2:$E$108) -> 0 | G12: =IF(F12>(D12+E12),(F12-(D12+E12)),0) -> 0 | H12: =IF(G12>0,0,D12+E12-F12) -> 111 | I12: =_xlfn.IFNA(_xlfn.XLOOKUP(C12,'00_SKU_Master'!$B$2:$B$2000,'00_SKU_Master'!$C$2:$C$2000),"") -> 61050F | J12: =IFERROR(_xlfn.XLOOKUP(C12,'00_SKU_Master'!$B$2:$B$2000,'00_SKU_Master'!$F$2:$F$2000,0)*N12,0) -> 211.6175 | K12: =_xlfn.IFNA(_xlfn.XLOOKUP(C12,'00_SKU_Master'!$B$2:$B$2000,'00_SKU_Master'!$H$2:$H$2000,0),"") -> ST 3D | L12: =_xlfn.IFNA(_xlfn.XLOOKUP(C12,'00_SKU_Master'!$B$2:$B$2000,'00_SKU_Master'!$K$2:$K$2000,0),"") -> Fast | M12: =_xlfn.XLOOKUP(C12,'00_SKU_Master'!$B$2:$B$2000,'00_SKU_Master'!$D$2:$D$2000) -> FB | N12: =IF((D12-F12)<0,0,D12-F12) -> 59
