Workbook

Sheet 00_SKU_Master
A1: Dept | B1: SKU | C1: RAW_WIP_CODE | D1: Customer | E1: Product_Group | F1: Avg_Case_Weight | G1: Trays_Per_Case | H1: Tray_Type | I1: Tray_Size | J1: SKU_Desc | K1: Tray Pack Speed | L1: Package_Type | M1: STD | N1: Class | O1: Weight | P1: Column1 | R1: ORDER | S1: RAW Request_KG | T1: Yield
A2: Cut_up | B2: 64 | D2: Bulk Pack | E2: ThighMeat | F2: 5 | J2: MB BSTHIGH AC BG 5KG | N2: SILVER | R2: =_xludf.IFNA(_xlfn.XLOOKUP(Table3[[#This Row],[SKU]],'03_BulkPack_Order'!$A$2:$A$67,'03_BulkPack_Order'!C:C),"") -> #NAME? | S2: =IFERROR(R2*1,"") | T2: =_xludf.IFNA(_xlfn.XLOOKUP(Table3[[#This Row],[SKU]],'00_Yield_Rates'!$B$2:$B$17,'00_Yield_Rates'!$E$2:$E$17),"") -> #NAME?
A3: Cut_up | B3: 65 | D3: Bulk Pack | E3: BSB | F3: 5 | J3: MB BSHB AC RND 5KG | N3: SILVER | R3: =_xludf.IFNA(_xlfn.XLOOKUP(Table3[[#This Row],[SKU]],'03_BulkPack_Order'!$A$2:$A$67,'03_BulkPack_Order'!C:C),"") -> #NAME? | S3: =IFERROR(R3*1,"") | T3: =_xludf.IFNA(_xlfn.XLOOKUP(Table3[[#This Row],[SKU]],'00_Yield_Rates'!$B$2:$B$17,'00_Yield_Rates'!$E$2:$E$17),"") -> #NAME?
A4: Cut_up | B4: 159 | D4: Bulk Pack | E4: BA | J4: MS LEG BA 18KG | N4: SILVER | R4: =_xludf.IFNA(_xlfn.XLOOKUP(Table3[[#This Row],[SKU]],'03_BulkPack_Order'!$A$2:$A$67,'03_BulkPack_Order'!C:C),"") -> #NAME? | S4: =IFERROR(R4*1,"") | T4: =_xludf.IFNA(_xlfn.XLOOKUP(Table3[[#This Row],[SKU]],'00_Yield_Rates'!$B$2:$B$17,'00_Yield_Rates'!$E$2:$E$17),"") -> #NAME?
A5: Cut_up | B5: 160 | D5: Bulk Pack | E5: DRUM | J5: MS DRUM 18KG | N5: SILVER | R5: =_xludf.IFNA(_xlfn.XLOOKUP(Table3[[#This Row],[SKU]],'03_BulkPack_Order'!$A$2:$A$67,'03_BulkPack_Order'!C:C),"") -> #NAME? | S5: =IFERROR(R5*1,"") | T5: =_xludf.IFNA(_xlfn.XLOOKUP(Table3[[#This Row],[SKU]],'00_Yield_Rates'!$B$2:$B$17,'00_Yield_Rates'!$E$2:$E$17),"") -> #NAME?
A6: Cut_up | B6: 161 | D6: Bulk Pack | E6: Thigh | J6: MB THIGH 20KG | N6: SILVER | R6: =_xludf.IFNA(_xlfn.XLOOKUP(Table3[[#This Row],[SKU]],'03_BulkPack_Order'!$A$2:$A$67,'03_BulkPack_Order'!C:C),"") -> #NAME? | S6: =IFERROR(R6*1,"") | T6: =_xludf.IFNA(_xlfn.XLOOKUP(Table3[[#This Row],[SKU]],'00_Yield_Rates'!$B$2:$B$17,'00_Yield_Rates'!$E$2:$E$17),"") -> #NAME?
A7: Cut_up | B7: 165 | D7: Bulk Pack | E7: BSB | F7: 10 | J7: MB BSHB AC RND 10KG | N7: SILVER | R7: =_xludf.IFNA(_xlfn.XLOOKUP(Table3[[#This Row],[SKU]],'03_BulkPack_Order'!$A$2:$A$67,'03_BulkPack_Order'!C:C),"") -> #NAME? | S7: =IFERROR(R7*1,"") | T7: =_xludf.IFNA(_xlfn.XLOOKUP(Table3[[#This Row],[SKU]],'00_Yield_Rates'!$B$2:$B$17,'00_Yield_Rates'!$E$2:$E$17),"") -> #NAME?
A8: Cut_up | B8: 834 | D8: Bulk Pack | E8: Thigh | F8: 18 | J8: THIGH 18KG | N8: SILVER | R8: =_xludf.IFNA(_xlfn.XLOOKUP(Table3[[#This Row],[SKU]],'03_BulkPack_Order'!$A$2:$A$67,'03_BulkPack_Order'!C:C),"") -> #NAME? | S8: =IFERROR(R8*1,"") | T8: =_xludf.IFNA(_xlfn.XLOOKUP(Table3[[#This Row],[SKU]],'00_Yield_Rates'!$B$2:$B$17,'00_Yield_Rates'!$E$2:$E$17),"") -> #NAME?
A9: Cut_up | B9: 868 | D9: Bulk Pack | E9: SplitWing | F9: 18 | J9: MB SPL WING 18KG | N9: SILVER | R9: =_xludf.IFNA(_xlfn.XLOOKUP(Table3[[#This Row],[SKU]],'03_BulkPack_Order'!$A$2:$A$67,'03_BulkPack_Order'!C:C),"") -> #NAME? | S9: =IFERROR(R9*1,"") | T9: =_xludf.IFNA(_xlfn.XLOOKUP(Table3[[#This Row],[SKU]],'00_Yield_Rates'!$B$2:$B$17,'00_Yield_Rates'!$E$2:$E$17),"") -> #NAME?
A10: Cut_up | B10: 895 | D10: Bulk Pack | E10: DRUM | J10: MB DRUM AC 18KG | N10: GOLD | R10: =_xludf.IFNA(_xlfn.XLOOKUP(Table3[[#This Row],[SKU]],'03_BulkPack_Order'!$A$2:$A$67,'03_BulkPack_Order'!C:C),"") -> #NAME? | S10: =IFERROR(R10*1,"") | T10: =_xludf.IFNA(_xlfn.XLOOKUP(Table3[[#This Row],[SKU]],'00_Yield_Rates'!$B$2:$B$17,'00_Yield_Rates'!$E$2:$E$17),"") -> #NAME?
A11: Cut_up | B11: 902 | D11: Bulk Pack | E11: Thigh | N11: SILVER | R11: =_xludf.IFNA(_xlfn.XLOOKUP(Table3[[#This Row],[SKU]],'03_BulkPack_Order'!$A$2:$A$67,'03_BulkPack_Order'!C:C),"") -> #NAME? | S11: =IFERROR(R11*1,"") | T11: =_xludf.IFNA(_xlfn.XLOOKUP(Table3[[#This Row],[SKU]],'00_Yield_Rates'!$B$2:$B$17,'00_Yield_Rates'!$E$2:$E$17),"") -> #NAME?
A12: Cut_up | B12: 904 | D12: Bulk Pack | E12: WING | F12: 18 | J12: MB WING AC 18KG | N12: SILVER | R12: =_xludf.IFNA(_xlfn.XLOOKUP(Table3[[#This Row],[SKU]],'03_BulkPack_Order'!$A$2:$A$67,'03_BulkPack_Order'!C:C),"") -> #NAME? | S12: =IFERROR(R12*1,"") | T12: =_xludf.IFNA(_xlfn.XLOOKUP(Table3[[#This Row],[SKU]],'00_Yield_Rates'!$B$2:$B$17,'00_Yield_Rates'!$E$2:$E$17),"") -> #NAME?
A13: Cut_up | B13: 1026 | D13: Bulk Pack | E13: WING | N13: SILVER | R13: =_xludf.IFNA(_xlfn.XLOOKUP(Table3[[#This Row],[SKU]],'03_BulkPack_Order'!$A$2:$A$67,'03_BulkPack_Order'!C:C),"") -> #NAME? | S13: =IFERROR(R13*1,"") | T13: =_xludf.IFNA(_xlfn.XLOOKUP(Table3[[#This Row],[SKU]],'00_Yield_Rates'!$B$2:$B$17,'00_Yield_Rates'!$E$2:$E$17),"") -> #NAME?
A14: Cut_up | B14: 1081 | D14: Bulk Pack | E14: BSB | N14: SILVER | R14: =_xludf.IFNA(_xlfn.XLOOKUP(Table3[[#This Row],[SKU]],'03_BulkPack_Order'!$A$2:$A$67,'03_BulkPack_Order'!C:C),"") -> #NAME? | S14: =IFERROR(R14*1,"") | T14: =_xludf.IFNA(_xlfn.XLOOKUP(Table3[[#This Row],[SKU]],'00_Yield_Rates'!$B$2:$B$17,'00_Yield_Rates'!$E$2:$E$17),"") -> #NAME?
A15: Cut_up | B15: 1446 | D15: Bulk Pack | E15: BSB | N15: SILVER | R15: =_xludf.IFNA(_xlfn.XLOOKUP(Table3[[#This Row],[SKU]],'03_BulkPack_Order'!$A$2:$A$67,'03_BulkPack_Order'!C:C),"") -> #NAME? | S15: =IFERROR(R15*1,"") | T15: =_xludf.IFNA(_xlfn.XLOOKUP(Table3[[#This Row],[SKU]],'00_Yield_Rates'!$B$2:$B$17,'00_Yield_Rates'!$E$2:$E$17),"") -> #NAME?
A16: Cut_up | B16: 1887 | D16: Bulk Pack | E16: BA | N16: GOLD | R16: =_xludf.IFNA(_xlfn.XLOOKUP(Table3[[#This Row],[SKU]],'03_BulkPack_Order'!$A$2:$A$67,'03_BulkPack_Order'!C:C),"") -> #NAME? | S16: =IFERROR(R16*1,"") | T16: =_xludf.IFNA(_xlfn.XLOOKUP(Table3[[#This Row],[SKU]],'00_Yield_Rates'!$B$2:$B$17,'00_Yield_Rates'!$E$2:$E$17),"") -> #NAME?
A17: Cut_up | B17: 1888 | D17: Bulk Pack | E17: SplitBreast | N17: GOLD | R17: =_xludf.IFNA(_xlfn.XLOOKUP(Table3[[#This Row],[SKU]],'03_BulkPack_Order'!$A$2:$A$67,'03_BulkPack_Order'!C:C),"") -> #NAME? | S17: =IFERROR(R17*1,"") | T17: =_xludf.IFNA(_xlfn.XLOOKUP(Table3[[#This Row],[SKU]],'00_Yield_Rates'!$B$2:$B$17,'00_Yield_Rates'!$E$2:$E$17),"") -> #NAME?
A18: Cut_up | B18: 1894 | D18: Bulk Pack | E18: BSB | J18: MB BSHB RND AC 18KG | N18: SILVER | R18: =_xludf.IFNA(_xlfn.XLOOKUP(Table3[[#This Row],[SKU]],'03_BulkPack_Order'!$A$2:$A$67,'03_BulkPack_Order'!C:C),"") -> #NAME? | S18: =IFERROR(R18*1,"") | T18: =_xludf.IFNA(_xlfn.XLOOKUP(Table3[[#This Row],[SKU]],'00_Yield_Rates'!$B$2:$B$17,'00_Yield_Rates'!$E$2:$E$17),"") -> #NAME?
A19: Cut_up | B19: 2233 | D19: Bulk Pack | E19: SplitWing | J19: 24839 MB COS SPL WING AC | N19: GOLD | R19: =_xludf.IFNA(_xlfn.XLOOKUP(Table3[[#This Row],[SKU]],'03_BulkPack_Order'!$A$2:$A$67,'03_BulkPack_Order'!C:C),"") -> #NAME? | S19: =IFERROR(R19*1,"") | T19: =_xludf.IFNA(_xlfn.XLOOKUP(Table3[[#This Row],[SKU]],'00_Yield_Rates'!$B$2:$B$17,'00_Yield_Rates'!$E$2:$E$17),"") -> #NAME?
A20: Cut_up | B20: 2235 | D20: Bulk Pack | E20: DRUM | N20: GOLD | R20: =_xludf.IFNA(_xlfn.XLOOKUP(Table3[[#This Row],[SKU]],'03_BulkPack_Order'!$A$2:$A$67,'03_BulkPack_Order'!C:C),"") -> #NAME? | S20: =IFERROR(R20*1,"") | T20: =_xludf.IFNA(_xlfn.XLOOKUP(Table3[[#This Row],[SKU]],'00_Yield_Rates'!$B$2:$B$17,'00_Yield_Rates'!$E$2:$E$17),"") -> #NAME?
A21: Cut_up | B21: 2236 | D21: Bulk Pack | E21: BSB | F21: 20 | J21: 17219 MB COS BSHB AC | N21: PLATINUM | R21: =_xludf.IFNA(_xlfn.XLOOKUP(Table3[[#This Row],[SKU]],'03_BulkPack_Order'!$A$2:$A$67,'03_BulkPack_Order'!C:C),"") -> #NAME? | S21: =IFERROR(R21*1,"") | T21: =_xludf.IFNA(_xlfn.XLOOKUP(Table3[[#This Row],[SKU]],'00_Yield_Rates'!$B$2:$B$17,'00_Yield_Rates'!$E$2:$E$17),"") -> #NAME?
A22: Cut_up | B22: 200064 | D22: Bulk Pack | E22: ThighMeat | F22: 5 | J22: MB HA BSTHIGH AC BG 5KG | N22: SILVER | R22: =_xludf.IFNA(_xlfn.XLOOKUP(Table3[[#This Row],[SKU]],'03_BulkPack_Order'!$A$2:$A$67,'03_BulkPack_Order'!C:C),"") -> #NAME? | S22: =IFERROR(R22*1,"") | T22: =_xludf.IFNA(_xlfn.XLOOKUP(Table3[[#This Row],[SKU]],'00_Yield_Rates'!$B$2:$B$17,'00_Yield_Rates'!$E$2:$E$17),"") -> #NAME?
A23: Cut_up | B23: 200083 | D23: Bulk Pack | E23: SplitBreast | J23: MB HA FB BA AC COMBO | N23: SILVER | R23: =_xludf.IFNA(_xlfn.XLOOKUP(Table3[[#This Row],[SKU]],'03_BulkPack_Order'!$A$2:$A$67,'03_BulkPack_Order'!C:C),"") -> #NAME? | S23: =IFERROR(R23*1,"") | T23: =_xludf.IFNA(_xlfn.XLOOKUP(Table3[[#This Row],[SKU]],'00_Yield_Rates'!$B$2:$B$17,'00_Yield_Rates'!$E$2:$E$17),"") -> #NAME?
A24: Cut_up | B24: 200089 | D24: Bulk Pack | E24: SplitBreast | F24: 585 | J24: MB HA FB AC COMBO | N24: SILVER | R24: =_xludf.IFNA(_xlfn.XLOOKUP(Table3[[#This Row],[SKU]],'03_BulkPack_Order'!$A$2:$A$67,'03_BulkPack_Order'!C:C),"") -> #NAME? | S24: =IFERROR(R24*1,"") | T24: =_xludf.IFNA(_xlfn.XLOOKUP(Table3[[#This Row],[SKU]],'00_Yield_Rates'!$B$2:$B$17,'00_Yield_Rates'!$E$2:$E$17),"") -> #NAME?
A25: Cut_up | B25: 200095 | D25: Bulk Pack | E25: DRUM | J25: MS HA DRUM 18KG | N25: SILVER | R25: =_xludf.IFNA(_xlfn.XLOOKUP(Table3[[#This Row],[SKU]],'03_BulkPack_Order'!$A$2:$A$67,'03_BulkPack_Order'!C:C),"") -> #NAME? | S25: =IFERROR(R25*1,"") | T25: =_xludf.IFNA(_xlfn.XLOOKUP(Table3[[#This Row],[SKU]],'00_Yield_Rates'!$B$2:$B$17,'00_Yield_Rates'!$E$2:$E$17),"") -> #NAME?
A26: Cut_up | B26: 200159 | D26: Bulk Pack | E26: BA | J26: MS HA LEG BA 18KG | N26: SILVER | R26: =_xludf.IFNA(_xlfn.XLOOKUP(Table3[[#This Row],[SKU]],'03_BulkPack_Order'!$A$2:$A$67,'03_BulkPack_Order'!C:C),"") -> #NAME? | S26: =IFERROR(R26*1,"") | T26: =_xludf.IFNA(_xlfn.XLOOKUP(Table3[[#This Row],[SKU]],'00_Yield_Rates'!$B$2:$B$17,'00_Yield_Rates'!$E$2:$E$17),"") -> #NAME?
A27: Cut_up | B27: 200902 | D27: Bulk Pack | E27: Thigh | J27: HA THIGH AC 18KG | N27: SILVER | R27: =_xludf.IFNA(_xlfn.XLOOKUP(Table3[[#This Row],[SKU]],'03_BulkPack_Order'!$A$2:$A$67,'03_BulkPack_Order'!C:C),"") -> #NAME? | S27: =IFERROR(R27*1,"") | T27: =_xludf.IFNA(_xlfn.XLOOKUP(Table3[[#This Row],[SKU]],'00_Yield_Rates'!$B$2:$B$17,'00_Yield_Rates'!$E$2:$E$17),"") -> #NAME?
A28: Cut_up | B28: 200903 | D28: Bulk Pack | E28: BA | J28: HA LEG BA AC 18KG | N28: SILVER | R28: =_xludf.IFNA(_xlfn.XLOOKUP(Table3[[#This Row],[SKU]],'03_BulkPack_Order'!$A$2:$A$67,'03_BulkPack_Order'!C:C),"") -> #NAME? | S28: =IFERROR(R28*1,"") | T28: =_xludf.IFNA(_xlfn.XLOOKUP(Table3[[#This Row],[SKU]],'00_Yield_Rates'!$B$2:$B$17,'00_Yield_Rates'!$E$2:$E$17),"") -> #NAME?
A29: Cut_up | B29: 200904 | D29: Bulk Pack | E29: WING | F29: 18 | J29: MB HA WING AC 18KG | N29: SILVER | R29: =_xludf.IFNA(_xlfn.XLOOKUP(Table3[[#This Row],[SKU]],'03_BulkPack_Order'!$A$2:$A$67,'03_BulkPack_Order'!C:C),"") -> #NAME? | S29: =IFERROR(R29*1,"") | T29: =_xludf.IFNA(_xlfn.XLOOKUP(Table3[[#This Row],[SKU]],'00_Yield_Rates'!$B$2:$B$17,'00_Yield_Rates'!$E$2:$E$17),"") -> #NAME?
A30: Cut_up | B30: 201894 | D30: Bulk Pack | E30: BSB | F30: 18 | J30: MB HA BSHB RND AC 18KG | N30: SILVER | R30: =_xludf.IFNA(_xlfn.XLOOKUP(Table3[[#This Row],[SKU]],'03_BulkPack_Order'!$A$2:$A$67,'03_BulkPack_Order'!C:C),"") -> #NAME? | S30: =IFERROR(R30*1,"") | T30: =_xludf.IFNA(_xlfn.XLOOKUP(Table3[[#This Row],[SKU]],'00_Yield_Rates'!$B$2:$B$17,'00_Yield_Rates'!$E$2:$E$17),"") -> #NAME?
A31: Cut_up | B31: 201895 | D31: Bulk Pack | E31: BSB | F31: 18 | J31: MB HA BSHB RND AC 18KG FFF | N31: SILVER | R31: =_xludf.IFNA(_xlfn.XLOOKUP(Table3[[#This Row],[SKU]],'03_BulkPack_Order'!$A$2:$A$67,'03_BulkPack_Order'!C:C),"") -> #NAME? | S31: =IFERROR(R31*1,"") | T31: =_xludf.IFNA(_xlfn.XLOOKUP(Table3[[#This Row],[SKU]],'00_Yield_Rates'!$B$2:$B$17,'00_Yield_Rates'!$E$2:$E$17),"") -> #NAME?
A32: Cut_up | B32: 201899 | D32: Bulk Pack | E32: BSB | F32: 10 | J32: MB HA BSHB 2ND 10KG | N32: SILVER | R32: =_xludf.IFNA(_xlfn.XLOOKUP(Table3[[#This Row],[SKU]],'03_BulkPack_Order'!$A$2:$A$67,'03_BulkPack_Order'!C:C),"") -> #NAME? | S32: =IFERROR(R32*1,"") | T32: =_xludf.IFNA(_xlfn.XLOOKUP(Table3[[#This Row],[SKU]],'00_Yield_Rates'!$B$2:$B$17,'00_Yield_Rates'!$E$2:$E$17),"") -> #NAME?
A33: Cut_up | B33: 203033 | D33: Bulk Pack | E33: BA | N33: SILVER | R33: =_xludf.IFNA(_xlfn.XLOOKUP(Table3[[#This Row],[SKU]],'03_BulkPack_Order'!$A$2:$A$67,'03_BulkPack_Order'!C:C),"") -> #NAME? | S33: =IFERROR(R33*1,"") | T33: =_xludf.IFNA(_xlfn.XLOOKUP(Table3[[#This Row],[SKU]],'00_Yield_Rates'!$B$2:$B$17,'00_Yield_Rates'!$E$2:$E$17),"") -> #NAME?
A34: Cut_up | B34: 203035 | D34: Bulk Pack | E34: SplitWing | F34: 23 | J34: MB HA SPL WING AC RET 23KG | N34: PLATINUM | R34: =_xludf.IFNA(_xlfn.XLOOKUP(Table3[[#This Row],[SKU]],'03_BulkPack_Order'!$A$2:$A$67,'03_BulkPack_Order'!C:C),"") -> #NAME? | S34: =IFERROR(R34*1,"") | T34: =_xludf.IFNA(_xlfn.XLOOKUP(Table3[[#This Row],[SKU]],'00_Yield_Rates'!$B$2:$B$17,'00_Yield_Rates'!$E$2:$E$17),"") -> #NAME?
A35: Cut_up | B35: 203087 | D35: Bulk Pack | E35: BSB | N35: PLATINUM | R35: =_xludf.IFNA(_xlfn.XLOOKUP(Table3[[#This Row],[SKU]],'03_BulkPack_Order'!$A$2:$A$67,'03_BulkPack_Order'!C:C),"") -> #NAME? | S35: =IFERROR(R35*1,"") | T35: =_xludf.IFNA(_xlfn.XLOOKUP(Table3[[#This Row],[SKU]],'00_Yield_Rates'!$B$2:$B$17,'00_Yield_Rates'!$E$2:$E$17),"") -> #NAME?
A36: Cut_up | B36: 203169 | D36: Bulk Pack | E36: BSB | N36: SILVER | R36: =_xludf.IFNA(_xlfn.XLOOKUP(Table3[[#This Row],[SKU]],'03_BulkPack_Order'!$A$2:$A$67,'03_BulkPack_Order'!C:C),"") -> #NAME? | S36: =IFERROR(R36*1,"") | T36: =_xludf.IFNA(_xlfn.XLOOKUP(Table3[[#This Row],[SKU]],'00_Yield_Rates'!$B$2:$B$17,'00_Yield_Rates'!$E$2:$E$17),"") -> #NAME?
A37: Cut_up | B37: 203171 | D37: Bulk Pack | E37: DRUM | N37: SILVER | R37: =_xludf.IFNA(_xlfn.XLOOKUP(Table3[[#This Row],[SKU]],'03_BulkPack_Order'!$A$2:$A$67,'03_BulkPack_Order'!C:C),"") -> #NAME? | S37: =IFERROR(R37*1,"") | T37: =_xludf.IFNA(_xlfn.XLOOKUP(Table3[[#This Row],[SKU]],'00_Yield_Rates'!$B$2:$B$17,'00_Yield_Rates'!$E$2:$E$17),"") -> #NAME?
A38: Cut_up | B38: 203172 | D38: Bulk Pack | E38: WING | F38: 25 | J38: MS HA WING RET 25KG | N38: SILVER | R38: =_xludf.IFNA(_xlfn.XLOOKUP(Table3[[#This Row],[SKU]],'03_BulkPack_Order'!$A$2:$A$67,'03_BulkPack_Order'!C:C),"") -> #NAME? | S38: =IFERROR(R38*1,"") | T38: =_xludf.IFNA(_xlfn.XLOOKUP(Table3[[#This Row],[SKU]],'00_Yield_Rates'!$B$2:$B$17,'00_Yield_Rates'!$E$2:$E$17),"") -> #NAME?
A39: Cut_up | B39: 203173 | D39: Bulk Pack | E39: SplitWing | J39: MS HA SPL WING RET 25KG | N39: SILVER | R39: =_xludf.IFNA(_xlfn.XLOOKUP(Table3[[#This Row],[SKU]],'03_BulkPack_Order'!$A$2:$A$67,'03_BulkPack_Order'!C:C),"") -> #NAME? | S39: =IFERROR(R39*1,"") | T39: =_xludf.IFNA(_xlfn.XLOOKUP(Table3[[#This Row],[SKU]],'00_Yield_Rates'!$B$2:$B$17,'00_Yield_Rates'!$E$2:$E$17),"") -> #NAME?
A40: Cut_up | B40: 203174 | D40: Bulk Pack | E40: ThighMeat | N40: SILVER | R40: =_xludf.IFNA(_xlfn.XLOOKUP(Table3[[#This Row],[SKU]],'03_BulkPack_Order'!$A$2:$A$67,'03_BulkPack_Order'!C:C),"") -> #NAME? | S40: =IFERROR(R40*1,"") | T40: =_xludf.IFNA(_xlfn.XLOOKUP(Table3[[#This Row],[SKU]],'00_Yield_Rates'!$B$2:$B$17,'00_Yield_Rates'!$E$2:$E$17),"") -> #NAME?
...

Sheet 01_Cages_Plan
B2: Cut up Plan | G2: 0.27083333
B3: Total Cages | C3: ='03_BulkPack_Order'!C2 -> 265 | E3: RWA | G3: =(F3/C8*1/24) -> 0 | O3: Flock # 1 | P3: Big Bird | Q3: 200141
B4: Total Cages Request | C4: ='03_BulkPack_Order'!C2-F7 -> 160 | E4: MLF | F4: =SUM(K7:K11) -> 105 | G4: =G3+(F4/C7*1/24) -> 0.26947464 | H4: =F4/C7*1/24 -> 0.26947464 | O4: Flock # 2 | P4: Small Bird | Q4: 200140
B5: Avg Cage weight | C5: 680 | E5: St. Fran | F5: =K12 -> 0 | G5: =G4+(F5/C7*1/24) -> 0.26947464 | H5: =F5/C7*1/24 -> 0 | O5: Flock # 3 | P5: Small Bird | Q5: 200015
B6: Avg Bird weight | C6: 1.6 | E6: EVP | F6: =K13 -> 0 | O6: Flock # 4 | Q6: St Francois
B7: Cages/Hour | C7: =60/(C5/C6/C9) -> 16.235294 | E7: Total: | F7: =SUM(F3:F6) -> 105 | J7: 200190/191 | K7: 7 | L7: =K7/$C$7 -> 0.43115942 | O7: Flock # 5 | Q7: Eden Valley
B8: Brids/cage | C8: 410 | J8: 200140 | K8: 35 | L8: =K8/$C$7 -> 2.1557971 | M8: 1.3-1.6 | O8: Flock # 6 | P8: Mix Bird | Q8: 200023
B9: Machine Speed (BPM) | C9: 115 | J9: 200141 | K9: 62 | L9: =K9/$C$7 -> 3.8188406 | M9: 1.6-2.3 | O9: Flock # 7 | P9: Big Bird | Q9: 200017
B10: RWA | C10: Bnls | D10: Split wing | E10: Thigh | F10: Drum | J10: 200150 | K10: 1 | L10: =K10/$C$7 -> 0.061594203 | M10: 1.6-2.3 | O10: Flock # 19 | P10: Mix Bird | Q10: 200190
B11: =MAX(C11:F11) -> 0 | C11: =B27 -> 0 | D11: =B33 -> 0 | E11: =B34 -> 0 | F11: =B36 -> 0 | J11: 200151 | K11: 0 | L11: =K11/$C$7 -> 0 | M11: 1.3-1.6
B12: EXTRA Case/25KG | C12: =(F3-C11)*C5*D26/25 -> 0 | D12: =(F3-D11)*C5*D33/25 -> 0 | E12: =(F3-E11)*C5*D34/25 -> 0 | F12: =(F3-F11)*C5*D36/25 -> 0 | J12: Saint Francois | K12: 0 | L12: =K12/$C$7 -> 0 | M12: 1.8
F13: Need | H13: Cases left over | J13: Eden Valley | K13: 0 | L13: =K13/$C$7 -> 0
B14: Breast | C14: =B43 -> 365.85366 | E14: =IF(C11>F3,F3,C11) -> 0 | F14: =C14+E14 -> 365.85366 | G14: Bnls | H14: =(C3-F14)*C5*'08_Chart_Data'!M9/25 -> -836.68195
B16: WINGS | C16: =B62 -> 1.7647059 | E16: =IF(D11>F3,F3,D11) -> 0 | F16: =C16+E16 -> 1.7647059 | G16: Wings | H16: =(C3-F16)*C5*'08_Chart_Data'!M3/25 -> 414.564
B18: THIGH | C18: =B76 -> 62.55418 | E18: =IF(E11>F3,F3,E11) -> 0 | F18: =C18+E18 -> 62.55418 | G18: Thigh | H18: =(C3-F22-F18)*C5*'08_Chart_Data'!I23/25 -> 957.8685
B20: DRUM | C20: =B95 -> 1.5756303 | E20: =IF(F11>F3,F3,F11) -> 0 | F20: =C20+E20 -> 1.5756303 | G20: Drums | H20: =(C3-F20-F22)*C5*'08_Chart_Data'!I18/25 -> 953.18261
B22: B.A LEG | C22: =B108 -> 13.113811 | F22: =C22 -> 13.113811
C25: Code | D25: % | E25: Cases | F25: Weight | G25: Cages | H25: Bird | I25: Time
B26: RWA | C26: 61051 | D26: =_xlfn.IFNA(_xlfn.XLOOKUP(C26,'08_Chart_Data'!$Q$3:$Q$104,'08_Chart_Data'!$R$3:$R$104,0),"") -> 0.305 | E26: =_xlfn.IFNA(_xlfn.XLOOKUP(C26,'10_Cone_Line'!$A$3:$A$136,'10_Cone_Line'!$E$3:$E$136,0),"") -> 0 | F26: =_xlfn.IFNA(E26*_xlfn.XLOOKUP(C26,'08_Chart_Data'!$Q$3:$Q$104,'08_Chart_Data'!$S$3:$S$104,0)/D26,"") -> 0 | G26: =IFERROR(F26/$C$5,"0") -> 0 | H26: =IFERROR(F26/$C$6,"-") -> 0 | I26: =IFERROR(IF(H26<0,"",(H26/$C$9)/1440),"") -> 0
B27: =SUMIF(G26:G32,">0") -> 0 | C27: 61049 | D27: =_xlfn.IFNA(_xlfn.XLOOKUP(C27,'08_Chart_Data'!$Q$3:$Q$104,'08_Chart_Data'!$R$3:$R$104,0),"") -> 0.36 | E27: =_xlfn.IFNA(_xlfn.XLOOKUP(C27,'10_Cone_Line'!$A$3:$A$136,'10_Cone_Line'!$E$3:$E$136,0),"") -> 0 | F27: =_xlfn.IFNA(E27*_xlfn.XLOOKUP(C27,'08_Chart_Data'!$Q$3:$Q$104,'08_Chart_Data'!$S$3:$S$104,0)/D27,"") -> 0 | G27: =IFERROR(F27/$C$5,"0") -> 0 | H27: =IFERROR(F27/$C$6,"-") -> 0 | I27: =IFERROR(IF(H27<0,"",(H27/$C$9)/1440),"") -> 0
C28: 61042 | D28: =_xlfn.IFNA(_xlfn.XLOOKUP(C28,'08_Chart_Data'!$Q$3:$Q$104,'08_Chart_Data'!$R$3:$R$104,0),"") -> 0.38 | E28: =_xlfn.IFNA(_xlfn.XLOOKUP(C28,'10_Cone_Line'!$A$3:$A$136,'10_Cone_Line'!$E$3:$E$136,0),"") -> 0 | F28: =_xlfn.IFNA(E28*_xlfn.XLOOKUP(C28,'08_Chart_Data'!$Q$3:$Q$104,'08_Chart_Data'!$S$3:$S$104,0)/D28,"") -> 0 | G28: =IFERROR(F28/$C$5,"0") -> 0 | H28: =IFERROR(F28/$C$6,"-") -> 0 | I28: =IFERROR(IF(H28<0,"",(H28/$C$9)/1440),"") -> 0
C29: 1081 | D29: =_xlfn.IFNA(_xlfn.XLOOKUP(C29,'08_Chart_Data'!$Q$3:$Q$104,'08_Chart_Data'!$R$3:$R$104,0),"") -> 0.305 | E29: =_xlfn.IFNA(_xlfn.XLOOKUP(C29,'10_Cone_Line'!$A$3:$A$136,'10_Cone_Line'!$E$3:$E$136,0),"") -> 0 | F29: =_xlfn.IFNA(E29*_xlfn.XLOOKUP(C29,'08_Chart_Data'!$Q$3:$Q$104,'08_Chart_Data'!$S$3:$S$104,0)/D29,"") -> 0 | G29: =IFERROR(F29/$C$5,"0") -> 0 | H29: =IFERROR(F29/$C$6,"-") -> 0 | I29: =IFERROR(IF(H29<0,"",(H29/$C$9)/1440),"") -> 0
C30: 61070 | D30: =_xlfn.IFNA(_xlfn.XLOOKUP(C30,'08_Chart_Data'!$Q$3:$Q$104,'08_Chart_Data'!$R$3:$R$104,0),"") -> 0.305 | E30: =_xlfn.IFNA(_xlfn.XLOOKUP(C30,'10_Cone_Line'!$A$3:$A$136,'10_Cone_Line'!$E$3:$E$136,0),"") -> 0 | F30: =_xlfn.IFNA(E30*_xlfn.XLOOKUP(C30,'08_Chart_Data'!$Q$3:$Q$104,'08_Chart_Data'!$S$3:$S$104,0)/D30,"") -> 0 | G30: =IFERROR(F30/$C$5,"0") -> 0 | H30: =IFERROR(F30/$C$6,"-") -> 0 | I30: =IFERROR(IF(H30<0,"",(H30/$C$9)/1440),"") -> 0
D31: =_xlfn.IFNA(_xlfn.XLOOKUP(C31,'08_Chart_Data'!$Q$3:$Q$104,'08_Chart_Data'!$R$3:$R$104,0),"") -> 0 | E31: =_xlfn.IFNA(_xlfn.XLOOKUP(C31,'10_Cone_Line'!$A$3:$A$136,'10_Cone_Line'!$E$3:$E$136,0),"") -> 0 | F31: =_xlfn.IFNA(E31*_xlfn.XLOOKUP(C31,'08_Chart_Data'!$Q$3:$Q$104,'08_Chart_Data'!$S$3:$S$104,0)/D31,"") -> #DIV/0! | G31: =IFERROR(F31/$C$5,"0") -> 0 | H31: =IFERROR(F31/$C$6,"-") -> - | I31: =IFERROR(IF(H31<0,"",(H31/$C$9)/1440),"")
C32: 61069 | D32: =_xlfn.IFNA(_xlfn.XLOOKUP(C32,'08_Chart_Data'!$Q$3:$Q$104,'08_Chart_Data'!$R$3:$R$104,0),"") -> 0.305 | E32: =_xlfn.IFNA(_xlfn.XLOOKUP(C32,'10_Cone_Line'!$A$3:$A$136,'10_Cone_Line'!$E$3:$E$136,0),"") -> 0 | F32: =_xlfn.IFNA(E32*_xlfn.XLOOKUP(C32,'08_Chart_Data'!$Q$3:$Q$104,'08_Chart_Data'!$S$3:$S$104,0)/D32,"") -> 0 | G32: =IFERROR(F32/$C$5,"0") -> 0 | H32: =IFERROR(F32/$C$6,"-") -> 0 | I32: =IFERROR(IF(H32<0,"",(H32/$C$9)/1440),"") -> 0
B33: =SUMIF(G33,">0") -> 0 | C33: 61016 | D33: =_xlfn.IFNA(_xlfn.XLOOKUP(C33,'08_Chart_Data'!$Q$3:$Q$104,'08_Chart_Data'!$R$3:$R$104,0),"") -> 0.0579 | E33: =_xlfn.IFNA(_xlfn.XLOOKUP(C33,'10_Cone_Line'!$A$3:$A$136,'10_Cone_Line'!$E$3:$E$136,0),"") -> 0 | F33: =_xlfn.IFNA(E33*_xlfn.XLOOKUP(C33,'08_Chart_Data'!$Q$3:$Q$104,'08_Chart_Data'!$S$3:$S$104,0)/D33,"") -> 0 | G33: =IFERROR(F33/$C$5,"0") -> 0 | H33: =IFERROR(F33/$C$6,"-") -> 0 | I33: =IFERROR(IF(H33<0,"",(H33/$C$9)/1440),"") -> 0
B34: =SUMIF(G34:G35,">0") -> 0 | C34: 61079 | D34: =_xlfn.IFNA(_xlfn.XLOOKUP(C34,'08_Chart_Data'!$Q$3:$Q$104,'08_Chart_Data'!$R$3:$R$104,0),"") -> 0.186 | E34: =_xlfn.IFNA(_xlfn.XLOOKUP(C34,'10_Cone_Line'!$A$3:$A$136,'10_Cone_Line'!$E$3:$E$136,0),"") -> -22 | F34: =_xlfn.IFNA(E34*_xlfn.XLOOKUP(C34,'08_Chart_Data'!$Q$3:$Q$104,'08_Chart_Data'!$S$3:$S$104,0)/D34,"") -> -2956.9892 | G34: =IFERROR(F34/$C$5,"0") -> -4.3485136 | H34: =IFERROR(F34/$C$6,"-") -> -1848.1183 | I34: =IFERROR(IF(H34<0,"",(H34/$C$9)/1440),"")
C35: 61087 | D35: =_xlfn.IFNA(_xlfn.XLOOKUP(C35,'08_Chart_Data'!$Q$3:$Q$104,'08_Chart_Data'!$R$3:$R$104,0),"") -> 0.105 | E35: =_xlfn.IFNA(_xlfn.XLOOKUP(C35,'10_Cone_Line'!$A$3:$A$136,'10_Cone_Line'!$E$3:$E$136,0),"") -> 0 | F35: =_xlfn.IFNA(E35*_xlfn.XLOOKUP(C35,'08_Chart_Data'!$Q$3:$Q$104,'08_Chart_Data'!$S$3:$S$104,0)/D35,"") -> 0 | G35: =IFERROR(F35/$C$5,"0") -> 0 | H35: =IFERROR(F35/$C$6,"-") -> 0 | I35: =IFERROR(IF(H35<0,"",(H35/$C$9)/1440),"") -> 0
B36: =SUMIF(G36:G37,">0") -> 0 | C36: 61074 | D36: =_xlfn.IFNA(_xlfn.XLOOKUP(C36,'08_Chart_Data'!$Q$3:$Q$104,'08_Chart_Data'!$R$3:$R$104,0),"") -> 0.14 | E36: =_xlfn.IFNA(_xlfn.XLOOKUP(C36,'10_Cone_Line'!$A$3:$A$136,'10_Cone_Line'!$E$3:$E$136,0),"") -> 0 | F36: =_xlfn.IFNA(E36*_xlfn.XLOOKUP(C36,'08_Chart_Data'!$Q$3:$Q$104,'08_Chart_Data'!$S$3:$S$104,0)/D36,"") -> 0 | G36: =IFERROR(F36/$C$5,"0") -> 0 | H36: =IFERROR(F36/$C$6,"-") -> 0 | I36: =IFERROR(IF(H36<0,"",(H36/$C$9)/1440),"") -> 0
C37: 61076 | D37: =_xlfn.IFNA(_xlfn.XLOOKUP(C37,'08_Chart_Data'!$Q$3:$Q$104,'08_Chart_Data'!$R$3:$R$104,0),"") -> 0.12 | E37: =_xlfn.IFNA(_xlfn.XLOOKUP(C37,'10_Cone_Line'!$A$3:$A$136,'10_Cone_Line'!$E$3:$E$136,0),"") -> -125 | F37: =_xlfn.IFNA(E37*_xlfn.XLOOKUP(C37,'08_Chart_Data'!$Q$3:$Q$104,'08_Chart_Data'!$S$3:$S$104,0)/D37,"") -> -26041.667 | G37: =IFERROR(F37/$C$5,"0") -> -38.296569 | H37: =IFERROR(F37/$C$6,"-") -> -16276.042 | I37: =IFERROR(IF(H37<0,"",(H37/$C$9)/1440),"")
D38: =_xlfn.IFNA(_xlfn.XLOOKUP(C38,'08_Chart_Data'!$Q$3:$Q$104,'08_Chart_Data'!$R$3:$R$104,0),"") -> 0 | E38: =_xlfn.IFNA(_xlfn.XLOOKUP(C38,'10_Cone_Line'!$A$3:$A$136,'10_Cone_Line'!$E$3:$E$136,0),"") -> 0 | F38: =_xlfn.IFNA(E38*_xlfn.XLOOKUP(C38,'08_Chart_Data'!$Q$3:$Q$104,'08_Chart_Data'!$S$3:$S$104,0)/D38,"") -> #DIV/0! | G38: =IFERROR(F38/$C$5,"0") -> 0 | H38: =IFERROR(F38/$C$6,"-") -> - | I38: =IFERROR(IF(H38<0,"",(H38/$C$9)/1440),"")
D39: =_xlfn.IFNA(_xlfn.XLOOKUP(C39,'08_Chart_Data'!$Q$3:$Q$104,'08_Chart_Data'!$R$3:$R$104,0),"") -> 0 | E39: =_xlfn.IFNA(_xlfn.XLOOKUP(C39,'10_Cone_Line'!$A$3:$A$136,'10_Cone_Line'!$E$3:$E$136,0),"") -> 0 | F39: =_xlfn.IFNA(E39*_xlfn.XLOOKUP(C39,'08_Chart_Data'!$Q$3:$Q$104,'08_Chart_Data'!$S$3:$S$104,0)/D39,"") -> #DIV/0! | G39: =IFERROR(F39/$C$5,"0") -> 0 | H39: =IFERROR(F39/$C$6,"-") -> - | I39: =IFERROR(IF(H39<0,"",(H39/$C$9)/1440),"")
D40: =_xlfn.IFNA(_xlfn.XLOOKUP(C40,'08_Chart_Data'!$Q$3:$Q$104,'08_Chart_Data'!$R$3:$R$104,0),"") -> 0 | E40: =_xlfn.IFNA(_xlfn.XLOOKUP(C40,'10_Cone_Line'!$A$3:$A$136,'10_Cone_Line'!$E$3:$E$136,0),"") -> 0 | F40: =_xlfn.IFNA(E40*_xlfn.XLOOKUP(C40,'08_Chart_Data'!$Q$3:$Q$104,'08_Chart_Data'!$S$3:$S$104,0)/D40,"") -> #DIV/0! | G40: =IFERROR(F40/$C$5,"0") -> 0 | H40: =IFERROR(F40/$C$6,"-") -> - | I40: =IFERROR(IF(H40<0,"",(H40/$C$9)/1440),"")
B41: Breast | C41: 61050F | D41: =_xlfn.IFNA(_xlfn.XLOOKUP(C41,'08_Chart_Data'!$Q$3:$Q$104,'08_Chart_Data'!$R$3:$R$104,0),"") -> 0.305 | E41: =_xlfn.IFNA(_xlfn.XLOOKUP(C41,'10_Cone_Line'!$A$3:$A$136,'10_Cone_Line'!$E$3:$E$136,0),"") -> 0 | F41: =_xlfn.IFNA(E41*_xlfn.XLOOKUP(C41,'08_Chart_Data'!$Q$3:$Q$104,'08_Chart_Data'!$S$3:$S$104,0)/D41,"") -> 0 | G41: =IFERROR(F41/$C$5,"0") -> 0 | H41: =IFERROR(F41/$C$6,"-") -> 0 | I41: =IFERROR(IF(H41<0,"",(H41/$C$9)/1440),"") -> 0
C42: 61050 | D42: =_xlfn.IFNA(_xlfn.XLOOKUP(C42,'08_Chart_Data'!$Q$3:$Q$104,'08_Chart_Data'!$R$3:$R$104,0),"") -> 0.305 | E42: =_xlfn.IFNA(_xlfn.XLOOKUP(C42,'10_Cone_Line'!$A$3:$A$136,'10_Cone_Line'!$E$3:$E$136,0),"") -> 0 | F42: =_xlfn.IFNA(E42*_xlfn.XLOOKUP(C42,'08_Chart_Data'!$Q$3:$Q$104,'08_Chart_Data'!$S$3:$S$104,0)/D42,"") -> 0 | G42: =IFERROR(F42/$C$5,"0") -> 0 | H42: =IFERROR(F42/$C$6,"-") -> 0 | I42: =IFERROR(IF(H42<0,"",(H42/$C$9)/1440),"") -> 0
B43: =SUMIF(G41:G59,">0") -> 365.85366 | C43: 1888 | D43: =_xlfn.IFNA(_xlfn.XLOOKUP(C43,'08_Chart_Data'!$Q$3:$Q$104,'08_Chart_Data'!$R$3:$R$104,0),"") -> 0.38 | E43: =_xlfn.IFNA(_xlfn.XLOOKUP(C43,'10_Cone_Line'!$A$3:$A$136,'10_Cone_Line'!$E$3:$E$136,0),"") -> 0 | F43: =_xlfn.IFNA(E43*_xlfn.XLOOKUP(C43,'08_Chart_Data'!$Q$3:$Q$104,'08_Chart_Data'!$S$3:$S$104,0)/D43,"") -> 0 | G43: =IFERROR(F43/$C$5,"0") -> 0 | H43: =IFERROR(F43/$C$6,"-") -> 0 | I43: =IFERROR(IF(H43<0,"",(H43/$C$9)/1440),"") -> 0
C44: 61040#2 | D44: =_xlfn.IFNA(_xlfn.XLOOKUP(C44,'08_Chart_Data'!$Q$3:$Q$104,'08_Chart_Data'!$R$3:$R$104,0),"") -> 0.41 | E44: =_xlfn.IFNA(_xlfn.XLOOKUP(C44,'10_Cone_Line'!$A$3:$A$136,'10_Cone_Line'!$E$3:$E$136,0),"") -> 0 | F44: =_xlfn.IFNA(E44*_xlfn.XLOOKUP(C44,'08_Chart_Data'!$Q$3:$Q$104,'08_Chart_Data'!$S$3:$S$104,0)/D44,"") -> 0 | G44: =IFERROR(F44/$C$5,"0") -> 0 | H44: =IFERROR(F44/$C$6,"-") -> 0 | I44: =IFERROR(IF(H44<0,"",(H44/$C$9)/1440),"") -> 0
B45: FFF | C45: 61048 | D45: =_xlfn.IFNA(_xlfn.XLOOKUP(C45,'08_Chart_Data'!$Q$3:$Q$104,'08_Chart_Data'!$R$3:$R$104,0),"") -> 0.38 | E45: =_xlfn.IFNA(_xlfn.XLOOKUP(C45,'10_Cone_Line'!$A$3:$A$136,'10_Cone_Line'!$E$3:$E$136,0),"") -> -127 | F45: =_xlfn.IFNA(E45*_xlfn.XLOOKUP(C45,'08_Chart_Data'!$Q$3:$Q$104,'08_Chart_Data'!$S$3:$S$104,0)/D45,"") -> -8355.2632 | G45: =IFERROR(F45/$C$5,"0") -> -12.287152 | H45: =IFERROR(F45/$C$6,"-") -> -5222.0395 | I45: =IFERROR(IF(H45<0,"",(H45/$C$9)/1440),"")
B46: =G41 -> 0 | C46: 61052 | D46: =_xlfn.IFNA(_xlfn.XLOOKUP(C46,'08_Chart_Data'!$Q$3:$Q$104,'08_Chart_Data'!$R$3:$R$104,0),"") -> 0.46 | E46: =_xlfn.IFNA(_xlfn.XLOOKUP(C46,'10_Cone_Line'!$A$3:$A$136,'10_Cone_Line'!$E$3:$E$136,0),"") -> 0 | F46: =_xlfn.IFNA(E46*_xlfn.XLOOKUP(C46,'08_Chart_Data'!$Q$3:$Q$104,'08_Chart_Data'!$S$3:$S$104,0)/D46,"") -> 0 | G46: =IFERROR(F46/$C$5,"0") -> 0 | H46: =IFERROR(F46/$C$6,"-") -> 0 | I46: =IFERROR(IF(H46<0,"",(H46/$C$9)/1440),"") -> 0
C47: 200083 | D47: =_xlfn.IFNA(_xlfn.XLOOKUP(C47,'08_Chart_Data'!$Q$3:$Q$104,'08_Chart_Data'!$R$3:$R$104,0),"") -> 0.41 | E47: =_xlfn.IFNA(_xlfn.XLOOKUP(C47,'10_Cone_Line'!$A$3:$A$136,'10_Cone_Line'!$E$3:$E$136,0),"") -> 0 | F47: =_xlfn.IFNA(E47*_xlfn.XLOOKUP(C47,'08_Chart_Data'!$Q$3:$Q$104,'08_Chart_Data'!$S$3:$S$104,0)/D47,"") -> 0 | G47: =IFERROR(F47/$C$5,"0") -> 0 | H47: =IFERROR(F47/$C$6,"-") -> 0 | I47: =IFERROR(IF(H47<0,"",(H47/$C$9)/1440),"") -> 0
...

Sheet 02_TrayPack_Order
A1: Code | B1: Extra Cases Produced | C1: Cases Remaining To Be Produced | E1: N | L1: Total | M1: WIP CODE | T1: Total | U1: Category
A2: ='05_Daily_Orders'!B2 -> 260 | B2: 0 | C2: 0 | F2: 0 | L2: =IF($E$1="n",0,(SUM(F2:K2)-B2)) -> 0 | M2: =_xlfn.IFNA(_xlfn.XLOOKUP(A2,'00_SKU_Master'!$B$2:$B$378,'00_SKU_Master'!$C$2:$C$378,0),"") -> 61050#2 | N2: =_xlfn.IFNA(_xlfn.XLOOKUP(A2,'00_SKU_Master'!$B$2:$B$378,'00_SKU_Master'!$F$2:$F$378,0)*F2/_xlfn.XLOOKUP(A2,'00_SKU_Master'!$B$2:$B$378,'00_SKU_Master'!$O:$O,0),"") -> #VALUE! | O2: =_xludf.IFNA(_xlfn.XLOOKUP($A4,'00_SKU_Master'!$B$2:$B$378,'00_SKU_Master'!$F$2:$F$378,0)*G4/_xlfn.XLOOKUP($A4,'00_SKU_Master'!$B$2:$B$378,'00_SKU_Master'!$O:$O,0),"") -> #NAME? | P2: =_xludf.IFNA(_xlfn.XLOOKUP($A4,'00_SKU_Master'!$B$2:$B$378,'00_SKU_Master'!$F$2:$F$378,0)*H4/_xlfn.XLOOKUP($A4,'00_SKU_Master'!$B$2:$B$378,'00_SKU_Master'!$O:$O,0),"") -> #NAME? | Q2: =_xludf.IFNA(_xlfn.XLOOKUP($A4,'00_SKU_Master'!$B$2:$B$378,'00_SKU_Master'!$F$2:$F$378,0)*I4/_xlfn.XLOOKUP($A4,'00_SKU_Master'!$B$2:$B$378,'00_SKU_Master'!$O:$O,0),"") -> #NAME? | R2: =_xludf.IFNA(_xlfn.XLOOKUP($A4,'00_SKU_Master'!$B$2:$B$378,'00_SKU_Master'!$F$2:$F$378,0)*J4/_xlfn.XLOOKUP($A4,'00_SKU_Master'!$B$2:$B$378,'00_SKU_Master'!$O:$O,0),"") -> #NAME? | S2: =_xludf.IFNA(_xlfn.XLOOKUP($A4,'00_SKU_Master'!$B$2:$B$378,'00_SKU_Master'!$F$2:$F$378,0)*K4/_xlfn.XLOOKUP($A4,'00_SKU_Master'!$B$2:$B$378,'00_SKU_Master'!$O:$O,0),"") -> #NAME? | T2: =SUM(N4:S4) -> #VALUE! | U2: ='05_Daily_Orders'!L2 -> LCL
A3: ='05_Daily_Orders'!B3 -> 331 | B3: 2 | C3: 0 | F3: 27 | L3: =IF($E$1="n",0,(SUM(F3:K3)-B3)) -> 0 | M3: =_xlfn.IFNA(_xlfn.XLOOKUP(A3,'00_SKU_Master'!$B$2:$B$378,'00_SKU_Master'!$C$2:$C$378,0),"") -> 61061 | N3: =_xlfn.IFNA(_xlfn.XLOOKUP(A3,'00_SKU_Master'!$B$2:$B$378,'00_SKU_Master'!$F$2:$F$378,0)*F3/_xlfn.XLOOKUP(A3,'00_SKU_Master'!$B$2:$B$378,'00_SKU_Master'!$O:$O,0),"") -> #VALUE! | O3: =_xludf.IFNA(_xlfn.XLOOKUP($A5,'00_SKU_Master'!$B$2:$B$378,'00_SKU_Master'!$F$2:$F$378,0)*G5/_xlfn.XLOOKUP($A5,'00_SKU_Master'!$B$2:$B$378,'00_SKU_Master'!$O:$O,0),"") -> #NAME? | P3: =_xludf.IFNA(_xlfn.XLOOKUP($A5,'00_SKU_Master'!$B$2:$B$378,'00_SKU_Master'!$F$2:$F$378,0)*H5/_xlfn.XLOOKUP($A5,'00_SKU_Master'!$B$2:$B$378,'00_SKU_Master'!$O:$O,0),"") -> #NAME? | Q3: =_xludf.IFNA(_xlfn.XLOOKUP($A5,'00_SKU_Master'!$B$2:$B$378,'00_SKU_Master'!$F$2:$F$378,0)*I5/_xlfn.XLOOKUP($A5,'00_SKU_Master'!$B$2:$B$378,'00_SKU_Master'!$O:$O,0),"") -> #NAME? | R3: =_xludf.IFNA(_xlfn.XLOOKUP($A5,'00_SKU_Master'!$B$2:$B$378,'00_SKU_Master'!$F$2:$F$378,0)*J5/_xlfn.XLOOKUP($A5,'00_SKU_Master'!$B$2:$B$378,'00_SKU_Master'!$O:$O,0),"") -> #NAME? | S3: =_xludf.IFNA(_xlfn.XLOOKUP($A5,'00_SKU_Master'!$B$2:$B$378,'00_SKU_Master'!$F$2:$F$378,0)*K5/_xlfn.XLOOKUP($A5,'00_SKU_Master'!$B$2:$B$378,'00_SKU_Master'!$O:$O,0),"") -> #NAME? | T3: =SUM(N5:S5) -> #VALUE! | U3: ='05_Daily_Orders'!L3 -> METRO
A4: ='05_Daily_Orders'!B4 -> 349 | B4: 0 | C4: 0 | F4: 0 | L4: =IF($E$1="n",0,(SUM(F4:K4)-B4)) -> 0 | M4: =_xlfn.IFNA(_xlfn.XLOOKUP(A4,'00_SKU_Master'!$B$2:$B$378,'00_SKU_Master'!$C$2:$C$378,0),"") -> 61040#2 | N4: =_xlfn.IFNA(_xlfn.XLOOKUP(A4,'00_SKU_Master'!$B$2:$B$378,'00_SKU_Master'!$F$2:$F$378,0)*F4/_xlfn.XLOOKUP(A4,'00_SKU_Master'!$B$2:$B$378,'00_SKU_Master'!$O:$O,0),"") -> #VALUE! | O4: =_xludf.IFNA(_xlfn.XLOOKUP($A6,'00_SKU_Master'!$B$2:$B$378,'00_SKU_Master'!$F$2:$F$378,0)*G6/_xlfn.XLOOKUP($A6,'00_SKU_Master'!$B$2:$B$378,'00_SKU_Master'!$O:$O,0),"") -> #NAME? | P4: =_xludf.IFNA(_xlfn.XLOOKUP($A6,'00_SKU_Master'!$B$2:$B$378,'00_SKU_Master'!$F$2:$F$378,0)*H6/_xlfn.XLOOKUP($A6,'00_SKU_Master'!$B$2:$B$378,'00_SKU_Master'!$O:$O,0),"") -> #NAME? | Q4: =_xludf.IFNA(_xlfn.XLOOKUP($A6,'00_SKU_Master'!$B$2:$B$378,'00_SKU_Master'!$F$2:$F$378,0)*I6/_xlfn.XLOOKUP($A6,'00_SKU_Master'!$B$2:$B$378,'00_SKU_Master'!$O:$O,0),"") -> #NAME? | R4: =_xludf.IFNA(_xlfn.XLOOKUP($A6,'00_SKU_Master'!$B$2:$B$378,'00_SKU_Master'!$F$2:$F$378,0)*J6/_xlfn.XLOOKUP($A6,'00_SKU_Master'!$B$2:$B$378,'00_SKU_Master'!$O:$O,0),"") -> #NAME? | S4: =_xludf.IFNA(_xlfn.XLOOKUP($A6,'00_SKU_Master'!$B$2:$B$378,'00_SKU_Master'!$F$2:$F$378,0)*K6/_xlfn.XLOOKUP($A6,'00_SKU_Master'!$B$2:$B$378,'00_SKU_Master'!$O:$O,0),"") -> #NAME? | T4: =SUM(N6:S6) -> #VALUE! | U4: ='05_Daily_Orders'!L4 -> FB
A5: ='05_Daily_Orders'!B5 -> 484 | B5: 0 | C5: 7 | F5: 44 | L5: =IF($E$1="n",0,(SUM(F5:K5)-B5)) -> 0 | M5: =_xlfn.IFNA(_xlfn.XLOOKUP(A5,'00_SKU_Master'!$B$2:$B$378,'00_SKU_Master'!$C$2:$C$378,0),"") -> 61121 | N5: =_xlfn.IFNA(_xlfn.XLOOKUP(A5,'00_SKU_Master'!$B$2:$B$378,'00_SKU_Master'!$F$2:$F$378,0)*F5/_xlfn.XLOOKUP(A5,'00_SKU_Master'!$B$2:$B$378,'00_SKU_Master'!$O:$O,0),"") -> #VALUE! | O5: =_xludf.IFNA(_xlfn.XLOOKUP($A7,'00_SKU_Master'!$B$2:$B$378,'00_SKU_Master'!$F$2:$F$378,0)*G7/_xlfn.XLOOKUP($A7,'00_SKU_Master'!$B$2:$B$378,'00_SKU_Master'!$O:$O,0),"") -> #NAME? | P5: =_xludf.IFNA(_xlfn.XLOOKUP($A7,'00_SKU_Master'!$B$2:$B$378,'00_SKU_Master'!$F$2:$F$378,0)*H7/_xlfn.XLOOKUP($A7,'00_SKU_Master'!$B$2:$B$378,'00_SKU_Master'!$O:$O,0),"") -> #NAME? | Q5: =_xludf.IFNA(_xlfn.XLOOKUP($A7,'00_SKU_Master'!$B$2:$B$378,'00_SKU_Master'!$F$2:$F$378,0)*I7/_xlfn.XLOOKUP($A7,'00_SKU_Master'!$B$2:$B$378,'00_SKU_Master'!$O:$O,0),"") -> #NAME? | R5: =_xludf.IFNA(_xlfn.XLOOKUP($A7,'00_SKU_Master'!$B$2:$B$378,'00_SKU_Master'!$F$2:$F$378,0)*J7/_xlfn.XLOOKUP($A7,'00_SKU_Master'!$B$2:$B$378,'00_SKU_Master'!$O:$O,0),"") -> #NAME? | S5: =_xludf.IFNA(_xlfn.XLOOKUP($A7,'00_SKU_Master'!$B$2:$B$378,'00_SKU_Master'!$F$2:$F$378,0)*K7/_xlfn.XLOOKUP($A7,'00_SKU_Master'!$B$2:$B$378,'00_SKU_Master'!$O:$O,0),"") -> #NAME? | T5: =SUM(N7:S7) -> #VALUE! | U5: ='05_Daily_Orders'!L5 -> FB
A6: ='05_Daily_Orders'!B6 -> 784 | B6: 0 | C6: 22 | F6: 136 | L6: =IF($E$1="n",0,(SUM(F6:K6)-B6)) -> 0 | M6: =_xlfn.IFNA(_xlfn.XLOOKUP(A6,'00_SKU_Master'!$B$2:$B$378,'00_SKU_Master'!$C$2:$C$378,0),"") -> 61086#2 | N6: =_xlfn.IFNA(_xlfn.XLOOKUP(A6,'00_SKU_Master'!$B$2:$B$378,'00_SKU_Master'!$F$2:$F$378,0)*F6/_xlfn.XLOOKUP(A6,'00_SKU_Master'!$B$2:$B$378,'00_SKU_Master'!$O:$O,0),"") -> #VALUE! | O6: =_xludf.IFNA(_xlfn.XLOOKUP($A8,'00_SKU_Master'!$B$2:$B$378,'00_SKU_Master'!$F$2:$F$378,0)*G8/_xlfn.XLOOKUP($A8,'00_SKU_Master'!$B$2:$B$378,'00_SKU_Master'!$O:$O,0),"") -> #NAME? | P6: =_xludf.IFNA(_xlfn.XLOOKUP($A8,'00_SKU_Master'!$B$2:$B$378,'00_SKU_Master'!$F$2:$F$378,0)*H8/_xlfn.XLOOKUP($A8,'00_SKU_Master'!$B$2:$B$378,'00_SKU_Master'!$O:$O,0),"") -> #NAME? | Q6: =_xludf.IFNA(_xlfn.XLOOKUP($A8,'00_SKU_Master'!$B$2:$B$378,'00_SKU_Master'!$F$2:$F$378,0)*I8/_xlfn.XLOOKUP($A8,'00_SKU_Master'!$B$2:$B$378,'00_SKU_Master'!$O:$O,0),"") -> #NAME? | R6: =_xludf.IFNA(_xlfn.XLOOKUP($A8,'00_SKU_Master'!$B$2:$B$378,'00_SKU_Master'!$F$2:$F$378,0)*J8/_xlfn.XLOOKUP($A8,'00_SKU_Master'!$B$2:$B$378,'00_SKU_Master'!$O:$O,0),"") -> #NAME? | S6: =_xludf.IFNA(_xlfn.XLOOKUP($A8,'00_SKU_Master'!$B$2:$B$378,'00_SKU_Master'!$F$2:$F$378,0)*K8/_xlfn.XLOOKUP($A8,'00_SKU_Master'!$B$2:$B$378,'00_SKU_Master'!$O:$O,0),"") -> #NAME? | T6: =SUM(N8:S8) -> #VALUE! | U6: ='05_Daily_Orders'!L6 -> FB
A7: ='05_Daily_Orders'!B7 -> 946 | B7: 0 | C7: 0 | F7: 0 | L7: =IF($E$1="n",0,(SUM(F7:K7)-B7)) -> 0 | M7: =_xlfn.IFNA(_xlfn.XLOOKUP(A7,'00_SKU_Master'!$B$2:$B$378,'00_SKU_Master'!$C$2:$C$378,0),"") -> 61040#2 | N7: =_xlfn.IFNA(_xlfn.XLOOKUP(A7,'00_SKU_Master'!$B$2:$B$378,'00_SKU_Master'!$F$2:$F$378,0)*F7/_xlfn.XLOOKUP(A7,'00_SKU_Master'!$B$2:$B$378,'00_SKU_Master'!$O:$O,0),"") -> #VALUE! | O7: =_xludf.IFNA(_xlfn.XLOOKUP($A9,'00_SKU_Master'!$B$2:$B$378,'00_SKU_Master'!$F$2:$F$378,0)*G9/_xlfn.XLOOKUP($A9,'00_SKU_Master'!$B$2:$B$378,'00_SKU_Master'!$O:$O,0),"") -> #NAME? | P7: =_xludf.IFNA(_xlfn.XLOOKUP($A9,'00_SKU_Master'!$B$2:$B$378,'00_SKU_Master'!$F$2:$F$378,0)*H9/_xlfn.XLOOKUP($A9,'00_SKU_Master'!$B$2:$B$378,'00_SKU_Master'!$O:$O,0),"") -> #NAME? | Q7: =_xludf.IFNA(_xlfn.XLOOKUP($A9,'00_SKU_Master'!$B$2:$B$378,'00_SKU_Master'!$F$2:$F$378,0)*I9/_xlfn.XLOOKUP($A9,'00_SKU_Master'!$B$2:$B$378,'00_SKU_Master'!$O:$O,0),"") -> #NAME? | R7: =_xludf.IFNA(_xlfn.XLOOKUP($A9,'00_SKU_Master'!$B$2:$B$378,'00_SKU_Master'!$F$2:$F$378,0)*J9/_xlfn.XLOOKUP($A9,'00_SKU_Master'!$B$2:$B$378,'00_SKU_Master'!$O:$O,0),"") -> #NAME? | S7: =_xludf.IFNA(_xlfn.XLOOKUP($A9,'00_SKU_Master'!$B$2:$B$378,'00_SKU_Master'!$F$2:$F$378,0)*K9/_xlfn.XLOOKUP($A9,'00_SKU_Master'!$B$2:$B$378,'00_SKU_Master'!$O:$O,0),"") -> #NAME? | T7: =SUM(N9:S9) -> #VALUE! | U7: ='05_Daily_Orders'!L7 -> FB
A8: ='05_Daily_Orders'!B8 -> 956 | B8: 0 | C8: 0 | F8: 0 | L8: =IF($E$1="n",0,(SUM(F8:K8)-B8)) -> 0 | M8: =_xlfn.IFNA(_xlfn.XLOOKUP(A8,'00_SKU_Master'!$B$2:$B$378,'00_SKU_Master'!$C$2:$C$378,0),"") -> 61072#2 | N8: =_xlfn.IFNA(_xlfn.XLOOKUP(A8,'00_SKU_Master'!$B$2:$B$378,'00_SKU_Master'!$F$2:$F$378,0)*F8/_xlfn.XLOOKUP(A8,'00_SKU_Master'!$B$2:$B$378,'00_SKU_Master'!$O:$O,0),"") -> #VALUE! | O8: =_xludf.IFNA(_xlfn.XLOOKUP($A10,'00_SKU_Master'!$B$2:$B$378,'00_SKU_Master'!$F$2:$F$378,0)*G10/_xlfn.XLOOKUP($A10,'00_SKU_Master'!$B$2:$B$378,'00_SKU_Master'!$O:$O,0),"") -> #NAME? | P8: =_xludf.IFNA(_xlfn.XLOOKUP($A10,'00_SKU_Master'!$B$2:$B$378,'00_SKU_Master'!$F$2:$F$378,0)*H10/_xlfn.XLOOKUP($A10,'00_SKU_Master'!$B$2:$B$378,'00_SKU_Master'!$O:$O,0),"") -> #NAME? | Q8: =_xludf.IFNA(_xlfn.XLOOKUP($A10,'00_SKU_Master'!$B$2:$B$378,'00_SKU_Master'!$F$2:$F$378,0)*I10/_xlfn.XLOOKUP($A10,'00_SKU_Master'!$B$2:$B$378,'00_SKU_Master'!$O:$O,0),"") -> #NAME? | R8: =_xludf.IFNA(_xlfn.XLOOKUP($A10,'00_SKU_Master'!$B$2:$B$378,'00_SKU_Master'!$F$2:$F$378,0)*J10/_xlfn.XLOOKUP($A10,'00_SKU_Master'!$B$2:$B$378,'00_SKU_Master'!$O:$O,0),"") -> #NAME? | S8: =_xludf.IFNA(_xlfn.XLOOKUP($A10,'00_SKU_Master'!$B$2:$B$378,'00_SKU_Master'!$F$2:$F$378,0)*K10/_xlfn.XLOOKUP($A10,'00_SKU_Master'!$B$2:$B$378,'00_SKU_Master'!$O:$O,0),"") -> #NAME? | T8: =SUM(N10:S10) -> #VALUE! | U8: ='05_Daily_Orders'!L8 -> FB
A9: ='05_Daily_Orders'!B9 -> 957 | B9: 0 | C9: 0 | F9: 0 | L9: =IF($E$1="n",0,(SUM(F9:K9)-B9)) -> 0 | M9: =_xlfn.IFNA(_xlfn.XLOOKUP(A9,'00_SKU_Master'!$B$2:$B$378,'00_SKU_Master'!$C$2:$C$378,0),"") -> 61082 | N9: =_xlfn.IFNA(_xlfn.XLOOKUP(A9,'00_SKU_Master'!$B$2:$B$378,'00_SKU_Master'!$F$2:$F$378,0)*F9/_xlfn.XLOOKUP(A9,'00_SKU_Master'!$B$2:$B$378,'00_SKU_Master'!$O:$O,0),"") -> #VALUE! | O9: =_xludf.IFNA(_xlfn.XLOOKUP($A11,'00_SKU_Master'!$B$2:$B$378,'00_SKU_Master'!$F$2:$F$378,0)*G11/_xlfn.XLOOKUP($A11,'00_SKU_Master'!$B$2:$B$378,'00_SKU_Master'!$O:$O,0),"") -> #NAME? | P9: =_xludf.IFNA(_xlfn.XLOOKUP($A11,'00_SKU_Master'!$B$2:$B$378,'00_SKU_Master'!$F$2:$F$378,0)*H11/_xlfn.XLOOKUP($A11,'00_SKU_Master'!$B$2:$B$378,'00_SKU_Master'!$O:$O,0),"") -> #NAME? | Q9: =_xludf.IFNA(_xlfn.XLOOKUP($A11,'00_SKU_Master'!$B$2:$B$378,'00_SKU_Master'!$F$2:$F$378,0)*I11/_xlfn.XLOOKUP($A11,'00_SKU_Master'!$B$2:$B$378,'00_SKU_Master'!$O:$O,0),"") -> #NAME? | R9: =_xludf.IFNA(_xlfn.XLOOKUP($A11,'00_SKU_Master'!$B$2:$B$378,'00_SKU_Master'!$F$2:$F$378,0)*J11/_xlfn.XLOOKUP($A11,'00_SKU_Master'!$B$2:$B$378,'00_SKU_Master'!$O:$O,0),"") -> #NAME? | S9: =_xludf.IFNA(_xlfn.XLOOKUP($A11,'00_SKU_Master'!$B$2:$B$378,'00_SKU_Master'!$F$2:$F$378,0)*K11/_xlfn.XLOOKUP($A11,'00_SKU_Master'!$B$2:$B$378,'00_SKU_Master'!$O:$O,0),"") -> #NAME? | T9: =SUM(N11:S11) -> #VALUE! | U9: ='05_Daily_Orders'!L9 -> FB
A10: ='05_Daily_Orders'!B10 -> 1023 | B10: 0 | C10: 0 | F10: 40 | L10: =IF($E$1="n",0,(SUM(F10:K10)-B10)) -> 0 | M10: =_xlfn.IFNA(_xlfn.XLOOKUP(A10,'00_SKU_Master'!$B$2:$B$378,'00_SKU_Master'!$C$2:$C$378,0),"") -> 61121 | N10: =_xlfn.IFNA(_xlfn.XLOOKUP(A10,'00_SKU_Master'!$B$2:$B$378,'00_SKU_Master'!$F$2:$F$378,0)*F10/_xlfn.XLOOKUP(A10,'00_SKU_Master'!$B$2:$B$378,'00_SKU_Master'!$O:$O,0),"") -> #VALUE! | O10: =_xludf.IFNA(_xlfn.XLOOKUP($A12,'00_SKU_Master'!$B$2:$B$378,'00_SKU_Master'!$F$2:$F$378,0)*G12/_xlfn.XLOOKUP($A12,'00_SKU_Master'!$B$2:$B$378,'00_SKU_Master'!$O:$O,0),"") -> #NAME? | P10: =_xludf.IFNA(_xlfn.XLOOKUP($A12,'00_SKU_Master'!$B$2:$B$378,'00_SKU_Master'!$F$2:$F$378,0)*H12/_xlfn.XLOOKUP($A12,'00_SKU_Master'!$B$2:$B$378,'00_SKU_Master'!$O:$O,0),"") -> #NAME? | Q10: =_xludf.IFNA(_xlfn.XLOOKUP($A12,'00_SKU_Master'!$B$2:$B$378,'00_SKU_Master'!$F$2:$F$378,0)*I12/_xlfn.XLOOKUP($A12,'00_SKU_Master'!$B$2:$B$378,'00_SKU_Master'!$O:$O,0),"") -> #NAME? | R10: =_xludf.IFNA(_xlfn.XLOOKUP($A12,'00_SKU_Master'!$B$2:$B$378,'00_SKU_Master'!$F$2:$F$378,0)*J12/_xlfn.XLOOKUP($A12,'00_SKU_Master'!$B$2:$B$378,'00_SKU_Master'!$O:$O,0),"") -> #NAME? | S10: =_xludf.IFNA(_xlfn.XLOOKUP($A12,'00_SKU_Master'!$B$2:$B$378,'00_SKU_Master'!$F$2:$F$378,0)*K12/_xlfn.XLOOKUP($A12,'00_SKU_Master'!$B$2:$B$378,'00_SKU_Master'!$O:$O,0),"") -> #NAME? | T10: =SUM(N12:S12) -> #VALUE! | U10: ='05_Daily_Orders'!L10 -> METRO
A11: ='05_Daily_Orders'!B11 -> 1830 | B11: 0 | C11: 24 | F11: 82 | L11: =IF($E$1="n",0,(SUM(F11:K11)-B11)) -> 0 | M11: =_xlfn.IFNA(_xlfn.XLOOKUP(A11,'00_SKU_Master'!$B$2:$B$378,'00_SKU_Master'!$C$2:$C$378,0),"") -> 61050F | N11: =_xlfn.IFNA(_xlfn.XLOOKUP(A11,'00_SKU_Master'!$B$2:$B$378,'00_SKU_Master'!$F$2:$F$378,0)*F11/_xlfn.XLOOKUP(A11,'00_SKU_Master'!$B$2:$B$378,'00_SKU_Master'!$O:$O,0),"") -> #VALUE! | O11: =_xludf.IFNA(_xlfn.XLOOKUP($A13,'00_SKU_Master'!$B$2:$B$378,'00_SKU_Master'!$F$2:$F$378,0)*G13/_xlfn.XLOOKUP($A13,'00_SKU_Master'!$B$2:$B$378,'00_SKU_Master'!$O:$O,0),"") -> #NAME? | P11: =_xludf.IFNA(_xlfn.XLOOKUP($A13,'00_SKU_Master'!$B$2:$B$378,'00_SKU_Master'!$F$2:$F$378,0)*H13/_xlfn.XLOOKUP($A13,'00_SKU_Master'!$B$2:$B$378,'00_SKU_Master'!$O:$O,0),"") -> #NAME? | Q11: =_xludf.IFNA(_xlfn.XLOOKUP($A13,'00_SKU_Master'!$B$2:$B$378,'00_SKU_Master'!$F$2:$F$378,0)*I13/_xlfn.XLOOKUP($A13,'00_SKU_Master'!$B$2:$B$378,'00_SKU_Master'!$O:$O,0),"") -> #NAME? | R11: =_xludf.IFNA(_xlfn.XLOOKUP($A13,'00_SKU_Master'!$B$2:$B$378,'00_SKU_Master'!$F$2:$F$378,0)*J13/_xlfn.XLOOKUP($A13,'00_SKU_Master'!$B$2:$B$378,'00_SKU_Master'!$O:$O,0),"") -> #NAME? | S11: =_xludf.IFNA(_xlfn.XLOOKUP($A13,'00_SKU_Master'!$B$2:$B$378,'00_SKU_Master'!$F$2:$F$378,0)*K13/_xlfn.XLOOKUP($A13,'00_SKU_Master'!$B$2:$B$378,'00_SKU_Master'!$O:$O,0),"") -> #NAME? | T11: =SUM(N13:S13) -> #VALUE! | U11: ='05_Daily_Orders'!L11 -> FB
A12: ='05_Daily_Orders'!B12 -> 1831 | B12: 0 | C12: 119 | F12: 117 | L12: =IF($E$1="n",0,(SUM(F12:K12)-B12)) -> 0 | M12: =_xlfn.IFNA(_xlfn.XLOOKUP(A12,'00_SKU_Master'!$B$2:$B$378,'00_SKU_Master'!$C$2:$C$378,0),"") -> 203021 | N12: =_xlfn.IFNA(_xlfn.XLOOKUP(A12,'00_SKU_Master'!$B$2:$B$378,'00_SKU_Master'!$F$2:$F$378,0)*F12/_xlfn.XLOOKUP(A12,'00_SKU_Master'!$B$2:$B$378,'00_SKU_Master'!$O:$O,0),"") -> #VALUE! | O12: =_xludf.IFNA(_xlfn.XLOOKUP($A14,'00_SKU_Master'!$B$2:$B$378,'00_SKU_Master'!$F$2:$F$378,0)*G14/_xlfn.XLOOKUP($A14,'00_SKU_Master'!$B$2:$B$378,'00_SKU_Master'!$O:$O,0),"") -> #NAME? | P12: =_xludf.IFNA(_xlfn.XLOOKUP($A14,'00_SKU_Master'!$B$2:$B$378,'00_SKU_Master'!$F$2:$F$378,0)*H14/_xlfn.XLOOKUP($A14,'00_SKU_Master'!$B$2:$B$378,'00_SKU_Master'!$O:$O,0),"") -> #NAME? | Q12: =_xludf.IFNA(_xlfn.XLOOKUP($A14,'00_SKU_Master'!$B$2:$B$378,'00_SKU_Master'!$F$2:$F$378,0)*I14/_xlfn.XLOOKUP($A14,'00_SKU_Master'!$B$2:$B$378,'00_SKU_Master'!$O:$O,0),"") -> #NAME? | R12: =_xludf.IFNA(_xlfn.XLOOKUP($A14,'00_SKU_Master'!$B$2:$B$378,'00_SKU_Master'!$F$2:$F$378,0)*J14/_xlfn.XLOOKUP($A14,'00_SKU_Master'!$B$2:$B$378,'00_SKU_Master'!$O:$O,0),"") -> #NAME? | S12: =_xludf.IFNA(_xlfn.XLOOKUP($A14,'00_SKU_Master'!$B$2:$B$378,'00_SKU_Master'!$F$2:$F$378,0)*K14/_xlfn.XLOOKUP($A14,'00_SKU_Master'!$B$2:$B$378,'00_SKU_Master'!$O:$O,0),"") -> #NAME? | T12: =SUM(N14:S14) -> #VALUE! | U12: ='05_Daily_Orders'!L12 -> FB
A13: ='05_Daily_Orders'!B13 -> 1837 | B13: 0 | C13: 0 | F13: 0 | L13: =IF($E$1="n",0,(SUM(F13:K13)-B13)) -> 0 | M13: =_xlfn.IFNA(_xlfn.XLOOKUP(A13,'00_SKU_Master'!$B$2:$B$378,'00_SKU_Master'!$C$2:$C$378,0),"") -> 61010 | N13: =_xlfn.IFNA(_xlfn.XLOOKUP(A13,'00_SKU_Master'!$B$2:$B$378,'00_SKU_Master'!$F$2:$F$378,0)*F13/_xlfn.XLOOKUP(A13,'00_SKU_Master'!$B$2:$B$378,'00_SKU_Master'!$O:$O,0),"") -> #VALUE! | O13: =_xludf.IFNA(_xlfn.XLOOKUP($A15,'00_SKU_Master'!$B$2:$B$378,'00_SKU_Master'!$F$2:$F$378,0)*G15/_xlfn.XLOOKUP($A15,'00_SKU_Master'!$B$2:$B$378,'00_SKU_Master'!$O:$O,0),"") -> #NAME? | P13: =_xludf.IFNA(_xlfn.XLOOKUP($A15,'00_SKU_Master'!$B$2:$B$378,'00_SKU_Master'!$F$2:$F$378,0)*H15/_xlfn.XLOOKUP($A15,'00_SKU_Master'!$B$2:$B$378,'00_SKU_Master'!$O:$O,0),"") -> #NAME? | Q13: =_xludf.IFNA(_xlfn.XLOOKUP($A15,'00_SKU_Master'!$B$2:$B$378,'00_SKU_Master'!$F$2:$F$378,0)*I15/_xlfn.XLOOKUP($A15,'00_SKU_Master'!$B$2:$B$378,'00_SKU_Master'!$O:$O,0),"") -> #NAME? | R13: =_xludf.IFNA(_xlfn.XLOOKUP($A15,'00_SKU_Master'!$B$2:$B$378,'00_SKU_Master'!$F$2:$F$378,0)*J15/_xlfn.XLOOKUP($A15,'00_SKU_Master'!$B$2:$B$378,'00_SKU_Master'!$O:$O,0),"") -> #NAME? | S13: =_xludf.IFNA(_xlfn.XLOOKUP($A15,'00_SKU_Master'!$B$2:$B$378,'00_SKU_Master'!$F$2:$F$378,0)*K15/_xlfn.XLOOKUP($A15,'00_SKU_Master'!$B$2:$B$378,'00_SKU_Master'!$O:$O,0),"") -> #NAME? | T13: =SUM(N15:S15) -> #VALUE! | U13: ='05_Daily_Orders'!L13 -> FB
... A265: ='05_Daily_Orders'!B265 -> 0 | B265: 0 | C265: 0 | F265: 0 | L265: =IF($E$1="n",0,(SUM(F265:K265)-B265)) -> 0 | M265: =_xlfn.IFNA(_xlfn.XLOOKUP(A265,'00_SKU_Master'!$B$2:$B$378,'00_SKU_Master'!$C$2:$C$378,0),"") -> 0 | N265: =_xlfn.IFNA(_xlfn.XLOOKUP(A265,'00_SKU_Master'!$B$2:$B$378,'00_SKU_Master'!$F$2:$F$378,0)*F265/_xlfn.XLOOKUP(A265,'00_SKU_Master'!$B$2:$B$378,'00_SKU_Master'!$O:$O,0),"") -> #VALUE! | O265: =_xludf.IFNA(_xlfn.XLOOKUP($A267,'00_SKU_Master'!$B$2:$B$378,'00_SKU_Master'!$F$2:$F$378,0)*G267/_xlfn.XLOOKUP($A267,'00_SKU_Master'!$B$2:$B$378,'00_SKU_Master'!$O:$O,0),"") -> #NAME? | P265: =_xludf.IFNA(_xlfn.XLOOKUP($A267,'00_SKU_Master'!$B$2:$B$378,'00_SKU_Master'!$F$2:$F$378,0)*H267/_xlfn.XLOOKUP($A267,'00_SKU_Master'!$B$2:$B$378,'00_SKU_Master'!$O:$O,0),"") -> #NAME? | Q265: =_xludf.IFNA(_xlfn.XLOOKUP($A267,'00_SKU_Master'!$B$2:$B$378,'00_SKU_Master'!$F$2:$F$378,0)*I267/_xlfn.XLOOKUP($A267,'00_SKU_Master'!$B$2:$B$378,'00_SKU_Master'!$O:$O,0),"") -> #NAME? | R265: =_xludf.IFNA(_xlfn.XLOOKUP($A267,'00_SKU_Master'!$B$2:$B$378,'00_SKU_Master'!$F$2:$F$378,0)*J267/_xlfn.XLOOKUP($A267,'00_SKU_Master'!$B$2:$B$378,'00_SKU_Master'!$O:$O,0),"") -> #NAME? | S265: =_xludf.IFNA(_xlfn.XLOOKUP($A267,'00_SKU_Master'!$B$2:$B$378,'00_SKU_Master'!$F$2:$F$378,0)*K267/_xlfn.XLOOKUP($A267,'00_SKU_Master'!$B$2:$B$378,'00_SKU_Master'!$O:$O,0),"") -> #NAME? | T265: =SUM(N267:S267) -> 0 | U265: ='05_Daily_Orders'!L265 -> 0

Sheet 03_BulkPack_Order
B2: Cages to cut today | C2: 265
B3: Traypack Target | C3: 10000cs+
B5: For Generic Traypack | C5: Qty x25kg
C6: Today | D6: Tomorrow | E6: Total
B7: Boneless Breast | C7: 160 | D7: 115 | E7: 275
B8: Skin on split breast | C8: 107 | D8: 45 | E8: 152
B9: Skinless split breast | C9: 55 | D9: 15 | E9: 70
B10: Whole wing | C10: 26 | D10: 0 | E10: 26
B11: Split wing | C11: 30 | D11: 10 | E11: 40
B12: Drums | C12: 70 | D12: 50 | E12: 120
B13: Bi thigh | C13: 195 | D13: 60 | E13: 255
B14: Bnls thighs | C14: 85 | D14: 45 | E14: 130
B15: Ba legs | C15: 95 | D15: 40 | E15: 135
B17: For Bagging | C17: Qtyx800kg
C18: Today | D18: Tomorrow | E18: Total
A19: 61062 | B19: BA Legs | C19: 3 | D19: 1 | E19: 4 | G19: =IFERROR(SUMIF('13_Progress_Track'!$A$2:$A$108,A19,'13_Progress_Track'!$E$2:$E$108),"0") -> 0 | H19: =SUM(C19:D19) -> 4
A20: 61073 | B20: Drum | C20: 4 | D20: 2 | E20: 6 | G20: =IFERROR(SUMIF('13_Progress_Track'!$A$2:$A$108,A20,'13_Progress_Track'!$E$2:$E$108),"0") -> 0 | H20: =SUM(C20:D20) -> 6
A21: 61018 | B21: Whole wing | C21: 6 | D21: 1 | E21: 7 | G21: =IFERROR(SUMIF('13_Progress_Track'!$A$2:$A$108,A21,'13_Progress_Track'!$E$2:$E$108),"0") -> 0 | H21: =SUM(C21:D21) -> 7
A22: 61014B | B22: Split wingx25kg | E22: 0 | G22: =IFERROR(SUMIF('13_Progress_Track'!$A$2:$A$108,A22,'13_Progress_Track'!$E$2:$E$108),"0") -> 0 | H22: =SUM(C22:D22) -> 0
G23: =IFERROR(SUMIF('13_Progress_Track'!$A$2:$A$108,A23,'13_Progress_Track'!$E$2:$E$108),"0") -> 0
G24: =IFERROR(SUMIF('13_Progress_Track'!$A$2:$A$108,A24,'13_Progress_Track'!$E$2:$E$108),"0") -> 0
A25: {=IFERROR(VALUE(LEFT(B25, MATCH(FALSE, ISNUMBER(MID(B25, ROW(INDIRECT("1:"&LEN(B25)+1)), 1) *1), 0) -1)),"")} | B25: For sale | G25: =IFERROR(SUMIF('13_Progress_Track'!$A$2:$A$108,A25,'13_Progress_Track'!$E$2:$E$108),"0") -> 0
A26: {=IFERROR(VALUE(LEFT(B26, MATCH(FALSE, ISNUMBER(MID(B26, ROW(INDIRECT("1:"&LEN(B26)+1)), 1) *1), 0) -1)),"")} -> 203035 | B26: 203035 container | C26: 174 | D26: Food Roll | G26: =IFERROR(SUMIF('13_Progress_Track'!$A$2:$A$108,A26,'13_Progress_Track'!$E$2:$E$108),"0") -> 0 | H26: =IFERROR(C26-G26,"") -> 174
A27: {=IFERROR(VALUE(LEFT(B27, MATCH(FALSE, ISNUMBER(MID(B27, ROW(INDIRECT("1:"&LEN(B27)+1)), 1) *1), 0) -1)),"")} -> 203172 | B27: 203172 container | D27: Goodmark | G27: =IFERROR(SUMIF('13_Progress_Track'!$A$2:$A$108,A27,'13_Progress_Track'!$E$2:$E$108),"0") -> 0 | H27: =IFERROR(C27-G27,"") -> 0
A28: {=IFERROR(VALUE(LEFT(B28, MATCH(FALSE, ISNUMBER(MID(B28, ROW(INDIRECT("1:"&LEN(B28)+1)), 1) *1), 0) -1)),"")} -> 868 | B28: 868 Spl Wings | D28: included rejected | G28: =IFERROR(SUMIF('13_Progress_Track'!$A$2:$A$108,A28,'13_Progress_Track'!$E$2:$E$108),"0") -> 0 | H28: =IFERROR(C28-G28,"") -> 0
A29: {=IFERROR(VALUE(LEFT(B29, MATCH(FALSE, ISNUMBER(MID(B29, ROW(INDIRECT("1:"&LEN(B29)+1)), 1) *1), 0) -1)),"")} -> 200868 | B29: 200868 MB HA SPL WING AC 18KG | C29: 120 | D29: rejected only | G29: =IFERROR(SUMIF('13_Progress_Track'!$A$2:$A$108,A29,'13_Progress_Track'!$E$2:$E$108),"0") -> 4 | H29: =IFERROR(C29-G29,"") -> 116
A30: {=IFERROR(VALUE(LEFT(B30, MATCH(FALSE, ISNUMBER(MID(B30, ROW(INDIRECT("1:"&LEN(B30)+1)), 1) *1), 0) -1)),"")} -> 40021 | B30: 40021 Spl Wings 4x10lb | G30: =IFERROR(SUMIF('13_Progress_Track'!$A$2:$A$108,A30,'13_Progress_Track'!$E$2:$E$108),"0") -> 0 | H30: =IFERROR(C30-G30,"") -> 0
A31: {=IFERROR(VALUE(LEFT(B31, MATCH(FALSE, ISNUMBER(MID(B31, ROW(INDIRECT("1:"&LEN(B31)+1)), 1) *1), 0) -1)),"")} -> 904 | B31: 904 H. Whole wings | G31: =IFERROR(SUMIF('13_Progress_Track'!$A$2:$A$108,A31,'13_Progress_Track'!$E$2:$E$108),"0") -> 0 | H31: =IFERROR(C31-G31,"") -> 0
A32: {=IFERROR(VALUE(LEFT(B32, MATCH(FALSE, ISNUMBER(MID(B32, ROW(INDIRECT("1:"&LEN(B32)+1)), 1) *1), 0) -1)),"")} -> 200904 | B32: 200904 H. Whole wings | G32: =IFERROR(SUMIF('13_Progress_Track'!$A$2:$A$108,A32,'13_Progress_Track'!$E$2:$E$108),"0") -> 0 | H32: =IFERROR(C32-G32,"") -> 0
A33: {=IFERROR(VALUE(LEFT(B33, MATCH(FALSE, ISNUMBER(MID(B33, ROW(INDIRECT("1:"&LEN(B33)+1)), 1) *1), 0) -1)),"")} -> 200905 | B33: 200905 H. Whole wings | G33: =IFERROR(SUMIF('13_Progress_Track'!$A$2:$A$108,A33,'13_Progress_Track'!$E$2:$E$108),"0") -> 0 | H33: =IFERROR(C33-G33,"") -> 0
A34: {=IFERROR(VALUE(LEFT(B34, MATCH(FALSE, ISNUMBER(MID(B34, ROW(INDIRECT("1:"&LEN(B34)+1)), 1) *1), 0) -1)),"")} -> 895 | B34: 895 Drums | G34: =IFERROR(SUMIF('13_Progress_Track'!$A$2:$A$108,A34,'13_Progress_Track'!$E$2:$E$108),"0") -> 0 | H34: =IFERROR(C34-G34,"") -> 0
A35: {=IFERROR(VALUE(LEFT(B35, MATCH(FALSE, ISNUMBER(MID(B35, ROW(INDIRECT("1:"&LEN(B35)+1)), 1) *1), 0) -1)),"")} -> 200095 | B35: 200095 H. Drums | C35: 250 | G35: =IFERROR(SUMIF('13_Progress_Track'!$A$2:$A$108,A35,'13_Progress_Track'!$E$2:$E$108),"0") -> 80 | H35: =IFERROR(C35-G35,"") -> 170
A36: {=IFERROR(VALUE(LEFT(B36, MATCH(FALSE, ISNUMBER(MID(B36, ROW(INDIRECT("1:"&LEN(B36)+1)), 1) *1), 0) -1)),"")} -> 160 | B36: 0160 Drums | G36: =IFERROR(SUMIF('13_Progress_Track'!$A$2:$A$108,A36,'13_Progress_Track'!$E$2:$E$108),"0") -> 0 | H36: =IFERROR(C36-G36,"") -> 0
A37: {=IFERROR(VALUE(LEFT(B37, MATCH(FALSE, ISNUMBER(MID(B37, ROW(INDIRECT("1:"&LEN(B37)+1)), 1) *1), 0) -1)),"")} -> 203271 | B37: 203271 DRUM 110G LESS RET 25KG | D37: have to be from 200140 birds | G37: =IFERROR(SUMIF('13_Progress_Track'!$A$2:$A$108,A37,'13_Progress_Track'!$E$2:$E$108),"0") -> 0 | H37: =IFERROR(C37-G37,"") -> 0
A38: {=IFERROR(VALUE(LEFT(B38, MATCH(FALSE, ISNUMBER(MID(B38, ROW(INDIRECT("1:"&LEN(B38)+1)), 1) *1), 0) -1)),"")} -> 159 | B38: 159 BA Legs | C38: 480 | G38: =IFERROR(SUMIF('13_Progress_Track'!$A$2:$A$108,A38,'13_Progress_Track'!$E$2:$E$108),"0") -> 0 | H38: =IFERROR(C38-G38,"") -> 480
A39: {=IFERROR(VALUE(LEFT(B39, MATCH(FALSE, ISNUMBER(MID(B39, ROW(INDIRECT("1:"&LEN(B39)+1)), 1) *1), 0) -1)),"")} -> 200159 | B39: 200159 H. BA Legs | G39: =IFERROR(SUMIF('13_Progress_Track'!$A$2:$A$108,A39,'13_Progress_Track'!$E$2:$E$108),"0") -> 0 | H39: =IFERROR(C39-G39,"") -> 0
A40: {=IFERROR(VALUE(LEFT(B40, MATCH(FALSE, ISNUMBER(MID(B40, ROW(INDIRECT("1:"&LEN(B40)+1)), 1) *1), 0) -1)),"")} -> 200903 | B40: 200903 H. BA Legs a/c | C40: 510 | G40: =IFERROR(SUMIF('13_Progress_Track'!$A$2:$A$108,A40,'13_Progress_Track'!$E$2:$E$108),"0") -> 61 | H40: =IFERROR(C40-G40,"") -> 449
A41: {=IFERROR(VALUE(LEFT(B41, MATCH(FALSE, ISNUMBER(MID(B41, ROW(INDIRECT("1:"&LEN(B41)+1)), 1) *1), 0) -1)),"")} -> 165 | B41: 165 Bnls breast | G41: =IFERROR(SUMIF('13_Progress_Track'!$A$2:$A$108,A41,'13_Progress_Track'!$E$2:$E$108),"0") -> 0 | H41: =IFERROR(C41-G41,"") -> 0
A42: {=IFERROR(VALUE(LEFT(B42, MATCH(FALSE, ISNUMBER(MID(B42, ROW(INDIRECT("1:"&LEN(B42)+1)), 1) *1), 0) -1)),"")} -> 1894 | B42: 1894 Bnls breast | G42: =IFERROR(SUMIF('13_Progress_Track'!$A$2:$A$108,A42,'13_Progress_Track'!$E$2:$E$108),"0") -> 0 | H42: =IFERROR(C42-G42,"") -> 0
A43: {=IFERROR(VALUE(LEFT(B43, MATCH(FALSE, ISNUMBER(MID(B43, ROW(INDIRECT("1:"&LEN(B43)+1)), 1) *1), 0) -1)),"")} -> 201894 | B43: 201894 H. Bnls breast | C43: 390 | G43: =IFERROR(SUMIF('13_Progress_Track'!$A$2:$A$108,A43,'13_Progress_Track'!$E$2:$E$108),"0") -> 40 | H43: =IFERROR(C43-G43,"") -> 350
...

Sheet 04_Bagging_Order
B2: Total Cases | K2: 1356 | L2: 2103 | M2: 1149
B3: DAY | I3: =SUMIF(I5:I25,">0") -> 1040 | J3: =SUM(J5:J22) -> 0 | K3: =SUMIF(K5:K23,">0") -> 1040 | N3: Totals: | Q3: =SUM(Q5:Q22) -> 0 | R3: =SUM(R5:R22) -> 0 | S3: =SUM(S5:S22) -> 0
B4: SKU | H4: SKU | I4: Today's | J4: Completed | K4: Remaining | L4: KG | M4: Raw Cages | N4: Product_Group | O4: Avg_Case_Weight | P4: Yield_Rate | Q4: WIP_kg | R4: Raw_kg_Needed | S4: Cages_Needed
B5: ='00_SKU_Master'!B357 -> 2050 | D5: 140 | H5: =B5 -> 2050 | I5: =SUM(C5:F5) -> 140 | J5: =SUMIF('13_Progress_Track'!$A$2:$A$108,B5,'13_Progress_Track'!$E$2:$E$108) -> 0 | K5: =I5-J5 -> 140 | L5: =_xlfn.IFNA(_xlfn.XLOOKUP(H5,$B$27:$B$41,$C$27:$C$41,0)*K5,"") -> 1586.6683 | M5: =_xlfn.IFNA(L5/_xlfn.XLOOKUP(H5,$B$27:$B$43,$F$27:$F$43,0),"") -> 2.6444472 | N5: =IFERROR(_xludf.XLOOKUP(B5,'00_SKU_Master'!$B$2:$B$378,'00_SKU_Master'!$E$2:$E$378,""),"") | O5: =IFERROR(_xlfn.SINGLE(_xlfn.XLOOKUP(B5,'00_SKU_Master'!$B$2:$B$378,'00_SKU_Master'!$F$2:$F$378,0)),0) -> 0 | P5: =IFERROR(_xludf.XLOOKUP(N5,'00_Yield_Rates'!$B$2:$B$33,'00_Yield_Rates'!$E$2:$E$33,0)/100,0) -> 0 | Q5: =IF(AND(ISNUMBER(I5),ISNUMBER(O5)),I5*O5,0) -> 0 | R5: =IF(AND(ISNUMBER(Q5),P5>0),Q5/P5,0) -> 0 | S5: =IF(R5>0,ROUNDUP(R5/680,1),0) -> 0
B6: ='00_SKU_Master'!B358 -> 2051 | D6: 380 | H6: =B6 -> 2051 | I6: =SUM(C6:F6) -> 380 | J6: =SUMIF('13_Progress_Track'!$A$2:$A$108,B6,'13_Progress_Track'!$E$2:$E$108) -> 0 | K6: =I6-J6 -> 380 | L6: =_xlfn.IFNA(_xlfn.XLOOKUP(H6,$B$27:$B$41,$C$27:$C$41,0)*K6,"") -> 4159.1857 | M6: =_xlfn.IFNA(L6/_xlfn.XLOOKUP(H6,$B$27:$B$43,$F$27:$F$43,0),"") -> 5.1989821 | N6: =IFERROR(_xludf.XLOOKUP(B6,'00_SKU_Master'!$B$2:$B$378,'00_SKU_Master'!$E$2:$E$378,""),"") | O6: =IFERROR(_xludf.XLOOKUP(B6,'00_SKU_Master'!$B$2:$B$378,'00_SKU_Master'!$F$2:$F$378,0),0) -> 0 | P6: =IFERROR(_xludf.XLOOKUP(N6,'00_Yield_Rates'!$B$2:$B$33,'00_Yield_Rates'!$E$2:$E$33,0)/100,0) -> 0 | Q6: =IF(AND(ISNUMBER(I6),ISNUMBER(O6)),I6*O6,0) -> 0 | R6: =IF(AND(ISNUMBER(Q6),P6>0),Q6/P6,0) -> 0 | S6: =IF(R6>0,ROUNDUP(R6/680,1),0) -> 0
B7: ='00_SKU_Master'!B359 -> 2081 | D7: 225 | H7: =B7 -> 2081 | I7: =SUM(C7:F7) -> 225 | J7: =SUMIF('13_Progress_Track'!$A$2:$A$108,B7,'13_Progress_Track'!$E$2:$E$108) -> 0 | K7: =I7-J7 -> 225 | L7: =_xlfn.IFNA(_xlfn.XLOOKUP(H7,$B$27:$B$41,$C$27:$C$41,0)*K7,"") -> 2530.0209 | M7: =_xlfn.IFNA(L7/_xlfn.XLOOKUP(H7,$B$27:$B$43,$F$27:$F$43,0),"") -> 4.2167016 | N7: =IFERROR(_xludf.XLOOKUP(B7,'00_SKU_Master'!$B$2:$B$378,'00_SKU_Master'!$E$2:$E$378,""),"") | O7: =IFERROR(_xludf.XLOOKUP(B7,'00_SKU_Master'!$B$2:$B$378,'00_SKU_Master'!$F$2:$F$378,0),0) -> 0 | P7: =IFERROR(_xludf.XLOOKUP(N7,'00_Yield_Rates'!$B$2:$B$33,'00_Yield_Rates'!$E$2:$E$33,0)/100,0) -> 0 | Q7: =IF(AND(ISNUMBER(I7),ISNUMBER(O7)),I7*O7,0) -> 0 | R7: =IF(AND(ISNUMBER(Q7),P7>0),Q7/P7,0) -> 0 | S7: =IF(R7>0,ROUNDUP(R7/680,1),0) -> 0
B8: ='00_SKU_Master'!B360 -> 7113 | D8: 0 | H8: =B8 -> 7113 | I8: =SUM(C8:F8) -> 0 | J8: =SUMIF('13_Progress_Track'!$A$2:$A$108,B8,'13_Progress_Track'!$E$2:$E$108) -> 0 | K8: =I8-J8 -> 0 | L8: =_xlfn.IFNA(_xlfn.XLOOKUP(H8,$B$27:$B$41,$C$27:$C$41,0)*K8,"") -> 0 | M8: =_xlfn.IFNA(L8/_xlfn.XLOOKUP(H8,$B$27:$B$43,$F$27:$F$43,0),"") -> 0 | N8: =IFERROR(_xludf.XLOOKUP(B8,'00_SKU_Master'!$B$2:$B$378,'00_SKU_Master'!$E$2:$E$378,""),"") | O8: =IFERROR(_xludf.XLOOKUP(B8,'00_SKU_Master'!$B$2:$B$378,'00_SKU_Master'!$F$2:$F$378,0),0) -> 0 | P8: =IFERROR(_xludf.XLOOKUP(N8,'00_Yield_Rates'!$B$2:$B$33,'00_Yield_Rates'!$E$2:$E$33,0)/100,0) -> 0 | Q8: =IF(AND(ISNUMBER(I8),ISNUMBER(O8)),I8*O8,0) -> 0 | R8: =IF(AND(ISNUMBER(Q8),P8>0),Q8/P8,0) -> 0 | S8: =IF(R8>0,ROUNDUP(R8/680,1),0) -> 0
B9: ='00_SKU_Master'!B361 -> 200179 | D9: 0 | H9: =B9 -> 200179 | I9: =SUM(C9:F9) -> 0 | J9: =SUMIF('13_Progress_Track'!$A$2:$A$108,B9,'13_Progress_Track'!$E$2:$E$108) -> 0 | K9: =I9-J9 -> 0 | L9: =_xlfn.IFNA(_xlfn.XLOOKUP(H9,$B$27:$B$41,$C$27:$C$41,0)*K9,"") -> 0 | M9: =_xlfn.IFNA(L9/_xlfn.XLOOKUP(H9,$B$27:$B$43,$F$27:$F$43,0),"") -> #DIV/0! | N9: =IFERROR(_xludf.XLOOKUP(B9,'00_SKU_Master'!$B$2:$B$378,'00_SKU_Master'!$E$2:$E$378,""),"") | O9: =IFERROR(_xludf.XLOOKUP(B9,'00_SKU_Master'!$B$2:$B$378,'00_SKU_Master'!$F$2:$F$378,0),0) -> 0 | P9: =IFERROR(_xludf.XLOOKUP(N9,'00_Yield_Rates'!$B$2:$B$33,'00_Yield_Rates'!$E$2:$E$33,0)/100,0) -> 0 | Q9: =IF(AND(ISNUMBER(I9),ISNUMBER(O9)),I9*O9,0) -> 0 | R9: =IF(AND(ISNUMBER(Q9),P9>0),Q9/P9,0) -> 0 | S9: =IF(R9>0,ROUNDUP(R9/680,1),0) -> 0
B10: ='00_SKU_Master'!B362 -> 200182 | D10: 75 | H10: =B10 -> 200182 | I10: =SUM(C10:F10) -> 75 | J10: =SUMIF('13_Progress_Track'!$A$2:$A$108,B10,'13_Progress_Track'!$E$2:$E$108) -> 0 | K10: =I10-J10 -> 75 | L10: =_xlfn.IFNA(_xlfn.XLOOKUP(H10,$B$27:$B$41,$C$27:$C$41,0)*K10,"") -> 744.76667 | M10: =_xlfn.IFNA(L10/_xlfn.XLOOKUP(H10,$B$27:$B$43,$F$27:$F$43,0),"") -> 1.2412778 | N10: =IFERROR(_xludf.XLOOKUP(B10,'00_SKU_Master'!$B$2:$B$378,'00_SKU_Master'!$E$2:$E$378,""),"") | O10: =IFERROR(_xludf.XLOOKUP(B10,'00_SKU_Master'!$B$2:$B$378,'00_SKU_Master'!$F$2:$F$378,0),0) -> 0 | P10: =IFERROR(_xludf.XLOOKUP(N10,'00_Yield_Rates'!$B$2:$B$33,'00_Yield_Rates'!$E$2:$E$33,0)/100,0) -> 0 | Q10: =IF(AND(ISNUMBER(I10),ISNUMBER(O10)),I10*O10,0) -> 0 | R10: =IF(AND(ISNUMBER(Q10),P10>0),Q10/P10,0) -> 0 | S10: =IF(R10>0,ROUNDUP(R10/680,1),0) -> 0
B11: ='00_SKU_Master'!B363 -> 200183 | D11: 97 | H11: =B11 -> 200183 | I11: =SUM(C11:F11) -> 97 | J11: =SUMIF('13_Progress_Track'!$A$2:$A$108,B11,'13_Progress_Track'!$E$2:$E$108) -> 0 | K11: =I11-J11 -> 97 | L11: =_xlfn.IFNA(_xlfn.XLOOKUP(H11,$B$27:$B$41,$C$27:$C$41,0)*K11,"") -> 881.9884 | M11: =_xlfn.IFNA(L11/_xlfn.XLOOKUP(H11,$B$27:$B$43,$F$27:$F$43,0),"") -> 1.1024855 | N11: =IFERROR(_xludf.XLOOKUP(B11,'00_SKU_Master'!$B$2:$B$378,'00_SKU_Master'!$E$2:$E$378,""),"") | O11: =IFERROR(_xludf.XLOOKUP(B11,'00_SKU_Master'!$B$2:$B$378,'00_SKU_Master'!$F$2:$F$378,0),0) -> 0 | P11: =IFERROR(_xludf.XLOOKUP(N11,'00_Yield_Rates'!$B$2:$B$33,'00_Yield_Rates'!$E$2:$E$33,0)/100,0) -> 0 | Q11: =IF(AND(ISNUMBER(I11),ISNUMBER(O11)),I11*O11,0) -> 0 | R11: =IF(AND(ISNUMBER(Q11),P11>0),Q11/P11,0) -> 0 | S11: =IF(R11>0,ROUNDUP(R11/680,1),0) -> 0
