Workbook

Sheet 00_SKU_Master
A1: Dept | B1: SKU | C1: RAW_WIP_CODE | D1: Customer | E1: Product_Group | F1: Avg_Case_Weight | G1: Trays_Per_Case | H1: Tray_Type | I1: Tray_Size | J1: SKU_Desc | K1: Tray Pack Speed | L1: Package_Type | M1: STD | N1: Class | O1: Weight | P1: Column1 | R1: ORDER | S1: RAW Request_KG | T1: Yield
A2: Cut_up | B2: 64 | D2: Bulk Pack | E2: ThighMeat | F2: 5 | J2: MB BSTHIGH AC BG 5KG | N2: SILVER | R2: =_xludf.IFNA(_xlfn.XLOOKUP(Table3[[#This Row],[SKU]],'03_BulkPack_Order'!$A$2:$A$67,'03_BulkPack_Order'!C:C),"") | S2: =IFERROR(R2*1,"") | T2: =_xludf.IFNA(_xlfn.XLOOKUP(Table3[[#This Row],[SKU]],'00_Yield_Rates'!$B$2:$B$17,'00_Yield_Rates'!$E$2:$E$17),"")
A3: Cut_up | B3: 65 | D3: Bulk Pack | E3: BSB | F3: 5 | J3: MB BSHB AC RND 5KG | N3: SILVER | R3: =_xludf.IFNA(_xlfn.XLOOKUP(Table3[[#This Row],[SKU]],'03_BulkPack_Order'!$A$2:$A$67,'03_BulkPack_Order'!C:C),"") | S3: =IFERROR(R3*1,"") | T3: =_xludf.IFNA(_xlfn.XLOOKUP(Table3[[#This Row],[SKU]],'00_Yield_Rates'!$B$2:$B$17,'00_Yield_Rates'!$E$2:$E$17),"")
A4: Cut_up | B4: 159 | D4: Bulk Pack | E4: BA | J4: MS LEG BA 18KG | N4: SILVER | R4: =_xludf.IFNA(_xlfn.XLOOKUP(Table3[[#This Row],[SKU]],'03_BulkPack_Order'!$A$2:$A$67,'03_BulkPack_Order'!C:C),"") | S4: =IFERROR(R4*1,"") | T4: =_xludf.IFNA(_xlfn.XLOOKUP(Table3[[#This Row],[SKU]],'00_Yield_Rates'!$B$2:$B$17,'00_Yield_Rates'!$E$2:$E$17),"")
A5: Cut_up | B5: 160 | D5: Bulk Pack | E5: DRUM | J5: MS DRUM 18KG | N5: SILVER | R5: =_xludf.IFNA(_xlfn.XLOOKUP(Table3[[#This Row],[SKU]],'03_BulkPack_Order'!$A$2:$A$67,'03_BulkPack_Order'!C:C),"") | S5: =IFERROR(R5*1,"") | T5: =_xludf.IFNA(_xlfn.XLOOKUP(Table3[[#This Row],[SKU]],'00_Yield_Rates'!$B$2:$B$17,'00_Yield_Rates'!$E$2:$E$17),"")
A6: Cut_up | B6: 161 | D6: Bulk Pack | E6: Thigh | J6: MB THIGH 20KG | N6: SILVER | R6: =_xludf.IFNA(_xlfn.XLOOKUP(Table3[[#This Row],[SKU]],'03_BulkPack_Order'!$A$2:$A$67,'03_BulkPack_Order'!C:C),"") | S6: =IFERROR(R6*1,"") | T6: =_xludf.IFNA(_xlfn.XLOOKUP(Table3[[#This Row],[SKU]],'00_Yield_Rates'!$B$2:$B$17,'00_Yield_Rates'!$E$2:$E$17),"")
A7: Cut_up | B7: 165 | D7: Bulk Pack | E7: BSB | F7: 10 | J7: MB BSHB AC RND 10KG | N7: SILVER | R7: =_xludf.IFNA(_xlfn.XLOOKUP(Table3[[#This Row],[SKU]],'03_BulkPack_Order'!$A$2:$A$67,'03_BulkPack_Order'!C:C),"") | S7: =IFERROR(R7*1,"") | T7: =_xludf.IFNA(_xlfn.XLOOKUP(Table3[[#This Row],[SKU]],'00_Yield_Rates'!$B$2:$B$17,'00_Yield_Rates'!$E$2:$E$17),"")
A8: Cut_up | B8: 834 | D8: Bulk Pack | E8: Thigh | F8: 18 | J8: THIGH 18KG | N8: SILVER | R8: =_xludf.IFNA(_xlfn.XLOOKUP(Table3[[#This Row],[SKU]],'03_BulkPack_Order'!$A$2:$A$67,'03_BulkPack_Order'!C:C),"") | S8: =IFERROR(R8*1,"") | T8: =_xludf.IFNA(_xlfn.XLOOKUP(Table3[[#This Row],[SKU]],'00_Yield_Rates'!$B$2:$B$17,'00_Yield_Rates'!$E$2:$E$17),"")
A9: Cut_up | B9: 868 | D9: Bulk Pack | E9: SplitWing | F9: 18 | J9: MB SPL WING 18KG | N9: SILVER | R9: =_xludf.IFNA(_xlfn.XLOOKUP(Table3[[#This Row],[SKU]],'03_BulkPack_Order'!$A$2:$A$67,'03_BulkPack_Order'!C:C),"") | S9: =IFERROR(R9*1,"") | T9: =_xludf.IFNA(_xlfn.XLOOKUP(Table3[[#This Row],[SKU]],'00_Yield_Rates'!$B$2:$B$17,'00_Yield_Rates'!$E$2:$E$17),"")
A10: Cut_up | B10: 895 | D10: Bulk Pack | E10: DRUM | J10: MB DRUM AC 18KG | N10: GOLD | R10: =_xludf.IFNA(_xlfn.XLOOKUP(Table3[[#This Row],[SKU]],'03_BulkPack_Order'!$A$2:$A$67,'03_BulkPack_Order'!C:C),"") | S10: =IFERROR(R10*1,"") | T10: =_xludf.IFNA(_xlfn.XLOOKUP(Table3[[#This Row],[SKU]],'00_Yield_Rates'!$B$2:$B$17,'00_Yield_Rates'!$E$2:$E$17),"")
A11: Cut_up | B11: 902 | D11: Bulk Pack | E11: Thigh | N11: SILVER | R11: =_xludf.IFNA(_xlfn.XLOOKUP(Table3[[#This Row],[SKU]],'03_BulkPack_Order'!$A$2:$A$67,'03_BulkPack_Order'!C:C),"") | S11: =IFERROR(R11*1,"") | T11: =_xludf.IFNA(_xlfn.XLOOKUP(Table3[[#This Row],[SKU]],'00_Yield_Rates'!$B$2:$B$17,'00_Yield_Rates'!$E$2:$E$17),"")
A12: Cut_up | B12: 904 | D12: Bulk Pack | E12: WING | F12: 18 | J12: MB WING AC 18KG | N12: SILVER | R12: =_xludf.IFNA(_xlfn.XLOOKUP(Table3[[#This Row],[SKU]],'03_BulkPack_Order'!$A$2:$A$67,'03_BulkPack_Order'!C:C),"") | S12: =IFERROR(R12*1,"") | T12: =_xludf.IFNA(_xlfn.XLOOKUP(Table3[[#This Row],[SKU]],'00_Yield_Rates'!$B$2:$B$17,'00_Yield_Rates'!$E$2:$E$17),"")
A13: Cut_up | B13: 1026 | D13: Bulk Pack | E13: WING | N13: SILVER | R13: =_xludf.IFNA(_xlfn.XLOOKUP(Table3[[#This Row],[SKU]],'03_BulkPack_Order'!$A$2:$A$67,'03_BulkPack_Order'!C:C),"") | S13: =IFERROR(R13*1,"") | T13: =_xludf.IFNA(_xlfn.XLOOKUP(Table3[[#This Row],[SKU]],'00_Yield_Rates'!$B$2:$B$17,'00_Yield_Rates'!$E$2:$E$17),"")
A14: Cut_up | B14: 1081 | D14: Bulk Pack | E14: BSB | N14: SILVER | R14: =_xludf.IFNA(_xlfn.XLOOKUP(Table3[[#This Row],[SKU]],'03_BulkPack_Order'!$A$2:$A$67,'03_BulkPack_Order'!C:C),"") | S14: =IFERROR(R14*1,"") | T14: =_xludf.IFNA(_xlfn.XLOOKUP(Table3[[#This Row],[SKU]],'00_Yield_Rates'!$B$2:$B$17,'00_Yield_Rates'!$E$2:$E$17),"")
A15: Cut_up | B15: 1446 | D15: Bulk Pack | E15: BSB | N15: SILVER | R15: =_xludf.IFNA(_xlfn.XLOOKUP(Table3[[#This Row],[SKU]],'03_BulkPack_Order'!$A$2:$A$67,'03_BulkPack_Order'!C:C),"") | S15: =IFERROR(R15*1,"") | T15: =_xludf.IFNA(_xlfn.XLOOKUP(Table3[[#This Row],[SKU]],'00_Yield_Rates'!$B$2:$B$17,'00_Yield_Rates'!$E$2:$E$17),"")
A16: Cut_up | B16: 1887 | D16: Bulk Pack | E16: BA | N16: GOLD | R16: =_xludf.IFNA(_xlfn.XLOOKUP(Table3[[#This Row],[SKU]],'03_BulkPack_Order'!$A$2:$A$67,'03_BulkPack_Order'!C:C),"") | S16: =IFERROR(R16*1,"") | T16: =_xludf.IFNA(_xlfn.XLOOKUP(Table3[[#This Row],[SKU]],'00_Yield_Rates'!$B$2:$B$17,'00_Yield_Rates'!$E$2:$E$17),"")
A17: Cut_up | B17: 1888 | D17: Bulk Pack | E17: SplitBreast | N17: GOLD | R17: =_xludf.IFNA(_xlfn.XLOOKUP(Table3[[#This Row],[SKU]],'03_BulkPack_Order'!$A$2:$A$67,'03_BulkPack_Order'!C:C),"") | S17: =IFERROR(R17*1,"") | T17: =_xludf.IFNA(_xlfn.XLOOKUP(Table3[[#This Row],[SKU]],'00_Yield_Rates'!$B$2:$B$17,'00_Yield_Rates'!$E$2:$E$17),"")
A18: Cut_up | B18: 1894 | D18: Bulk Pack | E18: BSB | J18: MB BSHB RND AC 18KG | N18: SILVER | R18: =_xludf.IFNA(_xlfn.XLOOKUP(Table3[[#This Row],[SKU]],'03_BulkPack_Order'!$A$2:$A$67,'03_BulkPack_Order'!C:C),"") | S18: =IFERROR(R18*1,"") | T18: =_xludf.IFNA(_xlfn.XLOOKUP(Table3[[#This Row],[SKU]],'00_Yield_Rates'!$B$2:$B$17,'00_Yield_Rates'!$E$2:$E$17),"")
A19: Cut_up | B19: 2233 | D19: Bulk Pack | E19: SplitWing | J19: 24839 MB COS SPL WING AC | N19: GOLD | R19: =_xludf.IFNA(_xlfn.XLOOKUP(Table3[[#This Row],[SKU]],'03_BulkPack_Order'!$A$2:$A$67,'03_BulkPack_Order'!C:C),"") | S19: =IFERROR(R19*1,"") | T19: =_xludf.IFNA(_xlfn.XLOOKUP(Table3[[#This Row],[SKU]],'00_Yield_Rates'!$B$2:$B$17,'00_Yield_Rates'!$E$2:$E$17),"")
A20: Cut_up | B20: 2235 | D20: Bulk Pack | E20: DRUM | N20: GOLD | R20: =_xludf.IFNA(_xlfn.XLOOKUP(Table3[[#This Row],[SKU]],'03_BulkPack_Order'!$A$2:$A$67,'03_BulkPack_Order'!C:C),"") | S20: =IFERROR(R20*1,"") | T20: =_xludf.IFNA(_xlfn.XLOOKUP(Table3[[#This Row],[SKU]],'00_Yield_Rates'!$B$2:$B$17,'00_Yield_Rates'!$E$2:$E$17),"")
A21: Cut_up | B21: 2236 | D21: Bulk Pack | E21: BSB | F21: 20 | J21: 17219 MB COS BSHB AC | N21: PLATINUM | R21: =_xludf.IFNA(_xlfn.XLOOKUP(Table3[[#This Row],[SKU]],'03_BulkPack_Order'!$A$2:$A$67,'03_BulkPack_Order'!C:C),"") | S21: =IFERROR(R21*1,"") | T21: =_xludf.IFNA(_xlfn.XLOOKUP(Table3[[#This Row],[SKU]],'00_Yield_Rates'!$B$2:$B$17,'00_Yield_Rates'!$E$2:$E$17),"")
A22: Cut_up | B22: 200064 | D22: Bulk Pack | E22: ThighMeat | F22: 5 | J22: MB HA BSTHIGH AC BG 5KG | N22: SILVER | R22: =_xludf.IFNA(_xlfn.XLOOKUP(Table3[[#This Row],[SKU]],'03_BulkPack_Order'!$A$2:$A$67,'03_BulkPack_Order'!C:C),"") | S22: =IFERROR(R22*1,"") | T22: =_xludf.IFNA(_xlfn.XLOOKUP(Table3[[#This Row],[SKU]],'00_Yield_Rates'!$B$2:$B$17,'00_Yield_Rates'!$E$2:$E$17),"")
A23: Cut_up | B23: 200083 | D23: Bulk Pack | E23: SplitBreast | J23: MB HA FB BA AC COMBO | N23: SILVER | R23: =_xludf.IFNA(_xlfn.XLOOKUP(Table3[[#This Row],[SKU]],'03_BulkPack_Order'!$A$2:$A$67,'03_BulkPack_Order'!C:C),"") | S23: =IFERROR(R23*1,"") | T23: =_xludf.IFNA(_xlfn.XLOOKUP(Table3[[#This Row],[SKU]],'00_Yield_Rates'!$B$2:$B$17,'00_Yield_Rates'!$E$2:$E$17),"")
A24: Cut_up | B24: 200089 | D24: Bulk Pack | E24: SplitBreast | F24: 585 | J24: MB HA FB AC COMBO | N24: SILVER | R24: =_xludf.IFNA(_xlfn.XLOOKUP(Table3[[#This Row],[SKU]],'03_BulkPack_Order'!$A$2:$A$67,'03_BulkPack_Order'!C:C),"") | S24: =IFERROR(R24*1,"") | T24: =_xludf.IFNA(_xlfn.XLOOKUP(Table3[[#This Row],[SKU]],'00_Yield_Rates'!$B$2:$B$17,'00_Yield_Rates'!$E$2:$E$17),"")
A25: Cut_up | B25: 200095 | D25: Bulk Pack | E25: DRUM | J25: MS HA DRUM 18KG | N25: SILVER | R25: =_xludf.IFNA(_xlfn.XLOOKUP(Table3[[#This Row],[SKU]],'03_BulkPack_Order'!$A$2:$A$67,'03_BulkPack_Order'!C:C),"") | S25: =IFERROR(R25*1,"") | T25: =_xludf.IFNA(_xlfn.XLOOKUP(Table3[[#This Row],[SKU]],'00_Yield_Rates'!$B$2:$B$17,'00_Yield_Rates'!$E$2:$E$17),"")
A26: Cut_up | B26: 200159 | D26: Bulk Pack | E26: BA | J26: MS HA LEG BA 18KG | N26: SILVER | R26: =_xludf.IFNA(_xlfn.XLOOKUP(Table3[[#This Row],[SKU]],'03_BulkPack_Order'!$A$2:$A$67,'03_BulkPack_Order'!C:C),"") | S26: =IFERROR(R26*1,"") | T26: =_xludf.IFNA(_xlfn.XLOOKUP(Table3[[#This Row],[SKU]],'00_Yield_Rates'!$B$2:$B$17,'00_Yield_Rates'!$E$2:$E$17),"")
A27: Cut_up | B27: 200902 | D27: Bulk Pack | E27: Thigh | J27: HA THIGH AC 18KG | N27: SILVER | R27: =_xludf.IFNA(_xlfn.XLOOKUP(Table3[[#This Row],[SKU]],'03_BulkPack_Order'!$A$2:$A$67,'03_BulkPack_Order'!C:C),"") | S27: =IFERROR(R27*1,"") | T27: =_xludf.IFNA(_xlfn.XLOOKUP(Table3[[#This Row],[SKU]],'00_Yield_Rates'!$B$2:$B$17,'00_Yield_Rates'!$E$2:$E$17),"")
A28: Cut_up | B28: 200903 | D28: Bulk Pack | E28: BA | J28: HA LEG BA AC 18KG | N28: SILVER | R28: =_xludf.IFNA(_xlfn.XLOOKUP(Table3[[#This Row],[SKU]],'03_BulkPack_Order'!$A$2:$A$67,'03_BulkPack_Order'!C:C),"") | S28: =IFERROR(R28*1,"") | T28: =_xludf.IFNA(_xlfn.XLOOKUP(Table3[[#This Row],[SKU]],'00_Yield_Rates'!$B$2:$B$17,'00_Yield_Rates'!$E$2:$E$17),"")
A29: Cut_up | B29: 200904 | D29: Bulk Pack | E29: WING | F29: 18 | J29: MB HA WING AC 18KG | N29: SILVER | R29: =_xludf.IFNA(_xlfn.XLOOKUP(Table3[[#This Row],[SKU]],'03_BulkPack_Order'!$A$2:$A$67,'03_BulkPack_Order'!C:C),"") | S29: =IFERROR(R29*1,"") | T29: =_xludf.IFNA(_xlfn.XLOOKUP(Table3[[#This Row],[SKU]],'00_Yield_Rates'!$B$2:$B$17,'00_Yield_Rates'!$E$2:$E$17),"")
A30: Cut_up | B30: 201894 | D30: Bulk Pack | E30: BSB | F30: 18 | J30: MB HA BSHB RND AC 18KG | N30: SILVER | R30: =_xludf.IFNA(_xlfn.XLOOKUP(Table3[[#This Row],[SKU]],'03_BulkPack_Order'!$A$2:$A$67,'03_BulkPack_Order'!C:C),"") | S30: =IFERROR(R30*1,"") | T30: =_xludf.IFNA(_xlfn.XLOOKUP(Table3[[#This Row],[SKU]],'00_Yield_Rates'!$B$2:$B$17,'00_Yield_Rates'!$E$2:$E$17),"")
A31: Cut_up | B31: 201895 | D31: Bulk Pack | E31: BSB | F31: 18 | J31: MB HA BSHB RND AC 18KG FFF | N31: SILVER | R31: =_xludf.IFNA(_xlfn.XLOOKUP(Table3[[#This Row],[SKU]],'03_BulkPack_Order'!$A$2:$A$67,'03_BulkPack_Order'!C:C),"") | S31: =IFERROR(R31*1,"") | T31: =_xludf.IFNA(_xlfn.XLOOKUP(Table3[[#This Row],[SKU]],'00_Yield_Rates'!$B$2:$B$17,'00_Yield_Rates'!$E$2:$E$17),"")
A32: Cut_up | B32: 201899 | D32: Bulk Pack | E32: BSB | F32: 10 | J32: MB HA BSHB 2ND 10KG | N32: SILVER | R32: =_xludf.IFNA(_xlfn.XLOOKUP(Table3[[#This Row],[SKU]],'03_BulkPack_Order'!$A$2:$A$67,'03_BulkPack_Order'!C:C),"") | S32: =IFERROR(R32*1,"") | T32: =_xludf.IFNA(_xlfn.XLOOKUP(Table3[[#This Row],[SKU]],'00_Yield_Rates'!$B$2:$B$17,'00_Yield_Rates'!$E$2:$E$17),"")
A33: Cut_up | B33: 203033 | D33: Bulk Pack | E33: BA | N33: SILVER | R33: =_xludf.IFNA(_xlfn.XLOOKUP(Table3[[#This Row],[SKU]],'03_BulkPack_Order'!$A$2:$A$67,'03_BulkPack_Order'!C:C),"") | S33: =IFERROR(R33*1,"") | T33: =_xludf.IFNA(_xlfn.XLOOKUP(Table3[[#This Row],[SKU]],'00_Yield_Rates'!$B$2:$B$17,'00_Yield_Rates'!$E$2:$E$17),"")
A34: Cut_up | B34: 203035 | D34: Bulk Pack | E34: SplitWing | F34: 23 | J34: MB HA SPL WING AC RET 23KG | N34: PLATINUM | R34: =_xludf.IFNA(_xlfn.XLOOKUP(Table3[[#This Row],[SKU]],'03_BulkPack_Order'!$A$2:$A$67,'03_BulkPack_Order'!C:C),"") | S34: =IFERROR(R34*1,"") | T34: =_xludf.IFNA(_xlfn.XLOOKUP(Table3[[#This Row],[SKU]],'00_Yield_Rates'!$B$2:$B$17,'00_Yield_Rates'!$E$2:$E$17),"")
A35: Cut_up | B35: 203087 | D35: Bulk Pack | E35: BSB | N35: PLATINUM | R35: =_xludf.IFNA(_xlfn.XLOOKUP(Table3[[#This Row],[SKU]],'03_BulkPack_Order'!$A$2:$A$67,'03_BulkPack_Order'!C:C),"") | S35: =IFERROR(R35*1,"") | T35: =_xludf.IFNA(_xlfn.XLOOKUP(Table3[[#This Row],[SKU]],'00_Yield_Rates'!$B$2:$B$17,'00_Yield_Rates'!$E$2:$E$17),"")
A36: Cut_up | B36: 203169 | D36: Bulk Pack | E36: BSB | N36: SILVER | R36: =_xludf.IFNA(_xlfn.XLOOKUP(Table3[[#This Row],[SKU]],'03_BulkPack_Order'!$A$2:$A$67,'03_BulkPack_Order'!C:C),"") | S36: =IFERROR(R36*1,"") | T36: =_xludf.IFNA(_xlfn.XLOOKUP(Table3[[#This Row],[SKU]],'00_Yield_Rates'!$B$2:$B$17,'00_Yield_Rates'!$E$2:$E$17),"")
A37: Cut_up | B37: 203171 | D37: Bulk Pack | E37: DRUM | N37: SILVER | R37: =_xludf.IFNA(_xlfn.XLOOKUP(Table3[[#This Row],[SKU]],'03_BulkPack_Order'!$A$2:$A$67,'03_BulkPack_Order'!C:C),"") | S37: =IFERROR(R37*1,"") | T37: =_xludf.IFNA(_xlfn.XLOOKUP(Table3[[#This Row],[SKU]],'00_Yield_Rates'!$B$2:$B$17,'00_Yield_Rates'!$E$2:$E$17),"")
A38: Cut_up | B38: 203172 | D38: Bulk Pack | E38: WING | F38: 25 | J38: MS HA WING RET 25KG | N38: SILVER | R38: =_xludf.IFNA(_xlfn.XLOOKUP(Table3[[#This Row],[SKU]],'03_BulkPack_Order'!$A$2:$A$67,'03_BulkPack_Order'!C:C),"") | S38: =IFERROR(R38*1,"") | T38: =_xludf.IFNA(_xlfn.XLOOKUP(Table3[[#This Row],[SKU]],'00_Yield_Rates'!$B$2:$B$17,'00_Yield_Rates'!$E$2:$E$17),"")
A39: Cut_up | B39: 203173 | D39: Bulk Pack | E39: SplitWing | J39: MS HA SPL WING RET 25KG | N39: SILVER | R39: =_xludf.IFNA(_xlfn.XLOOKUP(Table3[[#This Row],[SKU]],'03_BulkPack_Order'!$A$2:$A$67,'03_BulkPack_Order'!C:C),"") | S39: =IFERROR(R39*1,"") | T39: =_xludf.IFNA(_xlfn.XLOOKUP(Table3[[#This Row],[SKU]],'00_Yield_Rates'!$B$2:$B$17,'00_Yield_Rates'!$E$2:$E$17),"")
A40: Cut_up | B40: 203174 | D40: Bulk Pack | E40: ThighMeat | N40: SILVER | R40: =_xludf.IFNA(_xlfn.XLOOKUP(Table3[[#This Row],[SKU]],'03_BulkPack_Order'!$A$2:$A$67,'03_BulkPack_Order'!C:C),"") | S40: =IFERROR(R40*1,"") | T40: =_xludf.IFNA(_xlfn.XLOOKUP(Table3[[#This Row],[SKU]],'00_Yield_Rates'!$B$2:$B$17,'00_Yield_Rates'!$E$2:$E$17),"")
...

Sheet 01_Cages_Plan
B2: Cut up Plan | G2: 0.27083333
B3: Total Cages | C3: ='03_BulkPack_Order'!C2 | E3: RWA | G3: =(F3/C8*1/24) | O3: Flock # 1 | P3: Big Bird | Q3: 200141
B4: Total Cages Request | C4: ='03_BulkPack_Order'!C2-F7 | E4: MLF | F4: =SUM(K7:K11) | G4: =G3+(F4/C7*1/24) | H4: =F4/C7*1/24 | O4: Flock # 2 | P4: Small Bird | Q4: 200140
B5: Avg Cage weight | C5: 680 | E5: St. Fran | F5: =K12 | G5: =G4+(F5/C7*1/24) | H5: =F5/C7*1/24 | O5: Flock # 3 | P5: Small Bird | Q5: 200015
B6: Avg Bird weight | C6: 1.6 | E6: EVP | F6: =K13 | O6: Flock # 4 | Q6: St Francois
B7: Cages/Hour | C7: =60/(C5/C6/C9) | E7: Total: | F7: =SUM(F3:F6) | J7: 200190/191 | K7: 4 | L7: =K7/$C$7 | O7: Flock # 5 | Q7: Eden Valley
B8: Brids/cage | C8: 410 | J8: 200140 | K8: 33 | L8: =K8/$C$7 | M8: 1.3-1.6 | O8: Flock # 6 | P8: Mix Bird | Q8: 200023
B9: Machine Speed (BPM) | C9: 115 | J9: 200141 | K9: 38 | L9: =K9/$C$7 | M9: 1.6-2.3 | O9: Flock # 7 | P9: Big Bird | Q9: 200017
B10: RWA | C10: Bnls | D10: Split wing | E10: Thigh | F10: Drum | J10: 200150 | K10: 1 | L10: =K10/$C$7 | M10: 1.6-2.3 | O10: Flock # 19 | P10: Mix Bird | Q10: 200190
B11: =MAX(C11:F11) | C11: =B27 | D11: =B33 | E11: =B34 | F11: =B36 | J11: 200151 | L11: =K11/$C$7 | M11: 1.3-1.6
B12: EXTRA Case/25KG | C12: =(F3-C11)*C5*D26/25 | D12: =(F3-D11)*C5*D33/25 | E12: =(F3-E11)*C5*D34/25 | F12: =(F3-F11)*C5*D36/25 | J12: Saint Francois | K12: 30 | L12: =K12/$C$7 | M12: 1.8
F13: Need | H13: Cases left over | J13: Eden Valley | L13: =K13/$C$7
B14: Breast | C14: =B43 | E14: =IF(C11>F3,F3,C11) | F14: =C14+E14 | G14: Bnls | H14: =(C3-F14)*C5*'08_Chart_Data'!M9/25
B16: WINGS | C16: =B62 | E16: =IF(D11>F3,F3,D11) | F16: =C16+E16 | G16: Wings | H16: =(C3-F16)*C5*'08_Chart_Data'!M3/25
B18: THIGH | C18: =B76 | E18: =IF(E11>F3,F3,E11) | F18: =C18+E18 | G18: Thigh | H18: =(C3-F22-F18)*C5*'08_Chart_Data'!I23/25
B20: DRUM | C20: =B95 | E20: =IF(F11>F3,F3,F11) | F20: =C20+E20 | G20: Drums | H20: =(C3-F20-F22)*C5*'08_Chart_Data'!I18/25
B22: B.A LEG | C22: =B108 | F22: =C22
C25: Code | D25: % | E25: Cases | F25: Weight | G25: Cages | H25: Bird | I25: Time
B26: RWA | C26: 61051 | D26: =_xludf.IFNA(_xlfn.XLOOKUP(C26,'08_Chart_Data'!$Q$3:$Q$104,'08_Chart_Data'!$R$3:$R$104,0),"") | E26: =_xludf.IFNA(_xlfn.XLOOKUP(C26,'10_Cone_Line'!$A$3:$A$136,'10_Cone_Line'!$E$3:$E$136,0),"") | F26: =_xludf.IFNA(E26*_xlfn.XLOOKUP(C26,'08_Chart_Data'!$Q$3:$Q$104,'08_Chart_Data'!$S$3:$S$104,0)/D26,"") | G26: =IFERROR(F26/$C$5,"0") | H26: =IFERROR(F26/$C$6,"-") | I26: =IFERROR(IF(H26<0,"",(H26/$C$9)/1440),"")
B27: =SUMIF(G26:G32,">0") | C27: 61049 | D27: =_xludf.IFNA(_xlfn.XLOOKUP(C27,'08_Chart_Data'!$Q$3:$Q$104,'08_Chart_Data'!$R$3:$R$104,0),"") | E27: =_xludf.IFNA(_xlfn.XLOOKUP(C27,'10_Cone_Line'!$A$3:$A$136,'10_Cone_Line'!$E$3:$E$136,0),"") | F27: =_xludf.IFNA(E27*_xlfn.XLOOKUP(C27,'08_Chart_Data'!$Q$3:$Q$104,'08_Chart_Data'!$S$3:$S$104,0)/D27,"") | G27: =IFERROR(F27/$C$5,"0") | H27: =IFERROR(F27/$C$6,"-") | I27: =IFERROR(IF(H27<0,"",(H27/$C$9)/1440),"")
C28: 61042 | D28: =_xludf.IFNA(_xlfn.XLOOKUP(C28,'08_Chart_Data'!$Q$3:$Q$104,'08_Chart_Data'!$R$3:$R$104,0),"") | E28: =_xludf.IFNA(_xlfn.XLOOKUP(C28,'10_Cone_Line'!$A$3:$A$136,'10_Cone_Line'!$E$3:$E$136,0),"") | F28: =_xludf.IFNA(E28*_xlfn.XLOOKUP(C28,'08_Chart_Data'!$Q$3:$Q$104,'08_Chart_Data'!$S$3:$S$104,0)/D28,"") | G28: =IFERROR(F28/$C$5,"0") | H28: =IFERROR(F28/$C$6,"-") | I28: =IFERROR(IF(H28<0,"",(H28/$C$9)/1440),"")
C29: 1081 | D29: =_xludf.IFNA(_xlfn.XLOOKUP(C29,'08_Chart_Data'!$Q$3:$Q$104,'08_Chart_Data'!$R$3:$R$104,0),"") | E29: =_xludf.IFNA(_xlfn.XLOOKUP(C29,'10_Cone_Line'!$A$3:$A$136,'10_Cone_Line'!$E$3:$E$136,0),"") | F29: =_xludf.IFNA(E29*_xlfn.XLOOKUP(C29,'08_Chart_Data'!$Q$3:$Q$104,'08_Chart_Data'!$S$3:$S$104,0)/D29,"") | G29: =IFERROR(F29/$C$5,"0") | H29: =IFERROR(F29/$C$6,"-") | I29: =IFERROR(IF(H29<0,"",(H29/$C$9)/1440),"")
C30: 61070 | D30: =_xludf.IFNA(_xlfn.XLOOKUP(C30,'08_Chart_Data'!$Q$3:$Q$104,'08_Chart_Data'!$R$3:$R$104,0),"") | E30: =_xludf.IFNA(_xlfn.XLOOKUP(C30,'10_Cone_Line'!$A$3:$A$136,'10_Cone_Line'!$E$3:$E$136,0),"") | F30: =_xludf.IFNA(E30*_xlfn.XLOOKUP(C30,'08_Chart_Data'!$Q$3:$Q$104,'08_Chart_Data'!$S$3:$S$104,0)/D30,"") | G30: =IFERROR(F30/$C$5,"0") | H30: =IFERROR(F30/$C$6,"-") | I30: =IFERROR(IF(H30<0,"",(H30/$C$9)/1440),"")
D31: =_xludf.IFNA(_xlfn.XLOOKUP(C31,'08_Chart_Data'!$Q$3:$Q$104,'08_Chart_Data'!$R$3:$R$104,0),"") | E31: =_xludf.IFNA(_xlfn.XLOOKUP(C31,'10_Cone_Line'!$A$3:$A$136,'10_Cone_Line'!$E$3:$E$136,0),"") | F31: =_xludf.IFNA(E31*_xlfn.XLOOKUP(C31,'08_Chart_Data'!$Q$3:$Q$104,'08_Chart_Data'!$S$3:$S$104,0)/D31,"") | G31: =IFERROR(F31/$C$5,"0") | H31: =IFERROR(F31/$C$6,"-") | I31: =IFERROR(IF(H31<0,"",(H31/$C$9)/1440),"")
C32: 61069 | D32: =_xludf.IFNA(_xlfn.XLOOKUP(C32,'08_Chart_Data'!$Q$3:$Q$104,'08_Chart_Data'!$R$3:$R$104,0),"") | E32: =_xludf.IFNA(_xlfn.XLOOKUP(C32,'10_Cone_Line'!$A$3:$A$136,'10_Cone_Line'!$E$3:$E$136,0),"") | F32: =_xludf.IFNA(E32*_xlfn.XLOOKUP(C32,'08_Chart_Data'!$Q$3:$Q$104,'08_Chart_Data'!$S$3:$S$104,0)/D32,"") | G32: =IFERROR(F32/$C$5,"0") | H32: =IFERROR(F32/$C$6,"-") | I32: =IFERROR(IF(H32<0,"",(H32/$C$9)/1440),"")
B33: =SUMIF(G33,">0") | C33: 61016 | D33: =_xludf.IFNA(_xlfn.XLOOKUP(C33,'08_Chart_Data'!$Q$3:$Q$104,'08_Chart_Data'!$R$3:$R$104,0),"") | E33: =_xludf.IFNA(_xlfn.XLOOKUP(C33,'10_Cone_Line'!$A$3:$A$136,'10_Cone_Line'!$E$3:$E$136,0),"") | F33: =_xludf.IFNA(E33*_xlfn.XLOOKUP(C33,'08_Chart_Data'!$Q$3:$Q$104,'08_Chart_Data'!$S$3:$S$104,0)/D33,"") | G33: =IFERROR(F33/$C$5,"0") | H33: =IFERROR(F33/$C$6,"-") | I33: =IFERROR(IF(H33<0,"",(H33/$C$9)/1440),"")
B34: =SUMIF(G34:G35,">0") | C34: 61079 | D34: =_xludf.IFNA(_xlfn.XLOOKUP(C34,'08_Chart_Data'!$Q$3:$Q$104,'08_Chart_Data'!$R$3:$R$104,0),"") | E34: =_xludf.IFNA(_xlfn.XLOOKUP(C34,'10_Cone_Line'!$A$3:$A$136,'10_Cone_Line'!$E$3:$E$136,0),"") | F34: =_xludf.IFNA(E34*_xlfn.XLOOKUP(C34,'08_Chart_Data'!$Q$3:$Q$104,'08_Chart_Data'!$S$3:$S$104,0)/D34,"") | G34: =IFERROR(F34/$C$5,"0") | H34: =IFERROR(F34/$C$6,"-") | I34: =IFERROR(IF(H34<0,"",(H34/$C$9)/1440),"")
C35: 61087 | D35: =_xludf.IFNA(_xlfn.XLOOKUP(C35,'08_Chart_Data'!$Q$3:$Q$104,'08_Chart_Data'!$R$3:$R$104,0),"") | E35: =_xludf.IFNA(_xlfn.XLOOKUP(C35,'10_Cone_Line'!$A$3:$A$136,'10_Cone_Line'!$E$3:$E$136,0),"") | F35: =_xludf.IFNA(E35*_xlfn.XLOOKUP(C35,'08_Chart_Data'!$Q$3:$Q$104,'08_Chart_Data'!$S$3:$S$104,0)/D35,"") | G35: =IFERROR(F35/$C$5,"0") | H35: =IFERROR(F35/$C$6,"-") | I35: =IFERROR(IF(H35<0,"",(H35/$C$9)/1440),"")
B36: =SUMIF(G36:G37,">0") | C36: 61074 | D36: =_xludf.IFNA(_xlfn.XLOOKUP(C36,'08_Chart_Data'!$Q$3:$Q$104,'08_Chart_Data'!$R$3:$R$104,0),"") | E36: =_xludf.IFNA(_xlfn.XLOOKUP(C36,'10_Cone_Line'!$A$3:$A$136,'10_Cone_Line'!$E$3:$E$136,0),"") | F36: =_xludf.IFNA(E36*_xlfn.XLOOKUP(C36,'08_Chart_Data'!$Q$3:$Q$104,'08_Chart_Data'!$S$3:$S$104,0)/D36,"") | G36: =IFERROR(F36/$C$5,"0") | H36: =IFERROR(F36/$C$6,"-") | I36: =IFERROR(IF(H36<0,"",(H36/$C$9)/1440),"")
C37: 61076 | D37: =_xludf.IFNA(_xlfn.XLOOKUP(C37,'08_Chart_Data'!$Q$3:$Q$104,'08_Chart_Data'!$R$3:$R$104,0),"") | E37: =_xludf.IFNA(_xlfn.XLOOKUP(C37,'10_Cone_Line'!$A$3:$A$136,'10_Cone_Line'!$E$3:$E$136,0),"") | F37: =_xludf.IFNA(E37*_xlfn.XLOOKUP(C37,'08_Chart_Data'!$Q$3:$Q$104,'08_Chart_Data'!$S$3:$S$104,0)/D37,"") | G37: =IFERROR(F37/$C$5,"0") | H37: =IFERROR(F37/$C$6,"-") | I37: =IFERROR(IF(H37<0,"",(H37/$C$9)/1440),"")
E38: =_xludf.IFNA(_xlfn.XLOOKUP(C38,'10_Cone_Line'!$A$3:$A$136,'10_Cone_Line'!$E$3:$E$136,0),"") | F38: =_xludf.IFNA(E38*_xlfn.XLOOKUP(C38,'08_Chart_Data'!$Q$3:$Q$104,'08_Chart_Data'!$S$3:$S$104,0)/D38,"") | G38: =IFERROR(F38/$C$5,"0") | H38: =IFERROR(F38/$C$6,"-") | I38: =IFERROR(IF(H38<0,"",(H38/$C$9)/1440),"")
E39: =_xludf.IFNA(_xlfn.XLOOKUP(C39,'10_Cone_Line'!$A$3:$A$136,'10_Cone_Line'!$E$3:$E$136,0),"") | F39: =_xludf.IFNA(E39*_xlfn.XLOOKUP(C39,'08_Chart_Data'!$Q$3:$Q$104,'08_Chart_Data'!$S$3:$S$104,0)/D39,"") | G39: =IFERROR(F39/$C$5,"0") | H39: =IFERROR(F39/$C$6,"-") | I39: =IFERROR(IF(H39<0,"",(H39/$C$9)/1440),"")
E40: =_xludf.IFNA(_xlfn.XLOOKUP(C40,'10_Cone_Line'!$A$3:$A$136,'10_Cone_Line'!$E$3:$E$136,0),"") | F40: =_xludf.IFNA(E40*_xlfn.XLOOKUP(C40,'08_Chart_Data'!$Q$3:$Q$104,'08_Chart_Data'!$S$3:$S$104,0)/D40,"") | G40: =IFERROR(F40/$C$5,"0") | H40: =IFERROR(F40/$C$6,"-") | I40: =IFERROR(IF(H40<0,"",(H40/$C$9)/1440),"")
B41: Breast | C41: 61050F | D41: =_xludf.IFNA(_xlfn.XLOOKUP(C41,'00_SKU_Master'!$B$2:$B$378,'00_SKU_Master'!T:T)/100,"") | E41: =_xludf.IFNA(_xlfn.XLOOKUP(C41,'10_Cone_Line'!$A$3:$A$136,'10_Cone_Line'!$E$3:$E$136,0),"") | F41: =_xludf.IFNA(E41*_xlfn.XLOOKUP(C41,'08_Chart_Data'!$Q$3:$Q$104,'08_Chart_Data'!$S$3:$S$104,0)/D41,"") | G41: =IFERROR(F41/$C$5,"0") | H41: =IFERROR(F41/$C$6,"-") | I41: =IFERROR(IF(H41<0,"",(H41/$C$9)/1440),"")
C42: 61050 | D42: =_xludf.IFNA(_xlfn.XLOOKUP(C42,'00_SKU_Master'!$B$2:$B$378,'00_SKU_Master'!T:T)/100,"") | E42: =_xludf.IFNA(_xlfn.XLOOKUP(C42,'10_Cone_Line'!$A$3:$A$136,'10_Cone_Line'!$E$3:$E$136,0),"") | F42: =_xludf.IFNA(E42*_xlfn.XLOOKUP(C42,'08_Chart_Data'!$Q$3:$Q$104,'08_Chart_Data'!$S$3:$S$104,0)/D42,"") | G42: =IFERROR(F42/$C$5,"0") | H42: =IFERROR(F42/$C$6,"-") | I42: =IFERROR(IF(H42<0,"",(H42/$C$9)/1440),"")
B43: =SUMIF(G41:G59,">0") | C43: 1888 | D43: =_xludf.IFNA(_xlfn.XLOOKUP(C43,'00_SKU_Master'!$B$2:$B$378,'00_SKU_Master'!T:T)/100,"") | E43: =_xludf.IFNA(_xlfn.XLOOKUP(C43,'10_Cone_Line'!$A$3:$A$136,'10_Cone_Line'!$E$3:$E$136,0),"") | F43: =_xludf.IFNA(E43*_xlfn.XLOOKUP(C43,'08_Chart_Data'!$Q$3:$Q$104,'08_Chart_Data'!$S$3:$S$104,0)/D43,"") | G43: =IFERROR(F43/$C$5,"0") | H43: =IFERROR(F43/$C$6,"-") | I43: =IFERROR(IF(H43<0,"",(H43/$C$9)/1440),"")
C44: 61040#2 | D44: =_xludf.IFNA(_xlfn.XLOOKUP(C44,'00_SKU_Master'!$B$2:$B$378,'00_SKU_Master'!T:T)/100,"") | E44: =_xludf.IFNA(_xlfn.XLOOKUP(C44,'10_Cone_Line'!$A$3:$A$136,'10_Cone_Line'!$E$3:$E$136,0),"") | F44: =_xludf.IFNA(E44*_xlfn.XLOOKUP(C44,'08_Chart_Data'!$Q$3:$Q$104,'08_Chart_Data'!$S$3:$S$104,0)/D44,"") | G44: =IFERROR(F44/$C$5,"0") | H44: =IFERROR(F44/$C$6,"-") | I44: =IFERROR(IF(H44<0,"",(H44/$C$9)/1440),"")
B45: FFF | C45: 61048 | D45: =_xludf.IFNA(_xlfn.XLOOKUP(C45,'00_SKU_Master'!$B$2:$B$378,'00_SKU_Master'!T:T)/100,"") | E45: =_xludf.IFNA(_xlfn.XLOOKUP(C45,'10_Cone_Line'!$A$3:$A$136,'10_Cone_Line'!$E$3:$E$136,0),"") | F45: =_xludf.IFNA(E45*_xlfn.XLOOKUP(C45,'08_Chart_Data'!$Q$3:$Q$104,'08_Chart_Data'!$S$3:$S$104,0)/D45,"") | G45: =IFERROR(F45/$C$5,"0") | H45: =IFERROR(F45/$C$6,"-") | I45: =IFERROR(IF(H45<0,"",(H45/$C$9)/1440),"")
B46: =G41 | C46: 61052 | D46: =_xludf.IFNA(_xlfn.XLOOKUP(C46,'00_SKU_Master'!$B$2:$B$378,'00_SKU_Master'!T:T)/100,"") | E46: =_xludf.IFNA(_xlfn.XLOOKUP(C46,'10_Cone_Line'!$A$3:$A$136,'10_Cone_Line'!$E$3:$E$136,0),"") | F46: =_xludf.IFNA(E46*_xlfn.XLOOKUP(C46,'08_Chart_Data'!$Q$3:$Q$104,'08_Chart_Data'!$S$3:$S$104,0)/D46,"") | G46: =IFERROR(F46/$C$5,"0") | H46: =IFERROR(F46/$C$6,"-") | I46: =IFERROR(IF(H46<0,"",(H46/$C$9)/1440),"")
C47: 200083 | D47: =_xludf.IFNA(_xlfn.XLOOKUP(C47,'00_SKU_Master'!$B$2:$B$378,'00_SKU_Master'!T:T)/100,"") | E47: =_xludf.IFNA(_xlfn.XLOOKUP(C47,'10_Cone_Line'!$A$3:$A$136,'10_Cone_Line'!$E$3:$E$136,0),"") | F47: =_xludf.IFNA(E47*_xlfn.XLOOKUP(C47,'08_Chart_Data'!$Q$3:$Q$104,'08_Chart_Data'!$S$3:$S$104,0)/D47,"") | G47: =IFERROR(F47/$C$5,"0") | H47: =IFERROR(F47/$C$6,"-") | I47: =IFERROR(IF(H47<0,"",(H47/$C$9)/1440),"")
...

Sheet 02_TrayPack_Order
A1: Code | B1: Extra Cases Produced | C1: Cases Remaining To Be Produced | D1: "+/-" | E1: Order + Add ON | L1: Total | M1: WIP CODE | T1: Total | U1: Category
A2: ='05_Daily_Orders'!B3 | B2: 0 | C2: 0 | F2: 0 | L2: =IF($E$1="n",0,(SUM(F4:K4)-B4)) | M2: =_xludf.IFNA(_xlfn.XLOOKUP(A4,'00_SKU_Master'!$B$2:$B$378,'00_SKU_Master'!$C$2:$C$378,0),"") | N2: =_xludf.IFNA(_xlfn.XLOOKUP(A4,'00_SKU_Master'!$B$2:$B$378,'00_SKU_Master'!$F$2:$F$378,0)*F4/_xlfn.XLOOKUP(A4,'00_SKU_Master'!$B$2:$B$378,'00_SKU_Master'!$O:$O,0),"") | O2: =_xludf.IFNA(_xlfn.XLOOKUP($A4,'00_SKU_Master'!$B$2:$B$378,'00_SKU_Master'!$F$2:$F$378,0)*G4/_xlfn.XLOOKUP($A4,'00_SKU_Master'!$B$2:$B$378,'00_SKU_Master'!$O:$O,0),"") | P2: =_xludf.IFNA(_xlfn.XLOOKUP($A4,'00_SKU_Master'!$B$2:$B$378,'00_SKU_Master'!$F$2:$F$378,0)*H4/_xlfn.XLOOKUP($A4,'00_SKU_Master'!$B$2:$B$378,'00_SKU_Master'!$O:$O,0),"") | Q2: =_xludf.IFNA(_xlfn.XLOOKUP($A4,'00_SKU_Master'!$B$2:$B$378,'00_SKU_Master'!$F$2:$F$378,0)*I4/_xlfn.XLOOKUP($A4,'00_SKU_Master'!$B$2:$B$378,'00_SKU_Master'!$O:$O,0),"") | R2: =_xludf.IFNA(_xlfn.XLOOKUP($A4,'00_SKU_Master'!$B$2:$B$378,'00_SKU_Master'!$F$2:$F$378,0)*J4/_xlfn.XLOOKUP($A4,'00_SKU_Master'!$B$2:$B$378,'00_SKU_Master'!$O:$O,0),"") | S2: =_xludf.IFNA(_xlfn.XLOOKUP($A4,'00_SKU_Master'!$B$2:$B$378,'00_SKU_Master'!$F$2:$F$378,0)*K4/_xlfn.XLOOKUP($A4,'00_SKU_Master'!$B$2:$B$378,'00_SKU_Master'!$O:$O,0),"") | T2: =SUM(N4:S4) | U2: ='05_Daily_Orders'!L3
A3: ='05_Daily_Orders'!B4 | B3: 0 | C3: 5 | F3: 0 | L3: =IF($E$1="n",0,(SUM(F5:K5)-B5)) | M3: =_xludf.IFNA(_xlfn.XLOOKUP(A5,'00_SKU_Master'!$B$2:$B$378,'00_SKU_Master'!$C$2:$C$378,0),"") | N3: =_xludf.IFNA(_xlfn.XLOOKUP(A5,'00_SKU_Master'!$B$2:$B$378,'00_SKU_Master'!$F$2:$F$378,0)*F5/_xlfn.XLOOKUP(A5,'00_SKU_Master'!$B$2:$B$378,'00_SKU_Master'!$O:$O,0),"") | O3: =_xludf.IFNA(_xlfn.XLOOKUP($A5,'00_SKU_Master'!$B$2:$B$378,'00_SKU_Master'!$F$2:$F$378,0)*G5/_xlfn.XLOOKUP($A5,'00_SKU_Master'!$B$2:$B$378,'00_SKU_Master'!$O:$O,0),"") | P3: =_xludf.IFNA(_xlfn.XLOOKUP($A5,'00_SKU_Master'!$B$2:$B$378,'00_SKU_Master'!$F$2:$F$378,0)*H5/_xlfn.XLOOKUP($A5,'00_SKU_Master'!$B$2:$B$378,'00_SKU_Master'!$O:$O,0),"") | Q3: =_xludf.IFNA(_xlfn.XLOOKUP($A5,'00_SKU_Master'!$B$2:$B$378,'00_SKU_Master'!$F$2:$F$378,0)*I5/_xlfn.XLOOKUP($A5,'00_SKU_Master'!$B$2:$B$378,'00_SKU_Master'!$O:$O,0),"") | R3: =_xludf.IFNA(_xlfn.XLOOKUP($A5,'00_SKU_Master'!$B$2:$B$378,'00_SKU_Master'!$F$2:$F$378,0)*J5/_xlfn.XLOOKUP($A5,'00_SKU_Master'!$B$2:$B$378,'00_SKU_Master'!$O:$O,0),"") | S3: =_xludf.IFNA(_xlfn.XLOOKUP($A5,'00_SKU_Master'!$B$2:$B$378,'00_SKU_Master'!$F$2:$F$378,0)*K5/_xlfn.XLOOKUP($A5,'00_SKU_Master'!$B$2:$B$378,'00_SKU_Master'!$O:$O,0),"") | T3: =SUM(N5:S5) | U3: ='05_Daily_Orders'!L4
A4: ='05_Daily_Orders'!B5 | B4: 0 | C4: 0 | F4: 0 | L4: =IF($E$1="n",0,(SUM(F6:K6)-B6)) | M4: =_xludf.IFNA(_xlfn.XLOOKUP(A6,'00_SKU_Master'!$B$2:$B$378,'00_SKU_Master'!$C$2:$C$378,0),"") | N4: =_xludf.IFNA(_xlfn.XLOOKUP(A6,'00_SKU_Master'!$B$2:$B$378,'00_SKU_Master'!$F$2:$F$378,0)*F6/_xlfn.XLOOKUP(A6,'00_SKU_Master'!$B$2:$B$378,'00_SKU_Master'!$O:$O,0),"") | O4: =_xludf.IFNA(_xlfn.XLOOKUP($A6,'00_SKU_Master'!$B$2:$B$378,'00_SKU_Master'!$F$2:$F$378,0)*G6/_xlfn.XLOOKUP($A6,'00_SKU_Master'!$B$2:$B$378,'00_SKU_Master'!$O:$O,0),"") | P4: =_xludf.IFNA(_xlfn.XLOOKUP($A6,'00_SKU_Master'!$B$2:$B$378,'00_SKU_Master'!$F$2:$F$378,0)*H6/_xlfn.XLOOKUP($A6,'00_SKU_Master'!$B$2:$B$378,'00_SKU_Master'!$O:$O,0),"") | Q4: =_xludf.IFNA(_xlfn.XLOOKUP($A6,'00_SKU_Master'!$B$2:$B$378,'00_SKU_Master'!$F$2:$F$378,0)*I6/_xlfn.XLOOKUP($A6,'00_SKU_Master'!$B$2:$B$378,'00_SKU_Master'!$O:$O,0),"") | R4: =_xludf.IFNA(_xlfn.XLOOKUP($A6,'00_SKU_Master'!$B$2:$B$378,'00_SKU_Master'!$F$2:$F$378,0)*J6/_xlfn.XLOOKUP($A6,'00_SKU_Master'!$B$2:$B$378,'00_SKU_Master'!$O:$O,0),"") | S4: =_xludf.IFNA(_xlfn.XLOOKUP($A6,'00_SKU_Master'!$B$2:$B$378,'00_SKU_Master'!$F$2:$F$378,0)*K6/_xlfn.XLOOKUP($A6,'00_SKU_Master'!$B$2:$B$378,'00_SKU_Master'!$O:$O,0),"") | T4: =SUM(N6:S6) | U4: ='05_Daily_Orders'!L5
A5: ='05_Daily_Orders'!B6 | B5: 0 | C5: 9 | F5: 44 | L5: =IF($E$1="n",0,(SUM(F7:K7)-B7)) | M5: =_xludf.IFNA(_xlfn.XLOOKUP(A7,'00_SKU_Master'!$B$2:$B$378,'00_SKU_Master'!$C$2:$C$378,0),"") | N5: =_xludf.IFNA(_xlfn.XLOOKUP(A7,'00_SKU_Master'!$B$2:$B$378,'00_SKU_Master'!$F$2:$F$378,0)*F7/_xlfn.XLOOKUP(A7,'00_SKU_Master'!$B$2:$B$378,'00_SKU_Master'!$O:$O,0),"") | O5: =_xludf.IFNA(_xlfn.XLOOKUP($A7,'00_SKU_Master'!$B$2:$B$378,'00_SKU_Master'!$F$2:$F$378,0)*G7/_xlfn.XLOOKUP($A7,'00_SKU_Master'!$B$2:$B$378,'00_SKU_Master'!$O:$O,0),"") | P5: =_xludf.IFNA(_xlfn.XLOOKUP($A7,'00_SKU_Master'!$B$2:$B$378,'00_SKU_Master'!$F$2:$F$378,0)*H7/_xlfn.XLOOKUP($A7,'00_SKU_Master'!$B$2:$B$378,'00_SKU_Master'!$O:$O,0),"") | Q5: =_xludf.IFNA(_xlfn.XLOOKUP($A7,'00_SKU_Master'!$B$2:$B$378,'00_SKU_Master'!$F$2:$F$378,0)*I7/_xlfn.XLOOKUP($A7,'00_SKU_Master'!$B$2:$B$378,'00_SKU_Master'!$O:$O,0),"") | R5: =_xludf.IFNA(_xlfn.XLOOKUP($A7,'00_SKU_Master'!$B$2:$B$378,'00_SKU_Master'!$F$2:$F$378,0)*J7/_xlfn.XLOOKUP($A7,'00_SKU_Master'!$B$2:$B$378,'00_SKU_Master'!$O:$O,0),"") | S5: =_xludf.IFNA(_xlfn.XLOOKUP($A7,'00_SKU_Master'!$B$2:$B$378,'00_SKU_Master'!$F$2:$F$378,0)*K7/_xlfn.XLOOKUP($A7,'00_SKU_Master'!$B$2:$B$378,'00_SKU_Master'!$O:$O,0),"") | T5: =SUM(N7:S7) | U5: ='05_Daily_Orders'!L6
A6: ='05_Daily_Orders'!B7 | B6: 1 | C6: 0 | F6: 150 | L6: =IF($E$1="n",0,(SUM(F8:K8)-B8)) | M6: =_xludf.IFNA(_xlfn.XLOOKUP(A8,'00_SKU_Master'!$B$2:$B$378,'00_SKU_Master'!$C$2:$C$378,0),"") | N6: =_xludf.IFNA(_xlfn.XLOOKUP(A8,'00_SKU_Master'!$B$2:$B$378,'00_SKU_Master'!$F$2:$F$378,0)*F8/_xlfn.XLOOKUP(A8,'00_SKU_Master'!$B$2:$B$378,'00_SKU_Master'!$O:$O,0),"") | O6: =_xludf.IFNA(_xlfn.XLOOKUP($A8,'00_SKU_Master'!$B$2:$B$378,'00_SKU_Master'!$F$2:$F$378,0)*G8/_xlfn.XLOOKUP($A8,'00_SKU_Master'!$B$2:$B$378,'00_SKU_Master'!$O:$O,0),"") | P6: =_xludf.IFNA(_xlfn.XLOOKUP($A8,'00_SKU_Master'!$B$2:$B$378,'00_SKU_Master'!$F$2:$F$378,0)*H8/_xlfn.XLOOKUP($A8,'00_SKU_Master'!$B$2:$B$378,'00_SKU_Master'!$O:$O,0),"") | Q6: =_xludf.IFNA(_xlfn.XLOOKUP($A8,'00_SKU_Master'!$B$2:$B$378,'00_SKU_Master'!$F$2:$F$378,0)*I8/_xlfn.XLOOKUP($A8,'00_SKU_Master'!$B$2:$B$378,'00_SKU_Master'!$O:$O,0),"") | R6: =_xludf.IFNA(_xlfn.XLOOKUP($A8,'00_SKU_Master'!$B$2:$B$378,'00_SKU_Master'!$F$2:$F$378,0)*J8/_xlfn.XLOOKUP($A8,'00_SKU_Master'!$B$2:$B$378,'00_SKU_Master'!$O:$O,0),"") | S6: =_xludf.IFNA(_xlfn.XLOOKUP($A8,'00_SKU_Master'!$B$2:$B$378,'00_SKU_Master'!$F$2:$F$378,0)*K8/_xlfn.XLOOKUP($A8,'00_SKU_Master'!$B$2:$B$378,'00_SKU_Master'!$O:$O,0),"") | T6: =SUM(N8:S8) | U6: ='05_Daily_Orders'!L7
A7: ='05_Daily_Orders'!B8 | B7: 0 | C7: 0 | F7: 0 | L7: =IF($E$1="n",0,(SUM(F9:K9)-B9)) | M7: =_xludf.IFNA(_xlfn.XLOOKUP(A9,'00_SKU_Master'!$B$2:$B$378,'00_SKU_Master'!$C$2:$C$378,0),"") | N7: =_xludf.IFNA(_xlfn.XLOOKUP(A9,'00_SKU_Master'!$B$2:$B$378,'00_SKU_Master'!$F$2:$F$378,0)*F9/_xlfn.XLOOKUP(A9,'00_SKU_Master'!$B$2:$B$378,'00_SKU_Master'!$O:$O,0),"") | O7: =_xludf.IFNA(_xlfn.XLOOKUP($A9,'00_SKU_Master'!$B$2:$B$378,'00_SKU_Master'!$F$2:$F$378,0)*G9/_xlfn.XLOOKUP($A9,'00_SKU_Master'!$B$2:$B$378,'00_SKU_Master'!$O:$O,0),"") | P7: =_xludf.IFNA(_xlfn.XLOOKUP($A9,'00_SKU_Master'!$B$2:$B$378,'00_SKU_Master'!$F$2:$F$378,0)*H9/_xlfn.XLOOKUP($A9,'00_SKU_Master'!$B$2:$B$378,'00_SKU_Master'!$O:$O,0),"") | Q7: =_xludf.IFNA(_xlfn.XLOOKUP($A9,'00_SKU_Master'!$B$2:$B$378,'00_SKU_Master'!$F$2:$F$378,0)*I9/_xlfn.XLOOKUP($A9,'00_SKU_Master'!$B$2:$B$378,'00_SKU_Master'!$O:$O,0),"") | R7: =_xludf.IFNA(_xlfn.XLOOKUP($A9,'00_SKU_Master'!$B$2:$B$378,'00_SKU_Master'!$F$2:$F$378,0)*J9/_xlfn.XLOOKUP($A9,'00_SKU_Master'!$B$2:$B$378,'00_SKU_Master'!$O:$O,0),"") | S7: =_xludf.IFNA(_xlfn.XLOOKUP($A9,'00_SKU_Master'!$B$2:$B$378,'00_SKU_Master'!$F$2:$F$378,0)*K9/_xlfn.XLOOKUP($A9,'00_SKU_Master'!$B$2:$B$378,'00_SKU_Master'!$O:$O,0),"") | T7: =SUM(N9:S9) | U7: ='05_Daily_Orders'!L8
A8: ='05_Daily_Orders'!B9 | B8: 0 | C8: 0 | F8: 0 | L8: =IF($E$1="n",0,(SUM(F10:K10)-B10)) | M8: =_xludf.IFNA(_xlfn.XLOOKUP(A10,'00_SKU_Master'!$B$2:$B$378,'00_SKU_Master'!$C$2:$C$378,0),"") | N8: =_xludf.IFNA(_xlfn.XLOOKUP(A10,'00_SKU_Master'!$B$2:$B$378,'00_SKU_Master'!$F$2:$F$378,0)*F10/_xlfn.XLOOKUP(A10,'00_SKU_Master'!$B$2:$B$378,'00_SKU_Master'!$O:$O,0),"") | O8: =_xludf.IFNA(_xlfn.XLOOKUP($A10,'00_SKU_Master'!$B$2:$B$378,'00_SKU_Master'!$F$2:$F$378,0)*G10/_xlfn.XLOOKUP($A10,'00_SKU_Master'!$B$2:$B$378,'00_SKU_Master'!$O:$O,0),"") | P8: =_xludf.IFNA(_xlfn.XLOOKUP($A10,'00_SKU_Master'!$B$2:$B$378,'00_SKU_Master'!$F$2:$F$378,0)*H10/_xlfn.XLOOKUP($A10,'00_SKU_Master'!$B$2:$B$378,'00_SKU_Master'!$O:$O,0),"") | Q8: =_xludf.IFNA(_xlfn.XLOOKUP($A10,'00_SKU_Master'!$B$2:$B$378,'00_SKU_Master'!$F$2:$F$378,0)*I10/_xlfn.XLOOKUP($A10,'00_SKU_Master'!$B$2:$B$378,'00_SKU_Master'!$O:$O,0),"") | R8: =_xludf.IFNA(_xlfn.XLOOKUP($A10,'00_SKU_Master'!$B$2:$B$378,'00_SKU_Master'!$F$2:$F$378,0)*J10/_xlfn.XLOOKUP($A10,'00_SKU_Master'!$B$2:$B$378,'00_SKU_Master'!$O:$O,0),"") | S8: =_xludf.IFNA(_xlfn.XLOOKUP($A10,'00_SKU_Master'!$B$2:$B$378,'00_SKU_Master'!$F$2:$F$378,0)*K10/_xlfn.XLOOKUP($A10,'00_SKU_Master'!$B$2:$B$378,'00_SKU_Master'!$O:$O,0),"") | T8: =SUM(N10:S10) | U8: ='05_Daily_Orders'!L9
A9: ='05_Daily_Orders'!B10 | B9: 0 | C9: 0 | F9: 0 | L9: =IF($E$1="n",0,(SUM(F11:K11)-B11)) | M9: =_xludf.IFNA(_xlfn.XLOOKUP(A11,'00_SKU_Master'!$B$2:$B$378,'00_SKU_Master'!$C$2:$C$378,0),"") | N9: =_xludf.IFNA(_xlfn.XLOOKUP(A11,'00_SKU_Master'!$B$2:$B$378,'00_SKU_Master'!$F$2:$F$378,0)*F11/_xlfn.XLOOKUP(A11,'00_SKU_Master'!$B$2:$B$378,'00_SKU_Master'!$O:$O,0),"") | O9: =_xludf.IFNA(_xlfn.XLOOKUP($A11,'00_SKU_Master'!$B$2:$B$378,'00_SKU_Master'!$F$2:$F$378,0)*G11/_xlfn.XLOOKUP($A11,'00_SKU_Master'!$B$2:$B$378,'00_SKU_Master'!$O:$O,0),"") | P9: =_xludf.IFNA(_xlfn.XLOOKUP($A11,'00_SKU_Master'!$B$2:$B$378,'00_SKU_Master'!$F$2:$F$378,0)*H11/_xlfn.XLOOKUP($A11,'00_SKU_Master'!$B$2:$B$378,'00_SKU_Master'!$O:$O,0),"") | Q9: =_xludf.IFNA(_xlfn.XLOOKUP($A11,'00_SKU_Master'!$B$2:$B$378,'00_SKU_Master'!$F$2:$F$378,0)*I11/_xlfn.XLOOKUP($A11,'00_SKU_Master'!$B$2:$B$378,'00_SKU_Master'!$O:$O,0),"") | R9: =_xludf.IFNA(_xlfn.XLOOKUP($A11,'00_SKU_Master'!$B$2:$B$378,'00_SKU_Master'!$F$2:$F$378,0)*J11/_xlfn.XLOOKUP($A11,'00_SKU_Master'!$B$2:$B$378,'00_SKU_Master'!$O:$O,0),"") | S9: =_xludf.IFNA(_xlfn.XLOOKUP($A11,'00_SKU_Master'!$B$2:$B$378,'00_SKU_Master'!$F$2:$F$378,0)*K11/_xlfn.XLOOKUP($A11,'00_SKU_Master'!$B$2:$B$378,'00_SKU_Master'!$O:$O,0),"") | T9: =SUM(N11:S11) | U9: ='05_Daily_Orders'!L10
A10: ='05_Daily_Orders'!B11 | B10: 0 | C10: 12 | F10: 0 | L10: =IF($E$1="n",0,(SUM(F12:K12)-B12)) | M10: =_xludf.IFNA(_xlfn.XLOOKUP(A12,'00_SKU_Master'!$B$2:$B$378,'00_SKU_Master'!$C$2:$C$378,0),"") | N10: =_xludf.IFNA(_xlfn.XLOOKUP(A12,'00_SKU_Master'!$B$2:$B$378,'00_SKU_Master'!$F$2:$F$378,0)*F12/_xlfn.XLOOKUP(A12,'00_SKU_Master'!$B$2:$B$378,'00_SKU_Master'!$O:$O,0),"") | O10: =_xludf.IFNA(_xlfn.XLOOKUP($A12,'00_SKU_Master'!$B$2:$B$378,'00_SKU_Master'!$F$2:$F$378,0)*G12/_xlfn.XLOOKUP($A12,'00_SKU_Master'!$B$2:$B$378,'00_SKU_Master'!$O:$O,0),"") | P10: =_xludf.IFNA(_xlfn.XLOOKUP($A12,'00_SKU_Master'!$B$2:$B$378,'00_SKU_Master'!$F$2:$F$378,0)*H12/_xlfn.XLOOKUP($A12,'00_SKU_Master'!$B$2:$B$378,'00_SKU_Master'!$O:$O,0),"") | Q10: =_xludf.IFNA(_xlfn.XLOOKUP($A12,'00_SKU_Master'!$B$2:$B$378,'00_SKU_Master'!$F$2:$F$378,0)*I12/_xlfn.XLOOKUP($A12,'00_SKU_Master'!$B$2:$B$378,'00_SKU_Master'!$O:$O,0),"") | R10: =_xludf.IFNA(_xlfn.XLOOKUP($A12,'00_SKU_Master'!$B$2:$B$378,'00_SKU_Master'!$F$2:$F$378,0)*J12/_xlfn.XLOOKUP($A12,'00_SKU_Master'!$B$2:$B$378,'00_SKU_Master'!$O:$O,0),"") | S10: =_xludf.IFNA(_xlfn.XLOOKUP($A12,'00_SKU_Master'!$B$2:$B$378,'00_SKU_Master'!$F$2:$F$378,0)*K12/_xlfn.XLOOKUP($A12,'00_SKU_Master'!$B$2:$B$378,'00_SKU_Master'!$O:$O,0),"") | T10: =SUM(N12:S12) | U10: ='05_Daily_Orders'!L11
A11: ='05_Daily_Orders'!B12 | B11: 49 | C11: 0 | F11: 78 | L11: =IF($E$1="n",0,(SUM(F13:K13)-B13)) | M11: =_xludf.IFNA(_xlfn.XLOOKUP(A13,'00_SKU_Master'!$B$2:$B$378,'00_SKU_Master'!$C$2:$C$378,0),"") | N11: =_xludf.IFNA(_xlfn.XLOOKUP(A13,'00_SKU_Master'!$B$2:$B$378,'00_SKU_Master'!$F$2:$F$378,0)*F13/_xlfn.XLOOKUP(A13,'00_SKU_Master'!$B$2:$B$378,'00_SKU_Master'!$O:$O,0),"") | O11: =_xludf.IFNA(_xlfn.XLOOKUP($A13,'00_SKU_Master'!$B$2:$B$378,'00_SKU_Master'!$F$2:$F$378,0)*G13/_xlfn.XLOOKUP($A13,'00_SKU_Master'!$B$2:$B$378,'00_SKU_Master'!$O:$O,0),"") | P11: =_xludf.IFNA(_xlfn.XLOOKUP($A13,'00_SKU_Master'!$B$2:$B$378,'00_SKU_Master'!$F$2:$F$378,0)*H13/_xlfn.XLOOKUP($A13,'00_SKU_Master'!$B$2:$B$378,'00_SKU_Master'!$O:$O,0),"") | Q11: =_xludf.IFNA(_xlfn.XLOOKUP($A13,'00_SKU_Master'!$B$2:$B$378,'00_SKU_Master'!$F$2:$F$378,0)*I13/_xlfn.XLOOKUP($A13,'00_SKU_Master'!$B$2:$B$378,'00_SKU_Master'!$O:$O,0),"") | R11: =_xludf.IFNA(_xlfn.XLOOKUP($A13,'00_SKU_Master'!$B$2:$B$378,'00_SKU_Master'!$F$2:$F$378,0)*J13/_xlfn.XLOOKUP($A13,'00_SKU_Master'!$B$2:$B$378,'00_SKU_Master'!$O:$O,0),"") | S11: =_xludf.IFNA(_xlfn.XLOOKUP($A13,'00_SKU_Master'!$B$2:$B$378,'00_SKU_Master'!$F$2:$F$378,0)*K13/_xlfn.XLOOKUP($A13,'00_SKU_Master'!$B$2:$B$378,'00_SKU_Master'!$O:$O,0),"") | T11: =SUM(N13:S13) | U11: ='05_Daily_Orders'!L12
A12: ='05_Daily_Orders'!B13 | B12: 0 | C12: 88 | F12: 125 | L12: =IF($E$1="n",0,(SUM(F14:K14)-B14)) | M12: =_xludf.IFNA(_xlfn.XLOOKUP(A14,'00_SKU_Master'!$B$2:$B$378,'00_SKU_Master'!$C$2:$C$378,0),"") | N12: =_xludf.IFNA(_xlfn.XLOOKUP(A14,'00_SKU_Master'!$B$2:$B$378,'00_SKU_Master'!$F$2:$F$378,0)*F14/_xlfn.XLOOKUP(A14,'00_SKU_Master'!$B$2:$B$378,'00_SKU_Master'!$O:$O,0),"") | O12: =_xludf.IFNA(_xlfn.XLOOKUP($A14,'00_SKU_Master'!$B$2:$B$378,'00_SKU_Master'!$F$2:$F$378,0)*G14/_xlfn.XLOOKUP($A14,'00_SKU_Master'!$B$2:$B$378,'00_SKU_Master'!$O:$O,0),"") | P12: =_xludf.IFNA(_xlfn.XLOOKUP($A14,'00_SKU_Master'!$B$2:$B$378,'00_SKU_Master'!$F$2:$F$378,0)*H14/_xlfn.XLOOKUP($A14,'00_SKU_Master'!$B$2:$B$378,'00_SKU_Master'!$O:$O,0),"") | Q12: =_xludf.IFNA(_xlfn.XLOOKUP($A14,'00_SKU_Master'!$B$2:$B$378,'00_SKU_Master'!$F$2:$F$378,0)*I14/_xlfn.XLOOKUP($A14,'00_SKU_Master'!$B$2:$B$378,'00_SKU_Master'!$O:$O,0),"") | R12: =_xludf.IFNA(_xlfn.XLOOKUP($A14,'00_SKU_Master'!$B$2:$B$378,'00_SKU_Master'!$F$2:$F$378,0)*J14/_xlfn.XLOOKUP($A14,'00_SKU_Master'!$B$2:$B$378,'00_SKU_Master'!$O:$O,0),"") | S12: =_xludf.IFNA(_xlfn.XLOOKUP($A14,'00_SKU_Master'!$B$2:$B$378,'00_SKU_Master'!$F$2:$F$378,0)*K14/_xlfn.XLOOKUP($A14,'00_SKU_Master'!$B$2:$B$378,'00_SKU_Master'!$O:$O,0),"") | T12: =SUM(N14:S14) | U12: ='05_Daily_Orders'!L13
A13: ='05_Daily_Orders'!B14 | B13: 0 | C13: 0 | F13: 0 | L13: =IF($E$1="n",0,(SUM(F15:K15)-B15)) | M13: =_xludf.IFNA(_xlfn.XLOOKUP(A15,'00_SKU_Master'!$B$2:$B$378,'00_SKU_Master'!$C$2:$C$378,0),"") | N13: =_xludf.IFNA(_xlfn.XLOOKUP(A15,'00_SKU_Master'!$B$2:$B$378,'00_SKU_Master'!$F$2:$F$378,0)*F15/_xlfn.XLOOKUP(A15,'00_SKU_Master'!$B$2:$B$378,'00_SKU_Master'!$O:$O,0),"") | O13: =_xludf.IFNA(_xlfn.XLOOKUP($A15,'00_SKU_Master'!$B$2:$B$378,'00_SKU_Master'!$F$2:$F$378,0)*G15/_xlfn.XLOOKUP($A15,'00_SKU_Master'!$B$2:$B$378,'00_SKU_Master'!$O:$O,0),"") | P13: =_xludf.IFNA(_xlfn.XLOOKUP($A15,'00_SKU_Master'!$B$2:$B$378,'00_SKU_Master'!$F$2:$F$378,0)*H15/_xlfn.XLOOKUP($A15,'00_SKU_Master'!$B$2:$B$378,'00_SKU_Master'!$O:$O,0),"") | Q13: =_xludf.IFNA(_xlfn.XLOOKUP($A15,'00_SKU_Master'!$B$2:$B$378,'00_SKU_Master'!$F$2:$F$378,0)*I15/_xlfn.XLOOKUP($A15,'00_SKU_Master'!$B$2:$B$378,'00_SKU_Master'!$O:$O,0),"") | R13: =_xludf.IFNA(_xlfn.XLOOKUP($A15,'00_SKU_Master'!$B$2:$B$378,'00_SKU_Master'!$F$2:$F$378,0)*J15/_xlfn.XLOOKUP($A15,'00_SKU_Master'!$B$2:$B$378,'00_SKU_Master'!$O:$O,0),"") | S13: =_xludf.IFNA(_xlfn.XLOOKUP($A15,'00_SKU_Master'!$B$2:$B$378,'00_SKU_Master'!$F$2:$F$378,0)*K15/_xlfn.XLOOKUP($A15,'00_SKU_Master'!$B$2:$B$378,'00_SKU_Master'!$O:$O,0),"") | T13: =SUM(N15:S15) | U13: ='05_Daily_Orders'!L14
... A264: ='05_Daily_Orders'!B265 | B264: 0 | C264: 0 | F264: 0 | L264: =IF($E$1="n",0,(SUM(F266:K266)-B266)) | M264: =_xludf.IFNA(_xlfn.XLOOKUP(A266,'00_SKU_Master'!$B$2:$B$378,'00_SKU_Master'!$C$2:$C$378,0),"") | N264: =_xludf.IFNA(_xlfn.XLOOKUP(A266,'00_SKU_Master'!$B$2:$B$378,'00_SKU_Master'!$F$2:$F$378,0)*F266/_xlfn.XLOOKUP(A266,'00_SKU_Master'!$B$2:$B$378,'00_SKU_Master'!$O:$O,0),"") | O264: =_xludf.IFNA(_xlfn.XLOOKUP($A266,'00_SKU_Master'!$B$2:$B$378,'00_SKU_Master'!$F$2:$F$378,0)*G266/_xlfn.XLOOKUP($A266,'00_SKU_Master'!$B$2:$B$378,'00_SKU_Master'!$O:$O,0),"") | P264: =_xludf.IFNA(_xlfn.XLOOKUP($A266,'00_SKU_Master'!$B$2:$B$378,'00_SKU_Master'!$F$2:$F$378,0)*H266/_xlfn.XLOOKUP($A266,'00_SKU_Master'!$B$2:$B$378,'00_SKU_Master'!$O:$O,0),"") | Q264: =_xludf.IFNA(_xlfn.XLOOKUP($A266,'00_SKU_Master'!$B$2:$B$378,'00_SKU_Master'!$F$2:$F$378,0)*I266/_xlfn.XLOOKUP($A266,'00_SKU_Master'!$B$2:$B$378,'00_SKU_Master'!$O:$O,0),"") | R264: =_xludf.IFNA(_xlfn.XLOOKUP($A266,'00_SKU_Master'!$B$2:$B$378,'00_SKU_Master'!$F$2:$F$378,0)*J266/_xlfn.XLOOKUP($A266,'00_SKU_Master'!$B$2:$B$378,'00_SKU_Master'!$O:$O,0),"") | S264: =_xludf.IFNA(_xlfn.XLOOKUP($A266,'00_SKU_Master'!$B$2:$B$378,'00_SKU_Master'!$F$2:$F$378,0)*K266/_xlfn.XLOOKUP($A266,'00_SKU_Master'!$B$2:$B$378,'00_SKU_Master'!$O:$O,0),"") | T264: =SUM(N266:S266) | U264: ='05_Daily_Orders'!L265

Sheet 03_BulkPack_Order
B2: Cages to cut today | C2: 120
B3: Traypack Target | C3: 5000cs
B5: For Generic Traypack | C5: Qty x25kg
C6: Today | D6: Tomorrow | E6: Total
B7: Boneless Breast | D7: 0 | E7: 0
B8: Skin on split breast | C8: 31 | D8: 50 | E8: 81
B9: Skinless split breast | C9: 5 | D9: 30 | E9: 35
B10: Whole wing | C10: 5 | D10: 20 | E10: 25
B11: Split wing | C11: 15 | D11: 15 | E11: 30
B12: Drums | D12: 40 | E12: 40
B13: Bi thigh | D13: 60 | E13: 60
B14: Bnls thighs | D14: 80 | E14: 80
B15: Ba legs | C15: 20 | D15: 55 | E15: 75
B17: For Bagging | C17: Qtyx800kg
C18: Today | D18: Tomorrow | E18: Total
A19: 61062 | B19: BA Legs | D19: 1 | E19: 1 | G19: =IFERROR(SUMIF('13_Progress_Track'!$A$2:$A$108,A19,'13_Progress_Track'!$E$2:$E$108),"0") | H19: =SUM(C19:D19)
A20: 61073 | B20: Drum | C20: 2 | D20: 3 | E20: 5 | G20: =IFERROR(SUMIF('13_Progress_Track'!$A$2:$A$108,A20,'13_Progress_Track'!$E$2:$E$108),"0") | H20: =SUM(C20:D20)
A21: 61018 | B21: Whole wing | C21: 1 | D21: 3 | E21: 4 | G21: =IFERROR(SUMIF('13_Progress_Track'!$A$2:$A$108,A21,'13_Progress_Track'!$E$2:$E$108),"0") | H21: =SUM(C21:D21)
A22: 61014B | B22: Split wingx25kg | E22: 0 | G22: =IFERROR(SUMIF('13_Progress_Track'!$A$2:$A$108,A22,'13_Progress_Track'!$E$2:$E$108),"0") | H22: =SUM(C22:D22)
G23: =IFERROR(SUMIF('13_Progress_Track'!$A$2:$A$108,A23,'13_Progress_Track'!$E$2:$E$108),"0")
G24: =IFERROR(SUMIF('13_Progress_Track'!$A$2:$A$108,A24,'13_Progress_Track'!$E$2:$E$108),"0")
A25: {=IFERROR(VALUE(LEFT(B25, MATCH(FALSE, ISNUMBER(MID(B25, ROW(INDIRECT("1:"&LEN(B25)+1)), 1) *1), 0) -1)),"")} | B25: For sale | G25: =IFERROR(SUMIF('13_Progress_Track'!$A$2:$A$108,A25,'13_Progress_Track'!$E$2:$E$108),"0")
A26: {=IFERROR(VALUE(LEFT(B26, MATCH(FALSE, ISNUMBER(MID(B26, ROW(INDIRECT("1:"&LEN(B26)+1)), 1) *1), 0) -1)),"")} | B26: 203035 container | G26: =IFERROR(SUMIF('13_Progress_Track'!$A$2:$A$108,A26,'13_Progress_Track'!$E$2:$E$108),"0") | H26: =IFERROR(C26-G26,"")
A27: {=IFERROR(VALUE(LEFT(B27, MATCH(FALSE, ISNUMBER(MID(B27, ROW(INDIRECT("1:"&LEN(B27)+1)), 1) *1), 0) -1)),"")} | B27: 203172 container | G27: =IFERROR(SUMIF('13_Progress_Track'!$A$2:$A$108,A27,'13_Progress_Track'!$E$2:$E$108),"0") | H27: =IFERROR(C27-G27,"")
A28: {=IFERROR(VALUE(LEFT(B28, MATCH(FALSE, ISNUMBER(MID(B28, ROW(INDIRECT("1:"&LEN(B28)+1)), 1) *1), 0) -1)),"")} | B28: 868 Spl Wings | G28: =IFERROR(SUMIF('13_Progress_Track'!$A$2:$A$108,A28,'13_Progress_Track'!$E$2:$E$108),"0") | H28: =IFERROR(C28-G28,"")
A29: {=IFERROR(VALUE(LEFT(B29, MATCH(FALSE, ISNUMBER(MID(B29, ROW(INDIRECT("1:"&LEN(B29)+1)), 1) *1), 0) -1)),"")} | B29: 200868 MB HA SPL WING AC 18KG | C29: 100 | G29: =IFERROR(SUMIF('13_Progress_Track'!$A$2:$A$108,A29,'13_Progress_Track'!$E$2:$E$108),"0") | H29: =IFERROR(C29-G29,"")
A30: {=IFERROR(VALUE(LEFT(B30, MATCH(FALSE, ISNUMBER(MID(B30, ROW(INDIRECT("1:"&LEN(B30)+1)), 1) *1), 0) -1)),"")} | B30: 40021 Spl Wings 4x10lb | G30: =IFERROR(SUMIF('13_Progress_Track'!$A$2:$A$108,A30,'13_Progress_Track'!$E$2:$E$108),"0") | H30: =IFERROR(C30-G30,"")
A31: {=IFERROR(VALUE(LEFT(B31, MATCH(FALSE, ISNUMBER(MID(B31, ROW(INDIRECT("1:"&LEN(B31)+1)), 1) *1), 0) -1)),"")} | B31: 904 H. Whole wings | G31: =IFERROR(SUMIF('13_Progress_Track'!$A$2:$A$108,A31,'13_Progress_Track'!$E$2:$E$108),"0") | H31: =IFERROR(C31-G31,"")
A32: {=IFERROR(VALUE(LEFT(B32, MATCH(FALSE, ISNUMBER(MID(B32, ROW(INDIRECT("1:"&LEN(B32)+1)), 1) *1), 0) -1)),"")} | B32: 200904 H. Whole wings | G32: =IFERROR(SUMIF('13_Progress_Track'!$A$2:$A$108,A32,'13_Progress_Track'!$E$2:$E$108),"0") | H32: =IFERROR(C32-G32,"")
A33: {=IFERROR(VALUE(LEFT(B33, MATCH(FALSE, ISNUMBER(MID(B33, ROW(INDIRECT("1:"&LEN(B33)+1)), 1) *1), 0) -1)),"")} | B33: 200905 H. Whole wings | G33: =IFERROR(SUMIF('13_Progress_Track'!$A$2:$A$108,A33,'13_Progress_Track'!$E$2:$E$108),"0") | H33: =IFERROR(C33-G33,"")
A34: {=IFERROR(VALUE(LEFT(B34, MATCH(FALSE, ISNUMBER(MID(B34, ROW(INDIRECT("1:"&LEN(B34)+1)), 1) *1), 0) -1)),"")} | B34: 895 Drums | G34: =IFERROR(SUMIF('13_Progress_Track'!$A$2:$A$108,A34,'13_Progress_Track'!$E$2:$E$108),"0") | H34: =IFERROR(C34-G34,"")
A35: {=IFERROR(VALUE(LEFT(B35, MATCH(FALSE, ISNUMBER(MID(B35, ROW(INDIRECT("1:"&LEN(B35)+1)), 1) *1), 0) -1)),"")} | B35: 200095 H. Drums | C35: 40 | G35: =IFERROR(SUMIF('13_Progress_Track'!$A$2:$A$108,A35,'13_Progress_Track'!$E$2:$E$108),"0") | H35: =IFERROR(C35-G35,"")
A36: {=IFERROR(VALUE(LEFT(B36, MATCH(FALSE, ISNUMBER(MID(B36, ROW(INDIRECT("1:"&LEN(B36)+1)), 1) *1), 0) -1)),"")} | B36: 0160 Drums | G36: =IFERROR(SUMIF('13_Progress_Track'!$A$2:$A$108,A36,'13_Progress_Track'!$E$2:$E$108),"0") | H36: =IFERROR(C36-G36,"")
A37: {=IFERROR(VALUE(LEFT(B37, MATCH(FALSE, ISNUMBER(MID(B37, ROW(INDIRECT("1:"&LEN(B37)+1)), 1) *1), 0) -1)),"")} | B37: 203271 DRUM 110G LESS RET 25KG | G37: =IFERROR(SUMIF('13_Progress_Track'!$A$2:$A$108,A37,'13_Progress_Track'!$E$2:$E$108),"0") | H37: =IFERROR(C37-G37,"")
A38: {=IFERROR(VALUE(LEFT(B38, MATCH(FALSE, ISNUMBER(MID(B38, ROW(INDIRECT("1:"&LEN(B38)+1)), 1) *1), 0) -1)),"")} | B38: 159 BA Legs | C38: 150 | G38: =IFERROR(SUMIF('13_Progress_Track'!$A$2:$A$108,A38,'13_Progress_Track'!$E$2:$E$108),"0") | H38: =IFERROR(C38-G38,"")
A39: {=IFERROR(VALUE(LEFT(B39, MATCH(FALSE, ISNUMBER(MID(B39, ROW(INDIRECT("1:"&LEN(B39)+1)), 1) *1), 0) -1)),"")} | B39: 200159 H. BA Legs | G39: =IFERROR(SUMIF('13_Progress_Track'!$A$2:$A$108,A39,'13_Progress_Track'!$E$2:$E$108),"0") | H39: =IFERROR(C39-G39,"")
A40: {=IFERROR(VALUE(LEFT(B40, MATCH(FALSE, ISNUMBER(MID(B40, ROW(INDIRECT("1:"&LEN(B40)+1)), 1) *1), 0) -1)),"")} | B40: 200903 H. BA Legs a/c | C40: 150 | G40: =IFERROR(SUMIF('13_Progress_Track'!$A$2:$A$108,A40,'13_Progress_Track'!$E$2:$E$108),"0") | H40: =IFERROR(C40-G40,"")
A41: {=IFERROR(VALUE(LEFT(B41, MATCH(FALSE, ISNUMBER(MID(B41, ROW(INDIRECT("1:"&LEN(B41)+1)), 1) *1), 0) -1)),"")} | B41: 165 Bnls breast | G41: =IFERROR(SUMIF('13_Progress_Track'!$A$2:$A$108,A41,'13_Progress_Track'!$E$2:$E$108),"0") | H41: =IFERROR(C41-G41,"")
A42: {=IFERROR(VALUE(LEFT(B42, MATCH(FALSE, ISNUMBER(MID(B42, ROW(INDIRECT("1:"&LEN(B42)+1)), 1) *1), 0) -1)),"")} | B42: 1894 Bnls breast | G42: =IFERROR(SUMIF('13_Progress_Track'!$A$2:$A$108,A42,'13_Progress_Track'!$E$2:$E$108),"0") | H42: =IFERROR(C42-G42,"")
A43: {=IFERROR(VALUE(LEFT(B43, MATCH(FALSE, ISNUMBER(MID(B43, ROW(INDIRECT("1:"&LEN(B43)+1)), 1) *1), 0) -1)),"")} | B43: 201894 H. Bnls breast | G43: =IFERROR(SUMIF('13_Progress_Track'!$A$2:$A$108,A43,'13_Progress_Track'!$E$2:$E$108),"0") | H43: =IFERROR(C43-G43,"")
...

Sheet 04_Bagging_Order
B2: Total Cases | K2: 1356 | L2: 2103 | M2: 1149
B3: DAY | I3: =SUMIF(I5:I25,">0") | J3: =SUM(J5:J22) | K3: =SUMIF(K5:K23,">0")
B4: SKU | H4: SKU | I4: Today's | J4: Completed | K4: Remaining | L4: KG | M4: Raw Cages | O4: WIP
B5: ='00_SKU_Master'!B357 | D5: 99 | H5: =B5 | I5: =SUM(C5:F5) | J5: =SUMIF('13_Progress_Track'!$A$2:$A$108,B5,'13_Progress_Track'!$E$2:$E$108) | K5: =I5-J5 | L5: =_xludf.IFNA(_xlfn.XLOOKUP(H5,$B$27:$B$41,$C$27:$C$41,0)*K5,"") | M5: =_xludf.IFNA(L5/_xlfn.XLOOKUP(H5,$B$27:$B$43,$F$27:$F$43,0),"") | O5: =_xludf.IFNA(_xlfn.XLOOKUP(H5,$B$27:$B$43,$E$27:$E$43),"")
B6: ='00_SKU_Master'!B358 | D6: 188 | H6: =B6 | I6: =SUM(C6:F6) | J6: =SUMIF('13_Progress_Track'!$A$2:$A$108,B6,'13_Progress_Track'!$E$2:$E$108) | K6: =I6-J6 | L6: =_xludf.IFNA(_xlfn.XLOOKUP(H6,$B$27:$B$41,$C$27:$C$41,0)*K6,"") | M6: =_xludf.IFNA(L6/_xlfn.XLOOKUP(H6,$B$27:$B$43,$F$27:$F$43,0),"") | O6: =_xludf.IFNA(_xlfn.XLOOKUP(H6,$B$27:$B$43,$E$27:$E$43),"")
B7: ='00_SKU_Master'!B359 | D7: 81 | H7: =B7 | I7: =SUM(C7:F7) | J7: =SUMIF('13_Progress_Track'!$A$2:$A$108,B7,'13_Progress_Track'!$E$2:$E$108) | K7: =I7-J7 | L7: =_xludf.IFNA(_xlfn.XLOOKUP(H7,$B$27:$B$41,$C$27:$C$41,0)*K7,"") | M7: =_xludf.IFNA(L7/_xlfn.XLOOKUP(H7,$B$27:$B$43,$F$27:$F$43,0),"") | O7: =_xludf.IFNA(_xlfn.XLOOKUP(H7,$B$27:$B$43,$E$27:$E$43),"")
B8: ='00_SKU_Master'!B360 | D8: 0 | H8: =B8 | I8: =SUM(C8:F8) | J8: =SUMIF('13_Progress_Track'!$A$2:$A$108,B8,'13_Progress_Track'!$E$2:$E$108) | K8: =I8-J8 | L8: =_xludf.IFNA(_xlfn.XLOOKUP(H8,$B$27:$B$41,$C$27:$C$41,0)*K8,"") | M8: =_xludf.IFNA(L8/_xlfn.XLOOKUP(H8,$B$27:$B$43,$F$27:$F$43,0),"") | O8: =_xludf.IFNA(_xlfn.XLOOKUP(H8,$B$27:$B$43,$E$27:$E$43),"")
B9: ='00_SKU_Master'!B361 | D9: 0 | H9: =B9 | I9: =SUM(C9:F9) | J9: =SUMIF('13_Progress_Track'!$A$2:$A$108,B9,'13_Progress_Track'!$E$2:$E$108) | K9: =I9-J9 | L9: =_xludf.IFNA(_xlfn.XLOOKUP(H9,$B$27:$B$41,$C$27:$C$41,0)*K9,"") | M9: =_xludf.IFNA(L9/_xlfn.XLOOKUP(H9,$B$27:$B$43,$F$27:$F$43,0),"") | O9: =_xludf.IFNA(_xlfn.XLOOKUP(H9,$B$27:$B$43,$E$27:$E$43),"")
B10: ='00_SKU_Master'!B362 | D10: 34 | H10: =B10 | I10: =SUM(C10:F10) | J10: =SUMIF('13_Progress_Track'!$A$2:$A$108,B10,'13_Progress_Track'!$E$2:$E$108) | K10: =I10-J10 | L10: =_xludf.IFNA(_xlfn.XLOOKUP(H10,$B$27:$B$41,$C$27:$C$41,0)*K10,"") | M10: =_xludf.IFNA(L10/_xlfn.XLOOKUP(H10,$B$27:$B$43,$F$27:$F$43,0),"") | O10: =_xludf.IFNA(_xlfn.XLOOKUP(H10,$B$27:$B$43,$E$27:$E$43),"")
B11: ='00_SKU_Master'!B363 | D11: -11 | H11: =B11 | I11: =SUM(C11:F11) | J11: =SUMIF('13_Progress_Track'!$A$2:$A$108,B11,'13_Progress_Track'!$E$2:$E$108) | K11: =I11-J11 | L11: =_xludf.IFNA(_xlfn.XLOOKUP(H11,$B$27:$B$41,$C$27:$C$41,0)*K11,"") | M11: =_xludf.IFNA(L11/_xlfn.XLOOKUP(H11,$B$27:$B$43,$F$27:$F$43,0),"") | O11: =_xludf.IFNA(_xlfn.XLOOKUP(H11,$B$27:$B$43,$E$27:$E$43),"")
B12: ='00_SKU_Master'!B364 | D12: 30 | H12: =B12 | I12: =SUM(C12:F12) | J12: =SUMIF('13_Progress_Track'!$A$2:$A$108,B12,'13_Progress_Track'!$E$2:$E$108) | K12: =I12-J12 | L12: =_xludf.IFNA(_xlfn.XLOOKUP(H12,$B$27:$B$41,$C$27:$C$41,0)*K12,"") | M12: =_xludf.IFNA(L12/_xlfn.XLOOKUP(H12,$B$27:$B$43,$F$27:$F$43,0),"") | O12: =_xludf.IFNA(_xlfn.XLOOKUP(H12,$B$27:$B$43,$E$27:$E$43),"")
B13: ='00_SKU_Master'!B365 | D13: 0 | H13: =B13 | I13: =SUM(C13:F13) | J13: =SUMIF('13_Progress_Track'!$A$2:$A$108,B13,'13_Progress_Track'!$E$2:$E$108) | K13: =I13-J13 | L13: =_xludf.IFNA(_xlfn.XLOOKUP(H13,$B$27:$B$41,$C$27:$C$41,0)*K13,"") | M13: =_xludf.IFNA(L13/_xlfn.XLOOKUP(H13,$B$27:$B$43,$F$27:$F$43,0),"") | O13: =_xludf.IFNA(_xlfn.XLOOKUP(H13,$B$27:$B$43,$E$27:$E$43),"")
B14: ='00_SKU_Master'!B366 | H14: =B14 | I14: =SUM(C14:F14) | J14: =SUMIF('13_Progress_Track'!$A$2:$A$108,B14,'13_Progress_Track'!$E$2:$E$108) | K14: =I14-J14 | L14: =_xludf.IFNA(_xlfn.XLOOKUP(H14,$B$27:$B$41,$C$27:$C$41,0)*K14,"") | M14: =_xludf.IFNA(L14/_xlfn.XLOOKUP(H14,$B$27:$B$43,$F$27:$F$43,0),"") | O14: =_xludf.IFNA(_xlfn.XLOOKUP(H14,$B$27:$B$43,$E$27:$E$43),"")
B15: ='00_SKU_Master'!B367 | H15: =B15 | I15: =SUM(C15:F15) | J15: =SUMIF('13_Progress_Track'!$A$2:$A$108,B15,'13_Progress_Track'!$E$2:$E$108) | K15: =I15-J15 | L15: =_xludf.IFNA(_xlfn.XLOOKUP(H15,$B$27:$B$41,$C$27:$C$41,0)*K15,"") | M15: =_xludf.IFNA(L15/_xlfn.XLOOKUP(H15,$B$27:$B$43,$F$27:$F$43,0),"") | O15: =_xludf.IFNA(_xlfn.XLOOKUP(H15,$B$27:$B$43,$E$27:$E$43),"")
B16: ='00_SKU_Master'!B368 | H16: =B16 | I16: =SUM(C16:F16) | J16: =SUMIF('13_Progress_Track'!$A$2:$A$108,B16,'13_Progress_Track'!$E$2:$E$108) | K16: =I16-J16 | L16: =_xludf.IFNA(_xlfn.XLOOKUP(H16,$B$27:$B$41,$C$27:$C$41,0)*K16,"") | M16: =_xludf.IFNA(L16/_xlfn.XLOOKUP(H16,$B$27:$B$43,$F$27:$F$43,0),"") | O16: =_xludf.IFNA(_xlfn.XLOOKUP(H16,$B$27:$B$43,$E$27:$E$43),"")
B17: ='00_SKU_Master'!B369 | H17: =B17 | I17: =SUM(C17:F17) | J17: =SUMIF('13_Progress_Track'!$A$2:$A$108,B17,'13_Progress_Track'!$E$2:$E$108) | K17: =I17-J17 | L17: =_xludf.IFNA(_xlfn.XLOOKUP(H17,$B$27:$B$41,$C$27:$C$41,0)*K17,"") | M17: =_xludf.IFNA(L17/_xlfn.XLOOKUP(H17,$B$27:$B$43,$F$27:$F$43,0),"") | O17: =_xludf.IFNA(_xlfn.XLOOKUP(H17,$B$27:$B$43,$E$27:$E$43),"")
B18: ='00_SKU_Master'!B370 | H18: =B18 | I18: =SUM(C18:F18) | J18: =SUMIF('13_Progress_Track'!$A$2:$A$108,B18,'13_Progress_Track'!$E$2:$E$108) | K18: =I18-J18 | L18: =_xludf.IFNA(_xlfn.XLOOKUP(H18,$B$27:$B$41,$C$27:$C$41,0)*K18,"") | M18: =_xludf.IFNA(L18/_xlfn.XLOOKUP(H18,$B$27:$B$43,$F$27:$F$43,0),"") | O18: =_xludf.IFNA(_xlfn.XLOOKUP(H18,$B$27:$B$43,$E$27:$E$43),"")
B19: ='00_SKU_Master'!B371 | H19: =B19 | I19: =SUM(C19:F19) | J19: =SUMIF('13_Progress_Track'!$A$2:$A$108,B19,'13_Progress_Track'!$E$2:$E$108) | K19: =I19-J19 | L19: =_xludf.IFNA(_xlfn.XLOOKUP(H19,$B$27:$B$41,$C$27:$C$41,0)*K19,"") | M19: =_xludf.IFNA(L19/_xlfn.XLOOKUP(H19,$B$27:$B$43,$F$27:$F$43,0),"") | O19: =_xludf.IFNA(_xlfn.XLOOKUP(H19,$B$27:$B$43,$E$27:$E$43),"")
B20: ='00_SKU_Master'!B372 | H20: =B20 | I20: =SUM(C20:F20) | J20: =SUMIF('13_Progress_Track'!$A$2:$A$108,B20,'13_Progress_Track'!$E$2:$E$108) | K20: =I20-J20 | L20: =_xludf.IFNA(_xlfn.XLOOKUP(H20,$B$27:$B$41,$C$27:$C$41,0)*K20,"") | M20: =_xludf.IFNA(L20/_xlfn.XLOOKUP(H20,$B$27:$B$43,$F$27:$F$43,0),"") | O20: =_xludf.IFNA(_xlfn.XLOOKUP(H20,$B$27:$B$43,$E$27:$E$43),"")
B21: ='00_SKU_Master'!B373 | H21: =B21 | I21: =SUM(C21:F21) | J21: =SUMIF('13_Progress_Track'!$A$2:$A$108,B21,'13_Progress_Track'!$E$2:$E$108) | K21: =I21-J21 | L21: =_xludf.IFNA(_xlfn.XLOOKUP(H21,$B$27:$B$41,$C$27:$C$41,0)*K21,"") | M21: =_xludf.IFNA(L21/_xlfn.XLOOKUP(H21,$B$27:$B$43,$F$27:$F$43,0),"") | O21: =_xludf.IFNA(_xlfn.XLOOKUP(H21,$B$27:$B$43,$E$27:$E$43),"")
B22: ='00_SKU_Master'!B374 | H22: =B22 | I22: =SUM(C22:F22) | J22: =SUMIF('13_Progress_Track'!$A$2:$A$108,B22,'13_Progress_Track'!$E$2:$E$108) | K22: =I22-J22 | L22: =_xludf.IFNA(_xlfn.XLOOKUP(H22,$B$27:$B$41,$C$27:$C$41,0)*K22,"") | M22: =_xludf.IFNA(L22/_xlfn.XLOOKUP(H22,$B$27:$B$43,$F$27:$F$43,0),"") | O22: =_xludf.IFNA(_xlfn.XLOOKUP(H22,$B$27:$B$43,$E$27:$E$43),"")
M23: =_xludf.IFNA(L23/_xlfn.XLOOKUP(H23,$B$27:$B$43,$F$27:$F$43,0),"") | O23: =_xludf.IFNA(_xlfn.XLOOKUP(H23,$B$27:$B$43,$E$27:$E$43),"")
Q26: Request
B27: 2050 | C27: 11.333345 | D27: 0.46 | E27: 61062 | F27: 600 | I27: Inventory | J27: 61062 | L27: 1151 | O27: 61062 | P27: =SUMIF($O$5:$O$25,O27,$L$5:$L$25) | Q27: =P27-L27 | R27: =Q27/_xlfn.XLOOKUP(O27,$E$27:$E$41,$F$27:$F$41)
B28: 2051 | C28: 10.945225 | D28: 0.14 | E28: 61073 | F28: 800 | J28: 61073 | L28: 2266 | O28: 61073 | P28: =SUMIF($O$5:$O$25,O28,$L$5:$L$25) | Q28: =P28-L28 | R28: =Q28/_xlfn.XLOOKUP(O28,$E$27:$E$41,$F$27:$F$41)
B29: 2051 | C29: 10.6 | D29: 0.14 | E29: 61073 | F29: 800 | J29: 61018 | L29: 788 | O29: 61018 | P29: =SUMIF($O$5:$O$25,O29,$L$5:$L$25) | Q29: =P29-L29 | R29: =Q29/_xlfn.XLOOKUP(O29,$E$27:$E$41,$F$27:$F$41)
B30: 2081 | C30: 11.244537 | D30: 0.105 | E30: 61018 | F30: 600 | J30: 61014B | O30: 61014B | P30: =SUMIF($O$5:$O$25,O30,$L$5:$L$25) | Q30: =P30-L30 | R30: =P30/_xlfn.XLOOKUP(O30,$E$27:$E$41,$F$27:$F$41)
B31: 2112 | C31: 13.5 | D31: 0.46 | E31: 61062 | F31: 800 | J31: 200157
B32: 2511 | C32: 14 | D32: 0.095 | E32: 61014B | F32: 600
B33: 7011 | C33: 9.6 | E33: W-Chicken | F33: 600 | J33: BSK | K33: =SUMIF(G5:G25,J33,D5:D25)
B34: 7113 | C34: 12.853 | E34: W-Chicken | F34: 600 | J34: BOX | K34: =SUMIF(G5:G25,J34,D5:D25)
B35: 7301 | C35: 12.6 | D35: 0.46 | E35: 61062 | F35: 800
B36: 200182 | C36: 9.9302222 | D36: 0.105 | E36: 61018 | F36: 600
B37: 200183 | C37: 9.0926639 | D37: 0.46 | E37: 61062 | F37: 800
B38: 200184 | C38: 8.982093 | D38: 0.14 | E38: 61073 | F38: 800
B39: 207526 | C39: 12 | D39: 0.46 | E39: 61062 | F39: 800
B40: 207527 | C40: 12 | D40: 0.46 | E40: 61062 | F40: 800
B41: 2513

Sheet 05_Daily_Orders
A1: Description | B1: SKU | C1: Cases Ordered - Orginal | D1: Cases Added On | E1: Cases Completed | F1: Extra Cases Produced | G1: Cases Remaining | H1: Tray/box | I1: Don’t change | J1: Tray/Min | K1: Speed | L1: Category | M1: Today's Order
A2: ='00_SKU_Master'!J94 | B2: ='00_SKU_Master'!B94 | C2: =_xlfn.XLOOKUP(B3,'02_TrayPack_Order'!$A$2:$A$264,'02_TrayPack_Order'!$C$2:$C$264) | D2: =_xlfn.XLOOKUP(B3,'02_TrayPack_Order'!$A$2:$A$264,'02_TrayPack_Order'!$L$2:$L$264,0) | E2: =SUMIF('13_Progress_Track'!$A$2:$A$108,B3,'13_Progress_Track'!$E$2:$E$108) | F2: =IF(E3>(C3+D3),(E3-(C3+D3)),0) | G2: =IF(F3>0,0,C3+D3-E3) | H2: =_xludf.IFNA(_xlfn.XLOOKUP(B3,'00_SKU_Master'!$B$2:$B$378,'00_SKU_Master'!$C$2:$C$378),"") | J2: =_xludf.IFNA(_xlfn.XLOOKUP(B3,'00_SKU_Master'!B$2:B$378,'00_SKU_Master'!H$2:H$378,0),"") | K2: =_xludf.IFNA(_xlfn.XLOOKUP(B3,'00_SKU_Master'!B$2:B$378,'00_SKU_Master'!K$2:K$378,0),"") | L2: =_xlfn.XLOOKUP(B3,'00_SKU_Master'!$B$2:$B$378,'00_SKU_Master'!D:D) | M2: =IF((C3-E3)<0,0,C3-E3)
A3: ='00_SKU_Master'!J95 | B3: ='00_SKU_Master'!B95 | C3: =_xlfn.XLOOKUP(B4,'02_TrayPack_Order'!$A$2:$A$264,'02_TrayPack_Order'!$C$2:$C$264) | D3: =_xlfn.XLOOKUP(B4,'02_TrayPack_Order'!$A$2:$A$264,'02_TrayPack_Order'!$L$2:$L$264,0) | E3: =SUMIF('13_Progress_Track'!$A$2:$A$108,B4,'13_Progress_Track'!$E$2:$E$108) | F3: =IF(E4>(C4+D4),(E4-(C4+D4)),0) | G3: =IF(F4>0,0,C4+D4-E4) | H3: =_xludf.IFNA(_xlfn.XLOOKUP(B4,'00_SKU_Master'!$B$2:$B$378,'00_SKU_Master'!$C$2:$C$378),"") | J3: =_xludf.IFNA(_xlfn.XLOOKUP(B4,'00_SKU_Master'!B$2:B$378,'00_SKU_Master'!H$2:H$378,0),"") | K3: =_xludf.IFNA(_xlfn.XLOOKUP(B4,'00_SKU_Master'!B$2:B$378,'00_SKU_Master'!K$2:K$378,0),"") | L3: =_xlfn.XLOOKUP(B4,'00_SKU_Master'!$B$2:$B$378,'00_SKU_Master'!D:D) | M3: =IF((C4-E4)<0,0,C4-E4)
